Workbook

Sheet Notice
A1: MODÈLE FINANCIER — ASSURANCE CIMA (Vie + Non-Vie)
B3: H&C Group — Référence multisectorielle
B4: Conformité : Code CIMA — IFRS 17 (option) — SYSCOHADA
A6: 1. OBJET DU MODÈLE
B7: Objet | C7: Plan d'affaires sur 5 ans d'une compagnie d'assurance mixte (Vie + Non-Vie) de zone CIMA. Modèle de référence H&C Group pour les équipes développement et directions financières.
B8: Périmètre | C8: Souscription, sinistralité, provisions techniques CIMA, placements, P&L technique et non-technique, marge de solvabilité réglementaire CIMA.
B9: Hypothèses clés | C9: Portefeuille polices Vie/Non-Vie, taux de chargement, loss ratio, fréquence sinistres, taux technique des PM, rendement des placements.
A11: 2. STRUCTURE DU MODÈLE
B12: Hypothèses | C12: Macro, portefeuille, sinistralité, placements, fiscalité
B13: Portefeuille | C13: Polices Vie et Non-Vie par branche
B14: Primes | C14: Émissions, acquises, cédées en réassurance
B15: Sinistres | C15: Charges, IBNR, frais de gestion
B16: Provisions techniques | C16: PM, PSAP, PPNA, PREC
B17: Placements | C17: Allocation, rendements, RTE
B18: P_L technique | C18: Compte technique Vie + Non-Vie séparés
B19: P_L global | C19: P&L non-technique consolidé
B20: Bilan | C20: Actif (placements + créances) / Passif (PM + capitaux propres)
B21: Marge solvabilité | C21: Calcul marge réglementaire CIMA
B22: KPIs | C22: Loss ratio, expense ratio, ratio combiné, persistance
B23: Stress tests | C23: Choc sinistralité, choc liquidité, choc rendement
B24: Scénarios | C24: Vue comparée Pess/Base/Opt
A26: 3. CODE COULEUR
B27: Bleu (input) | C27: Cellule saisie manuellement — hypothèse modifiable
B28: Noir (formule) | C28: Cellule calculée automatiquement
B29: Vert (lien) | C29: Lien vers une autre feuille du classeur
B30: Fond jaune | C30: Hypothèse clé
B31: Bandeau navy | C31: Titre / en-tête
B32: Bandeau or | C32: Sous-titre

Sheet Hypothèses
A1: HYPOTHÈSES — ASSURANCE CIMA
B3: Y1 (2026) | C3: Y2 (2027) | D3: Y3 (2028) | E3: Y4 (2029) | F3: Y5 (2030)
A4: 1. MACRO & FISCALITÉ
A5: Inflation (%) | B5: 0.03 | C5: 0.025 | D5: 0.025 | E5: 0.025 | F5: 0.025 | H5: Zone CFA
A6: Taux IS (%) | B6: 0.3 | C6: 0.3 | D6: 0.3 | E6: 0.3 | F6: 0.3 | H6: Standard CIMA
A7: Taxe d'assurance Non-Vie (%) | B7: 0.07 | C7: 0.07 | D7: 0.07 | E7: 0.07 | F7: 0.07 | H7: Variable selon branches
A8: Charges patronales (%) | B8: 0.18 | C8: 0.18 | D8: 0.18 | E8: 0.18 | F8: 0.18
A10: 2. PORTEFEUILLE VIE
A11: Polices Vie actives (milliers) | B11: 25 | C11: 30 | D11: 36 | E11: 43 | F11: 51 | H11: Croissance soutenue
A12: Prime moyenne / police Vie (k FCFA) | B12: 180 | C12: 190 | D12: 200 | E12: 210 | F12: 220
A13: Taux de chute / lapse Vie (%) | B13: 0.08 | C13: 0.08 | D13: 0.075 | E13: 0.07 | F13: 0.07 | H13: Sortie portefeuille
A14: Taux de rachat moyen Vie (%) | B14: 0.06 | C14: 0.06 | D14: 0.055 | E14: 0.05 | F14: 0.05
A15: Taux technique PM (%) | B15: 0.035 | C15: 0.035 | D15: 0.035 | E15: 0.035 | F15: 0.035 | H15: Taux actuariel
A16: Participation aux bénéfices Vie (%) | B16: 0.9 | C16: 0.9 | D16: 0.9 | E16: 0.9 | F16: 0.9 | H16: % résultat technique
A18: 3. PORTEFEUILLE NON-VIE
A19: Polices Non-Vie automobile (k) | B19: 85 | C19: 95 | D19: 106 | E19: 119 | F19: 133
A20: Polices Non-Vie entreprises (k) | B20: 3.5 | C20: 4 | D20: 4.6 | E20: 5.3 | F20: 6.1
A21: Polices Non-Vie santé (k) | B21: 18 | C21: 21 | D21: 24 | E21: 28 | F21: 32 | H21: Forte croissance
A22: Prime moyenne auto (k FCFA) | B22: 85 | C22: 90 | D22: 95 | E22: 100 | F22: 105 | H22: RC + dommages
A23: Prime moyenne entreprises (k FCFA) | B23: 850 | C23: 900 | D23: 950 | E23: 1000 | F23: 1050
A24: Prime moyenne santé (k FCFA) | B24: 150 | C24: 160 | D24: 170 | E24: 180 | F24: 190
A26: 4. SINISTRALITÉ NON-VIE
A27: Loss ratio automobile (%) | B27: 0.68 | C27: 0.66 | D27: 0.65 | E27: 0.64 | F27: 0.63 | H27: Sinistres/primes acquises
A28: Loss ratio entreprises (%) | B28: 0.55 | C28: 0.54 | D28: 0.53 | E28: 0.52 | F28: 0.51 | H28: Meilleure sélection
A29: Loss ratio santé (%) | B29: 0.72 | C29: 0.71 | D29: 0.7 | E29: 0.69 | F29: 0.68
A30: Taux d'IBNR (% sinistres déclarés) | B30: 0.12 | C30: 0.12 | D30: 0.12 | E30: 0.12 | F30: 0.12 | H30: Sinistres tardifs
A32: 5. SINISTRALITÉ VIE
A33: Sinistres Vie (% PM moyennes) | B33: 0.045 | C33: 0.045 | D33: 0.044 | E33: 0.043 | F33: 0.042 | H33: Décès + rachats
A35: 6. FRAIS
A36: Frais d'acquisition Vie (% primes) | B36: 0.18 | C36: 0.17 | D36: 0.16 | E36: 0.15 | F36: 0.14 | H36: Commissions agents
A37: Frais d'acquisition Non-Vie (% primes) | B37: 0.2 | C37: 0.19 | D37: 0.18 | E37: 0.18 | F37: 0.17
A38: Frais d'administration (% primes) | B38: 0.08 | C38: 0.08 | D38: 0.075 | E38: 0.07 | F38: 0.07
A39: Frais de gestion sinistres (% sinistres) | B39: 0.05 | C39: 0.05 | D39: 0.05 | E39: 0.05 | F39: 0.05
A41: 7. RÉASSURANCE
A42: Taux de cession en réassurance Non-Vie (%) | B42: 0.25 | C42: 0.25 | D42: 0.25 | E42: 0.25 | F42: 0.25 | H42: Conservation 75%
A43: Commission de réassurance perçue (% cédé) | B43: 0.25 | C43: 0.25 | D43: 0.25 | E43: 0.25 | F43: 0.25 | H43: Rétrocession
A44: Taux de cession Vie (%) | B44: 0.1 | C44: 0.1 | D44: 0.1 | E44: 0.1 | F44: 0.1 | H44: Plus faible en Vie
A46: 8. PLACEMENTS — Allocation & Rendements
A47: % Obligations d'État zone CIMA | B47: 0.45 | C47: 0.45 | D47: 0.45 | E47: 0.45 | F47: 0.45 | H47: RTE éligible
A48: % Dépôts bancaires | B48: 0.2 | C48: 0.2 | D48: 0.2 | E48: 0.2 | F48: 0.2 | H48: RTE éligible
...

Sheet Portefeuille
A1: PORTEFEUILLE POLICES (Vie + Non-Vie)
B3: Y1 (2026) | C3: Y2 (2027) | D3: Y3 (2028) | E3: Y4 (2029) | F3: Y5 (2030)
A4: POLICES VIE
A5: Polices Vie actives (k) | B5: =Hypothèses!B11 -> 25 | C5: =Hypothèses!C11 -> 30 | D5: =Hypothèses!D11 -> 36 | E5: =Hypothèses!E11 -> 43 | F5: =Hypothèses!F11 -> 51
A6: Prime moyenne (k FCFA) | B6: =Hypothèses!B12 -> 180 | C6: =Hypothèses!C12 -> 190 | D6: =Hypothèses!D12 -> 200 | E6: =Hypothèses!E12 -> 210 | F6: =Hypothèses!F12 -> 220
A7: CA Vie potentiel (Md FCFA) | B7: =B5*B6/1000 -> 4.5 | C7: =C5*C6/1000 -> 5.7 | D7: =D5*D6/1000 -> 7.2 | E7: =E5*E6/1000 -> 9.03 | F7: =F5*F6/1000 -> 11.22
A9: POLICES NON-VIE — AUTOMOBILE
A10: Polices auto actives (k) | B10: =Hypothèses!B19 -> 85 | C10: =Hypothèses!C19 -> 95 | D10: =Hypothèses!D19 -> 106 | E10: =Hypothèses!E19 -> 119 | F10: =Hypothèses!F19 -> 133
A11: Prime moyenne auto (k FCFA) | B11: =Hypothèses!B22 -> 85 | C11: =Hypothèses!C22 -> 90 | D11: =Hypothèses!D22 -> 95 | E11: =Hypothèses!E22 -> 100 | F11: =Hypothèses!F22 -> 105
A12: Primes auto (Md FCFA) | B12: =B10*B11/1000 -> 7.225 | C12: =C10*C11/1000 -> 8.55 | D12: =D10*D11/1000 -> 10.07 | E12: =E10*E11/1000 -> 11.9 | F12: =F10*F11/1000 -> 13.965
A14: POLICES NON-VIE — ENTREPRISES
A15: Polices entreprises (k) | B15: =Hypothèses!B20 -> 3.5 | C15: =Hypothèses!C20 -> 4 | D15: =Hypothèses!D20 -> 4.6 | E15: =Hypothèses!E20 -> 5.3 | F15: =Hypothèses!F20 -> 6.1
A16: Prime moyenne entreprises (k FCFA) | B16: =Hypothèses!B23 -> 850 | C16: =Hypothèses!C23 -> 900 | D16: =Hypothèses!D23 -> 950 | E16: =Hypothèses!E23 -> 1000 | F16: =Hypothèses!F23 -> 1050
A17: Primes entreprises (Md FCFA) | B17: =B15*B16/1000 -> 2.975 | C17: =C15*C16/1000 -> 3.6 | D17: =D15*D16/1000 -> 4.37 | E17: =E15*E16/1000 -> 5.3 | F17: =F15*F16/1000 -> 6.405
A19: POLICES NON-VIE — SANTÉ
A20: Polices santé (k) | B20: =Hypothèses!B21 -> 18 | C20: =Hypothèses!C21 -> 21 | D20: =Hypothèses!D21 -> 24 | E20: =Hypothèses!E21 -> 28 | F20: =Hypothèses!F21 -> 32
A21: Prime moyenne santé (k FCFA) | B21: =Hypothèses!B24 -> 150 | C21: =Hypothèses!C24 -> 160 | D21: =Hypothèses!D24 -> 170 | E21: =Hypothèses!E24 -> 180 | F21: =Hypothèses!F24 -> 190
A22: Primes santé (Md FCFA) | B22: =B20*B21/1000 -> 2.7 | C22: =C20*C21/1000 -> 3.36 | D22: =D20*D21/1000 -> 4.08 | E22: =E20*E21/1000 -> 5.04 | F22: =F20*F21/1000 -> 6.08
A24: TOTAUX
A25: Total primes Non-Vie (Md FCFA) | B25: =B12+B17+B22 -> 12.9 | C25: =C12+C17+C22 -> 15.51 | D25: =D12+D17+D22 -> 18.52 | E25: =E12+E17+E22 -> 22.24 | F25: =F12+F17+F22 -> 26.45
A26: Total primes Vie + Non-Vie (Md FCFA) | B26: =B7+B25 -> 17.4 | C26: =C7+C25 -> 21.21 | D26: =D7+D25 -> 25.72 | E26: =E7+E25 -> 31.27 | F26: =F7+F25 -> 37.67

Sheet Primes
A1: PRIMES — ÉMISSIONS, ACQUISES, CESSIONS RÉASSURANCE
B3: Y1 (2026) | C3: Y2 (2027) | D3: Y3 (2028) | E3: Y4 (2029) | F3: Y5 (2030)
A4: PRIMES ÉMISES (Md FCFA)
A5: Primes émises Vie | B5: =Portefeuille!B7 -> 4.5 | C5: =Portefeuille!C7 -> 5.7 | D5: =Portefeuille!D7 -> 7.2 | E5: =Portefeuille!E7 -> 9.03 | F5: =Portefeuille!F7 -> 11.22
A6: Primes émises Non-Vie | B6: =Portefeuille!B25 -> 12.9 | C6: =Portefeuille!C25 -> 15.51 | D6: =Portefeuille!D25 -> 18.52 | E6: =Portefeuille!E25 -> 22.24 | F6: =Portefeuille!F25 -> 26.45
A7: Total primes émises | B7: =B5+B6 -> 17.4 | C7: =C5+C6 -> 21.21 | D7: =D5+D6 -> 25.72 | E7: =E5+E6 -> 31.27 | F7: =F5+F6 -> 37.67
A9: PRIMES ACQUISES (Md FCFA)
A10: Primes acquises Vie (~ primes émises) | B10: =B5 -> 4.5 | C10: =C5 -> 5.7 | D10: =D5 -> 7.2 | E10: =E5 -> 9.03 | F10: =F5 -> 11.22
A11: Primes acquises Non-Vie (approxim. 92%) | B11: =B6*0.92 -> 11.868 | C11: =C6*0.92 -> 14.2692 | D11: =D6*0.92 -> 17.0384 | E11: =E6*0.92 -> 20.4608 | F11: =F6*0.92 -> 24.334
A12: Variation PPNA (Non-Vie) | B12: =B6*0.08 -> 1.032 | C12: =C6*0.08 -> 1.2408 | D12: =D6*0.08 -> 1.4816 | E12: =E6*0.08 -> 1.7792 | F12: =F6*0.08 -> 2.116
A13: Total primes acquises | B13: =B10+B11 -> 16.368 | C13: =C10+C11 -> 19.9692 | D13: =D10+D11 -> 24.2384 | E13: =E10+E11 -> 29.4908 | F13: =F10+F11 -> 35.554
A15: RÉASSURANCE CÉDÉE
A16: Primes cédées Vie (Md FCFA) | B16: =B5*Hypothèses!B44 -> 0.45 | C16: =C5*Hypothèses!C44 -> 0.57 | D16: =D5*Hypothèses!D44 -> 0.72 | E16: =E5*Hypothèses!E44 -> 0.903 | F16: =F5*Hypothèses!F44 -> 1.122
A17: Primes cédées Non-Vie (Md FCFA) | B17: =B6*Hypothèses!B42 -> 3.225 | C17: =C6*Hypothèses!C42 -> 3.8775 | D17: =D6*Hypothèses!D42 -> 4.63 | E17: =E6*Hypothèses!E42 -> 5.56 | F17: =F6*Hypothèses!F42 -> 6.6125
A18: Total primes cédées | B18: =B16+B17 -> 3.675 | C18: =C16+C17 -> 4.4475 | D18: =D16+D17 -> 5.35 | E18: =E16+E17 -> 6.463 | F18: =F16+F17 -> 7.7345
A19: Commission de réassurance perçue | B19: =B18*Hypothèses!B43 -> 0.91875 | C19: =C18*Hypothèses!C43 -> 1.111875 | D19: =D18*Hypothèses!D43 -> 1.3375 | E19: =E18*Hypothèses!E43 -> 1.61575 | F19: =F18*Hypothèses!F43 -> 1.933625
A21: PRIMES ACQUISES NETTES
A22: Primes acquises nettes (Vie) | B22: =B10-B16 -> 4.05 | C22: =C10-C16 -> 5.13 | D22: =D10-D16 -> 6.48 | E22: =E10-E16 -> 8.127 | F22: =F10-F16 -> 10.098
A23: Primes acquises nettes (Non-Vie) | B23: =B11-B17 -> 8.643 | C23: =C11-C17 -> 10.3917 | D23: =D11-D17 -> 12.4084 | E23: =E11-E17 -> 14.9008 | F23: =F11-F17 -> 17.7215
A24: Total primes acquises nettes | B24: =B22+B23 -> 12.693 | C24: =C22+C23 -> 15.5217 | D24: =D22+D23 -> 18.8884 | E24: =E22+E23 -> 23.0278 | F24: =F22+F23 -> 27.8195

Sheet Sinistres
A1: SINISTRES, FRAIS DE GESTION ET IBNR
B3: Y1 (2026) | C3: Y2 (2027) | D3: Y3 (2028) | E3: Y4 (2029) | F3: Y5 (2030)
A4: SINISTRES NON-VIE (par branche)
A5: Sinistres automobile (Md FCFA) | B5: =Portefeuille!B12*Hypothèses!B27 -> 4.913 | C5: =Portefeuille!C12*Hypothèses!C27 -> 5.643 | D5: =Portefeuille!D12*Hypothèses!D27 -> 6.5455 | E5: =Portefeuille!E12*Hypothèses!E27 -> 7.616 | F5: =Portefeuille!F12*Hypothèses!F27 -> 8.79795
A6: Sinistres entreprises (Md FCFA) | B6: =Portefeuille!B17*Hypothèses!B28 -> 1.63625 | C6: =Portefeuille!C17*Hypothèses!C28 -> 1.944 | D6: =Portefeuille!D17*Hypothèses!D28 -> 2.3161 | E6: =Portefeuille!E17*Hypothèses!E28 -> 2.756 | F6: =Portefeuille!F17*Hypothèses!F28 -> 3.26655
A7: Sinistres santé (Md FCFA) | B7: =Portefeuille!B22*Hypothèses!B29 -> 1.944 | C7: =Portefeuille!C22*Hypothèses!C29 -> 2.3856 | D7: =Portefeuille!D22*Hypothèses!D29 -> 2.856 | E7: =Portefeuille!E22*Hypothèses!E29 -> 3.4776 | F7: =Portefeuille!F22*Hypothèses!F29 -> 4.1344
A8: Sinistres Non-Vie totaux | B8: =B5+B6+B7 -> 8.49325 | C8: =C5+C6+C7 -> 9.9726 | D8: =D5+D6+D7 -> 11.7176 | E8: =E5+E6+E7 -> 13.8496 | F8: =F5+F6+F7 -> 16.1989
A10: SINISTRES VIE
A11: Sinistres Vie (Md FCFA) | B11: =Primes!B5*0.6 -> 2.7 | C11: =Primes!C5*0.6 -> 3.42 | D11: =Primes!D5*0.6 -> 4.32 | E11: =Primes!E5*0.6 -> 5.418 | F11: =Primes!F5*0.6 -> 6.732
A12: Total sinistres bruts | B12: =B8+B11 -> 11.19325 | C12: =C8+C11 -> 13.3926 | D12: =D8+D11 -> 16.0376 | E12: =E8+E11 -> 19.2676 | F12: =F8+F11 -> 22.9309
A14: IBNR & PSAP (Md FCFA)
A15: IBNR Non-Vie (sinistres tardifs) | B15: =B8*Hypothèses!B30 -> 1.01919 | C15: =C8*Hypothèses!C30 -> 1.196712 | D15: =D8*Hypothèses!D30 -> 1.406112 | E15: =E8*Hypothèses!E30 -> 1.661952 | F15: =F8*Hypothèses!F30 -> 1.943868
A16: PSAP (provision sinistres à payer) | B16: =B8*0.4 -> 3.3973 | C16: =C8*0.4 -> 3.98904 | D16: =D8*0.4 -> 4.68704 | E16: =E8*0.4 -> 5.53984 | F16: =F8*0.4 -> 6.47956
A17: Charge totale sinistres Non-Vie (avec IBNR) | B17: =B8+B15 -> 9.51244 | C17: =C8+C15 -> 11.169312 | D17: =D8+D15 -> 13.123712 | E17: =E8+E15 -> 15.511552 | F17: =F8+F15 -> 18.142768
A19: FRAIS DE GESTION DES SINISTRES
A20: Frais de gestion sinistres (Md FCFA) | B20: =B12*Hypothèses!B39 -> 0.5596625 | C20: =C12*Hypothèses!C39 -> 0.66963 | D20: =D12*Hypothèses!D39 -> 0.80188 | E20: =E12*Hypothèses!E39 -> 0.96338 | F20: =F12*Hypothèses!F39 -> 1.146545

Sheet Provisions techniques
A1: PROVISIONS TECHNIQUES — RÉGLEMENTATION CIMA
B3: Y1 (2026) | C3: Y2 (2027) | D3: Y3 (2028) | E3: Y4 (2029) | F3: Y5 (2030)
A4: PROVISIONS VIE — PROVISIONS MATHÉMATIQUES (PM)
A5: PM Vie début période (Md FCFA) | B5: 20 | C5: =B6 -> 21.15 | D5: =C6 -> 22.46025 | E5: =D6 -> 23.966359 | F5: =E6 -> 25.708181
A6: PM Vie fin période (Md FCFA) | B6: =B5*(1+Hypothèses!B15)+Primes!B5*0.7-Sinistres!B11 -> 21.15 | C6: =C5*(1+Hypothèses!C15)+Primes!C5*0.7-Sinistres!C11 -> 22.46025 | D6: =D5*(1+Hypothèses!D15)+Primes!D5*0.7-Sinistres!D11 -> 23.966359 | E6: =E5*(1+Hypothèses!E15)+Primes!E5*0.7-Sinistres!E11 -> 25.708181 | F6: =F5*(1+Hypothèses!F15)+Primes!F5*0.7-Sinistres!F11 -> 27.729968
A7: Variation PM (= dotation P&L) | B7: =B6-B5 -> 1.15 | C7: =C6-C5 -> 1.31025 | D7: =D6-D5 -> 1.5061088 | E7: =E6-E5 -> 1.7418226 | F7: =F6-F5 -> 2.0217863
A9: PROVISIONS NON-VIE
A10: PPNA (provision primes non acquises) | B10: =Primes!B6*0.08 -> 1.032 | C10: =Primes!C6*0.08 -> 1.2408 | D10: =Primes!D6*0.08 -> 1.4816 | E10: =Primes!E6*0.08 -> 1.7792 | F10: =Primes!F6*0.08 -> 2.116
A11: PSAP (provision sinistres à payer) | B11: =Sinistres!B16 -> 3.3973 | C11: =Sinistres!C16 -> 3.98904 | D11: =Sinistres!D16 -> 4.68704 | E11: =Sinistres!E16 -> 5.53984 | F11: =Sinistres!F16 -> 6.47956
A12: Provision pour risques en cours (PREC) | B12: =B10*0.05 -> 0.0516 | C12: =C10*0.05 -> 0.06204 | D12: =D10*0.05 -> 0.07408 | E12: =E10*0.05 -> 0.08896 | F12: =F10*0.05 -> 0.1058
A13: Total provisions Non-Vie | B13: =B10+B11+B12 -> 4.4809 | C13: =C10+C11+C12 -> 5.29188 | D13: =D10+D11+D12 -> 6.24272 | E13: =E10+E11+E12 -> 7.408 | F13: =F10+F11+F12 -> 8.70136
A15: TOTAL PROVISIONS TECHNIQUES
A16: Total provisions techniques (Vie + Non-Vie) | B16: =B6+B13 -> 25.6309 | C16: =C6+C13 -> 27.75213 | D16: =D6+D13 -> 30.209079 | E16: =E6+E13 -> 33.116181 | F16: =F6+F13 -> 36.431328

Sheet Placements
A1: PLACEMENTS — ALLOCATION & RENDEMENTS
B3: Y1 (2026) | C3: Y2 (2027) | D3: Y3 (2028) | E3: Y4 (2029) | F3: Y5 (2030)
A4: BASE DES PLACEMENTS
A5: Total placements (= PM + PSAP + Capital) | B5: ='Provisions techniques'!B16+Hypothèses!B59 -> 30.6309 | C5: ='Provisions techniques'!C16+Hypothèses!C59 -> 32.75213 | D5: ='Provisions techniques'!D16+Hypothèses!D59 -> 35.209079 | E5: ='Provisions techniques'!E16+Hypothèses!E59 -> 43.116181 | F5: ='Provisions techniques'!F16+Hypothèses!F59 -> 46.431328
A7: ALLOCATION DES PLACEMENTS (Md FCFA)
A8: Obligations d'État CIMA | B8: =B5*Hypothèses!B47 -> 13.783905 | C8: =C5*Hypothèses!C47 -> 14.738459 | D8: =D5*Hypothèses!D47 -> 15.844085 | E8: =E5*Hypothèses!E47 -> 19.402282 | F8: =F5*Hypothèses!F47 -> 20.894097
A9: Dépôts bancaires | B9: =B5*Hypothèses!B48 -> 6.12618 | C9: =C5*Hypothèses!C48 -> 6.550426 | D9: =D5*Hypothèses!D48 -> 7.0418157 | E9: =E5*Hypothèses!E48 -> 8.6232363 | F9: =F5*Hypothèses!F48 -> 9.2862655
A10: Immobilier | B10: =B5*Hypothèses!B49 -> 6.12618 | C10: =C5*Hypothèses!C49 -> 6.550426 | D10: =D5*Hypothèses!D49 -> 7.0418157 | E10: =E5*Hypothèses!E49 -> 8.6232363 | F10: =F5*Hypothèses!F49 -> 9.2862655
A11: Actions | B11: =B5*Hypothèses!B50 -> 3.06309 | C11: =C5*Hypothèses!C50 -> 3.275213 | D11: =D5*Hypothèses!D50 -> 3.5209079 | E11: =E5*Hypothèses!E50 -> 4.3116181 | F11: =F5*Hypothèses!F50 -> 4.6431328
A12: Autres placements | B12: =B5*Hypothèses!B51 -> 1.531545 | C12: =C5*Hypothèses!C51 -> 1.6376065 | D12: =D5*Hypothèses!D51 -> 1.7604539 | E12: =E5*Hypothèses!E51 -> 2.1558091 | F12: =F5*Hypothèses!F51 -> 2.3215664
A13: Total placements | B13: =SUM(B8:B12) -> 30.6309 | C13: =SUM(C8:C12) -> 32.75213 | D13: =SUM(D8:D12) -> 35.209079 | E13: =SUM(E8:E12) -> 43.116181 | F13: =SUM(F8:F12) -> 46.431328
A15: RENDEMENT DES PLACEMENTS (Md FCFA)
A16: Rendement obligations | B16: =B8*Hypothèses!B52 -> 0.75811478 | C16: =C8*Hypothèses!C52 -> 0.81061522 | D16: =D8*Hypothèses!D52 -> 0.79220427 | E16: =E8*Hypothèses!E52 -> 0.97011408 | F16: =F8*Hypothèses!F52 -> 0.94023438
A17: Rendement dépôts | B17: =B9*Hypothèses!B53 -> 0.2450472 | C17: =C9*Hypothèses!C53 -> 0.26201704 | D17: =D9*Hypothèses!D53 -> 0.267589 | E17: =E9*Hypothèses!E53 -> 0.32768298 | F17: =F9*Hypothèses!F53 -> 0.32501929
A18: Rendement immobilier | B18: =B10*Hypothèses!B54 -> 0.4288326 | C18: =C10*Hypothèses!C54 -> 0.45852982 | D18: =D10*Hypothèses!D54 -> 0.4929271 | E18: =E10*Hypothèses!E54 -> 0.60362654 | F18: =F10*Hypothèses!F54 -> 0.65003859
A19: Rendement actions | B19: =B11*Hypothèses!B55 -> 0.306309 | C19: =C11*Hypothèses!C55 -> 0.3275213 | D19: =D11*Hypothèses!D55 -> 0.35209079 | E19: =E11*Hypothèses!E55 -> 0.43116181 | F19: =F11*Hypothèses!F55 -> 0.46431328
A20: Rendement autres | B20: =B12*Hypothèses!B56 -> 0.068919525 | C20: =C12*Hypothèses!C56 -> 0.073692293 | D20: =D12*Hypothèses!D56 -> 0.079220427 | E20: =E12*Hypothèses!E56 -> 0.097011408 | F20: =F12*Hypothèses!F56 -> 0.10447049
A21: Total produits des placements | B21: =SUM(B16:B20) -> 1.8072231 | C21: =SUM(C16:C20) -> 1.9323757 | D21: =SUM(D16:D20) -> 1.9840316 | E21: =SUM(E16:E20) -> 2.4295968 | F21: =SUM(F16:F20) -> 2.484076
A22: Rendement global des placements (%) | B22: =IFERROR(B21/B13,0) -> 0.059 | C22: =IFERROR(C21/C13,0) -> 0.059 | D22: =IFERROR(D21/D13,0) -> 0.05635 | E22: =IFERROR(E21/E13,0) -> 0.05635 | F22: =IFERROR(F21/F13,0) -> 0.0535
A24: RTE (Règlement Trésor Exigible)
A25: Placements liquides (oblig + dépôts) | B25: =B8+B9 -> 19.910085 | C25: =C8+C9 -> 21.288885 | D25: =D8+D9 -> 22.885901 | E25: =E8+E9 -> 28.025518 | F25: =F8+F9 -> 30.180363
A26: Taux de couverture RTE (%) | B26: =IFERROR(B25/'Provisions techniques'!B16,0) -> 0.77680007 | C26: =IFERROR(C25/'Provisions techniques'!C16,0) -> 0.76710813 | D26: =IFERROR(D25/'Provisions techniques'!D16,0) -> 0.75758355 | E26: =IFERROR(E25/'Provisions techniques'!E16,0) -> 0.84627867 | F26: =IFERROR(F25/'Provisions techniques'!F16,0) -> 0.82841787

Sheet P_L technique
A1: COMPTE TECHNIQUE — VIE ET NON-VIE
B3: Y1 (2026) | C3: Y2 (2027) | D3: Y3 (2028) | E3: Y4 (2029) | F3: Y5 (2030)
A4: COMPTE TECHNIQUE VIE
A5: + Primes acquises nettes Vie | B5: =Primes!B22 -> 4.05 | C5: =Primes!C22 -> 5.13 | D5: =Primes!D22 -> 6.48 | E5: =Primes!E22 -> 8.127 | F5: =Primes!F22 -> 10.098
A6: + Produits des placements affectés Vie (70%) | B6: =Placements!B21*0.7 -> 1.2650562 | C6: =Placements!C21*0.7 -> 1.352663 | D6: =Placements!D21*0.7 -> 1.3888221 | E6: =Placements!E21*0.7 -> 1.7007178 | F6: =Placements!F21*0.7 -> 1.7388532
A7: - Sinistres Vie | B7: =-Sinistres!B11 -> -2.7 | C7: =-Sinistres!C11 -> -3.42 | D7: =-Sinistres!D11 -> -4.32 | E7: =-Sinistres!E11 -> -5.418 | F7: =-Sinistres!F11 -> -6.732
A8: - Variation PM | B8: =-'Provisions techniques'!B7 -> -1.15 | C8: =-'Provisions techniques'!C7 -> -1.31025 | D8: =-'Provisions techniques'!D7 -> -1.5061088 | E8: =-'Provisions techniques'!E7 -> -1.7418226 | F8: =-'Provisions techniques'!F7 -> -2.0217863
A9: - Frais d'acquisition Vie | B9: =-Primes!B5*Hypothèses!B36 -> -0.81 | C9: =-Primes!C5*Hypothèses!C36 -> -0.969 | D9: =-Primes!D5*Hypothèses!D36 -> -1.152 | E9: =-Primes!E5*Hypothèses!E36 -> -1.3545 | F9: =-Primes!F5*Hypothèses!F36 -> -1.5708
A10: - Frais d'administration Vie | B10: =-Primes!B5*Hypothèses!B38 -> -0.36 | C10: =-Primes!C5*Hypothèses!C38 -> -0.456 | D10: =-Primes!D5*Hypothèses!D38 -> -0.54 | E10: =-Primes!E5*Hypothèses!E38 -> -0.6321 | F10: =-Primes!F5*Hypothèses!F38 -> -0.7854
A11: Résultat technique Vie | B11: =B5+B6+B7+B8+B9+B10 -> 0.29505617 | C11: =C5+C6+C7+C8+C9+C10 -> 0.32741297 | D11: =D5+D6+D7+D8+D9+D10 -> 0.35071336 | E11: =E5+E6+E7+E8+E9+E10 -> 0.68129522 | F11: =F5+F6+F7+F8+F9+F10 -> 0.72686687
A13: COMPTE TECHNIQUE NON-VIE
A14: + Primes acquises nettes Non-Vie | B14: =Primes!B23 -> 8.643 | C14: =Primes!C23 -> 10.3917 | D14: =Primes!D23 -> 12.4084 | E14: =Primes!E23 -> 14.9008 | F14: =Primes!F23 -> 17.7215
A15: + Produits des placements affectés Non-Vie (30%) | B15: =Placements!B21*0.3 -> 0.54216693 | C15: =Placements!C21*0.3 -> 0.5797127 | D15: =Placements!D21*0.3 -> 0.59520948 | E15: =Placements!E21*0.3 -> 0.72887904 | F15: =Placements!F21*0.3 -> 0.74522281
A16: - Sinistres Non-Vie + IBNR | B16: =-Sinistres!B17 -> -9.51244 | C16: =-Sinistres!C17 -> -11.169312 | D16: =-Sinistres!D17 -> -13.123712 | E16: =-Sinistres!E17 -> -15.511552 | F16: =-Sinistres!F17 -> -18.142768
A17: + Commission de réassurance perçue | B17: =Primes!B19 -> 0.91875 | C17: =Primes!C19 -> 1.111875 | D17: =Primes!D19 -> 1.3375 | E17: =Primes!E19 -> 1.61575 | F17: =Primes!F19 -> 1.933625
A18: - Frais d'acquisition Non-Vie | B18: =-Primes!B6*Hypothèses!B37 -> -2.58 | C18: =-Primes!C6*Hypothèses!C37 -> -2.9469 | D18: =-Primes!D6*Hypothèses!D37 -> -3.3336 | E18: =-Primes!E6*Hypothèses!E37 -> -4.0032 | F18: =-Primes!F6*Hypothèses!F37 -> -4.4965
A19: - Frais d'administration Non-Vie | B19: =-Primes!B6*Hypothèses!B38 -> -1.032 | C19: =-Primes!C6*Hypothèses!C38 -> -1.2408 | D19: =-Primes!D6*Hypothèses!D38 -> -1.389 | E19: =-Primes!E6*Hypothèses!E38 -> -1.5568 | F19: =-Primes!F6*Hypothèses!F38 -> -1.8515
A20: - Frais de gestion sinistres | B20: =-Sinistres!B20 -> -0.5596625 | C20: =-Sinistres!C20 -> -0.66963 | D20: =-Sinistres!D20 -> -0.80188 | E20: =-Sinistres!E20 -> -0.96338 | F20: =-Sinistres!F20 -> -1.146545
A21: Résultat technique Non-Vie | B21: =B14+B15+B16+B17+B18+B19+B20 -> -3.5801856 | C21: =C14+C15+C16+C17+C18+C19+C20 -> -3.9433543 | D21: =D14+D15+D16+D17+D18+D19+D20 -> -4.3070825 | E21: =E14+E15+E16+E17+E18+E19+E20 -> -4.789503 | F21: =F14+F15+F16+F17+F18+F19+F20 -> -5.2369652
A23: RÉSULTAT TECHNIQUE TOTAL
A24: Résultat technique consolidé (Vie + Non-Vie) | B24: =B11+B21 -> -3.2851294 | C24: =C11+C21 -> -3.6159413 | D24: =D11+D21 -> -3.9563692 | E24: =E11+E21 -> -4.1082077 | F24: =F11+F21 -> -4.5100983

Sheet P_L global
A1: COMPTE DE RÉSULTAT GLOBAL
B3: Y1 (2026) | C3: Y2 (2027) | D3: Y3 (2028) | E3: Y4 (2029) | F3: Y5 (2030)
A4: RÉSULTAT TECHNIQUE
A5: Résultat technique (Vie + Non-Vie) | B5: ='P_L technique'!B24 -> -3.2851294 | C5: ='P_L technique'!C24 -> -3.6159413 | D5: ='P_L technique'!D24 -> -3.9563692 | E5: ='P_L technique'!E24 -> -4.1082077 | F5: ='P_L technique'!F24 -> -4.5100983
A7: RÉSULTAT NON-TECHNIQUE
A8: Autres charges générales (siège, IT, conseil) | B8: -2.5 | C8: -2.7 | D8: -2.9 | E8: -3.1 | F8: -3.3
A9: Charges financières (intérêts dette) | B9: -0.3 | C9: -0.3 | D9: -0.3 | E9: -0.3 | F9: -0.3
A10: Résultat non-technique | B10: =B8+B9 -> -2.8 | C10: =C8+C9 -> -3 | D10: =D8+D9 -> -3.2 | E10: =E8+E9 -> -3.4 | F10: =F8+F9 -> -3.6
A12: RÉSULTAT NET
A13: Résultat avant impôt | B13: =B5+B10 -> -6.0851294 | C13: =C5+C10 -> -6.6159413 | D13: =D5+D10 -> -7.1563692 | E13: =E5+E10 -> -7.5082077 | F13: =F5+F10 -> -8.1100983
A14: Impôt sur les sociétés | B14: =-MAX(B13,0)*Hypothèses!B6 -> 0 | C14: =-MAX(C13,0)*Hypothèses!C6 -> 0 | D14: =-MAX(D13,0)*Hypothèses!D6 -> 0 | E14: =-MAX(E13,0)*Hypothèses!E6 -> 0 | F14: =-MAX(F13,0)*Hypothèses!F6 -> 0
A15: RÉSULTAT NET | B15: =B13+B14 -> -6.0851294 | C15: =C13+C14 -> -6.6159413 | D15: =D13+D14 -> -7.1563692 | E15: =E13+E14 -> -7.5082077 | F15: =F13+F14 -> -8.1100983

Sheet Bilan
A1: BILAN ASSURANCE
B3: Y1 (2026) | C3: Y2 (2027) | D3: Y3 (2028) | E3: Y4 (2029) | F3: Y5 (2030)
A4: ACTIF (Md FCFA)
A5: Placements totaux | B5: =Placements!B13 -> 30.6309 | C5: =Placements!C13 -> 32.75213 | D5: =Placements!D13 -> 35.209079 | E5: =Placements!E13 -> 43.116181 | F5: =Placements!F13 -> 46.431328
A6: Créances sur assurés & intermédiaires (15% primes) | B6: =Primes!B7*0.15 -> 2.61 | C6: =Primes!C7*0.15 -> 3.1815 | D6: =Primes!D7*0.15 -> 3.858 | E6: =Primes!E7*0.15 -> 4.6905 | F6: =Primes!F7*0.15 -> 5.6505
A7: Créances sur réassureurs (20% cessions) | B7: =Primes!B18*0.2 -> 0.735 | C7: =Primes!C18*0.2 -> 0.8895 | D7: =Primes!D18*0.2 -> 1.07 | E7: =Primes!E18*0.2 -> 1.2926 | F7: =Primes!F18*0.2 -> 1.5469
A8: Immobilisations nettes | B8: 3 | C8: 3.5 | D8: 4 | E8: 4.5 | F8: 5
A9: Trésorerie & équivalents | B9: 2 | C9: 2.5 | D9: 3 | E9: 3.5 | F9: 4
A10: TOTAL ACTIF | B10: =B5+B6+B7+B8+B9 -> 38.9759 | C10: =C5+C6+C7+C8+C9 -> 42.82313 | D10: =D5+D6+D7+D8+D9 -> 47.137079 | E10: =E5+E6+E7+E8+E9 -> 57.099281 | F10: =F5+F6+F7+F8+F9 -> 62.628728
A12: PASSIF (Md FCFA)
A13: Provisions techniques (PM + PSAP + PPNA + PREC) | B13: ='Provisions techniques'!B16 -> 25.6309 | C13: ='Provisions techniques'!C16 -> 27.75213 | D13: ='Provisions techniques'!D16 -> 30.209079 | E13: ='Provisions techniques'!E16 -> 33.116181 | F13: ='Provisions techniques'!F16 -> 36.431328
A14: Dettes envers réassureurs | B14: 1.5 | C14: 1.8 | D14: 2.1 | E14: 2.4 | F14: 2.7
A15: Autres dettes | B15: 1 | C15: 1.1 | D15: 1.2 | E15: 1.3 | F15: 1.4
A16: Capital social | B16: =Hypothèses!B59 -> 5 | C16: =Hypothèses!C59 -> 5 | D16: =Hypothèses!D59 -> 5 | E16: =Hypothèses!E59 -> 10 | F16: =Hypothèses!F59 -> 10
A17: Réserves | B17: 2 | C17: =B17+'P_L global'!B15*(1-Hypothèses!B60) -> -2.2595906 | D17: =C17+'P_L global'!C15*(1-Hypothèses!C60) -> -6.5599524 | E17: =D17+'P_L global'!D15*(1-Hypothèses!D60) -> -10.853774 | F17: =E17+'P_L global'!E15*(1-Hypothèses!E60) -> -14.983288
A18: Résultat de l'exercice | B18: ='P_L global'!B15 -> -6.0851294 | C18: ='P_L global'!C15 -> -6.6159413 | D18: ='P_L global'!D15 -> -7.1563692 | E18: ='P_L global'!E15 -> -7.5082077 | F18: ='P_L global'!F15 -> -8.1100983
A19: Total capitaux propres | B19: =B16+B17+B18 -> 0.9148706 | C19: =C16+C17+C18 -> -3.8755319 | D19: =D16+D17+D18 -> -8.7163216 | E19: =E16+E17+E18 -> -8.3619817 | F19: =F16+F17+F18 -> -13.093387
A20: TOTAL PASSIF | B20: =B13+B14+B15+B19 -> 29.045771 | C20: =C13+C14+C15+C19 -> 26.776598 | D20: =D13+D14+D15+D19 -> 24.792757 | E20: =E13+E14+E15+E19 -> 28.4542 | F20: =F13+F14+F15+F19 -> 27.437941
A22: CONTRÔLE ÉQUILIBRE
A23: Écart actif - passif | B23: =B10-B20 -> 9.9301294 | C23: =C10-C20 -> 16.046532 | D23: =D10-D20 -> 22.344322 | E23: =E10-E20 -> 28.645082 | F23: =F10-F20 -> 35.190787

Sheet Marge solvabilité
A1: MARGE DE SOLVABILITÉ — RÉGLEMENTATION CIMA
B3: Y1 (2026) | C3: Y2 (2027) | D3: Y3 (2028) | E3: Y4 (2029) | F3: Y5 (2030)
A4: MARGE MINIMALE EXIGÉE
A5: Min. Non-Vie = max(16% primes, 23% sinistres) | B5: =MAX(Primes!B6*0.18,Sinistres!B8*0.26) -> 2.322 | C5: =MAX(Primes!C6*0.18,Sinistres!C8*0.26) -> 2.7918 | D5: =MAX(Primes!D6*0.18,Sinistres!D8*0.26) -> 3.3336 | E5: =MAX(Primes!E6*0.18,Sinistres!E8*0.26) -> 4.0032 | F5: =MAX(Primes!F6*0.18,Sinistres!F8*0.26) -> 4.761
A6: Min. Vie = 4% des PM | B6: ='Provisions techniques'!B6*0.04 -> 0.846 | C6: ='Provisions techniques'!C6*0.04 -> 0.89841 | D6: ='Provisions techniques'!D6*0.04 -> 0.95865435 | E6: ='Provisions techniques'!E6*0.04 -> 1.0283273 | F6: ='Provisions techniques'!F6*0.04 -> 1.1091987
A7: Marge minimale totale exigée | B7: =B5+B6 -> 3.168 | C7: =C5+C6 -> 3.69021 | D7: =D5+D6 -> 4.2922544 | E7: =E5+E6 -> 5.0315273 | F7: =F5+F6 -> 5.8701987
A9: MARGE CONSTITUÉE
A10: Capitaux propres (Bilan) | B10: =Bilan!B19 -> 0.9148706 | C10: =Bilan!C19 -> -3.8755319 | D10: =Bilan!D19 -> -8.7163216 | E10: =Bilan!E19 -> -8.3619817 | F10: =Bilan!F19 -> -13.093387
A11: Marge constituée totale | B11: =B10 -> 0.9148706 | C11: =C10 -> -3.8755319 | D11: =D10 -> -8.7163216 | E11: =E10 -> -8.3619817 | F11: =F10 -> -13.093387
A13: RATIO DE COUVERTURE
A14: Ratio marge constituée / marge minimale | B14: =IFERROR(B11/B7,0) -> 0.28878491 | C14: =IFERROR(C11/C7,0) -> -1.0502199 | D14: =IFERROR(D11/D7,0) -> -2.0307095 | E14: =IFERROR(E11/E7,0) -> -1.6619172 | F14: =IFERROR(F11/F7,0) -> -2.2304844
A15: Seuil réglementaire CIMA | B15: 1 | C15: 1 | D15: 1 | E15: 1 | F15: 1
A16: Excédent / Insuffisance (Md FCFA) | B16: =B11-B7 -> -2.2531294 | C16: =C11-C7 -> -7.5657419 | D16: =D11-D7 -> -13.008576 | E16: =E11-E7 -> -13.393509 | F16: =F11-F7 -> -18.963585

Sheet KPIs
A1: TABLEAU DE BORD — INDICATEURS CLÉS
B3: Y1 (2026) | C3: Y2 (2027) | D3: Y3 (2028) | E3: Y4 (2029) | F3: Y5 (2030)
A4: 1. VOLUME & CROISSANCE
A5: Total primes émises (Md FCFA) | B5: =Primes!B7 -> 17.4 | C5: =Primes!C7 -> 21.21 | D5: =Primes!D7 -> 25.72 | E5: =Primes!E7 -> 31.27 | F5: =Primes!F7 -> 37.67
A6: Croissance primes (%) | B6: - | C6: =IFERROR(Primes!C7/Primes!B7-1,0) -> 0.21896552 | D6: =IFERROR(Primes!D7/Primes!C7-1,0) -> 0.21263555 | E6: =IFERROR(Primes!E7/Primes!D7-1,0) -> 0.21578538 | F6: =IFERROR(Primes!F7/Primes!E7-1,0) -> 0.20466901
A7: Part Vie / total | B7: =IFERROR(Primes!B5/Primes!B7,0) -> 0.25862069 | C7: =IFERROR(Primes!C5/Primes!C7,0) -> 0.26874116 | D7: =IFERROR(Primes!D5/Primes!D7,0) -> 0.27993779 | E7: =IFERROR(Primes!E5/Primes!E7,0) -> 0.28877518 | F7: =IFERROR(Primes!F5/Primes!F7,0) -> 0.29784975
A9: 2. RENTABILITÉ TECHNIQUE NON-VIE
A10: Loss ratio Non-Vie | B10: =IFERROR(Sinistres!B17/Primes!B11,0) -> 0.80152005 | C10: =IFERROR(Sinistres!C17/Primes!C11,0) -> 0.78275671 | D10: =IFERROR(Sinistres!D17/Primes!D11,0) -> 0.77024322 | E10: =IFERROR(Sinistres!E17/Primes!E11,0) -> 0.75811073 | F10: =IFERROR(Sinistres!F17/Primes!F11,0) -> 0.74557278
A11: Expense ratio Non-Vie | B11: =IFERROR((Primes!B6*(Hypothèses!B37+Hypothèses!B38)+Sinistres!B20)/Primes!B11,0) -> 0.3515051 | C11: =IFERROR((Primes!C6*(Hypothèses!C37+Hypothèses!C38)+Sinistres!C20)/Primes!C11,0) -> 0.34040661 | D11: =IFERROR((Primes!D6*(Hypothèses!D37+Hypothèses!D38)+Sinistres!D20)/Primes!D11,0) -> 0.32423702 | E11: =IFERROR((Primes!E6*(Hypothèses!E37+Hypothèses!E38)+Sinistres!E20)/Primes!E11,0) -> 0.31882331 | F11: =IFERROR((Primes!F6*(Hypothèses!F37+Hypothèses!F38)+Sinistres!F20)/Primes!F11,0) -> 0.30798656
A12: Ratio combiné Non-Vie | B12: =B10+B11 -> 1.1530252 | C12: =C10+C11 -> 1.1231633 | D12: =D10+D11 -> 1.0944802 | E12: =E10+E11 -> 1.076934 | F12: =F10+F11 -> 1.0535593
A14: 3. RENTABILITÉ GLOBALE
A15: Résultat technique Vie (Md FCFA) | B15: ='P_L technique'!B11 -> 0.29505617 | C15: ='P_L technique'!C11 -> 0.32741297 | D15: ='P_L technique'!D11 -> 0.35071336 | E15: ='P_L technique'!E11 -> 0.68129522 | F15: ='P_L technique'!F11 -> 0.72686687
A16: Résultat technique Non-Vie (Md FCFA) | B16: ='P_L technique'!B21 -> -3.5801856 | C16: ='P_L technique'!C21 -> -3.9433543 | D16: ='P_L technique'!D21 -> -4.3070825 | E16: ='P_L technique'!E21 -> -4.789503 | F16: ='P_L technique'!F21 -> -5.2369652
A17: Résultat net (Md FCFA) | B17: ='P_L global'!B15 -> -6.0851294 | C17: ='P_L global'!C15 -> -6.6159413 | D17: ='P_L global'!D15 -> -7.1563692 | E17: ='P_L global'!E15 -> -7.5082077 | F17: ='P_L global'!F15 -> -8.1100983
A18: Marge nette (RN / primes) | B18: =IFERROR(B17/Primes!B7,0) -> -0.34972008 | C18: =IFERROR(C17/Primes!C7,0) -> -0.31192557 | D18: =IFERROR(D17/Primes!D7,0) -> -0.27824141 | E18: =IFERROR(E17/Primes!E7,0) -> -0.24010898 | F18: =IFERROR(F17/Primes!F7,0) -> -0.21529329
A19: ROE | B19: =IFERROR(B17/Bilan!B19,0) -> -6.6513553 | C19: =IFERROR(C17/((Bilan!B19+Bilan!C19)/2),0) -> 4.4692321 | D19: =IFERROR(D17/((Bilan!C19+Bilan!D19)/2),0) -> 1.1366665 | E19: =IFERROR(E17/((Bilan!D19+Bilan!E19)/2),0) -> 0.87926858 | F19: =IFERROR(F17/((Bilan!E19+Bilan!F19)/2),0) -> 0.75599712
A21: 4. PORTEFEUILLE VIE
A22: Taux de chute (lapse) | B22: =Hypothèses!B13 -> 0.08 | C22: =Hypothèses!C13 -> 0.08 | D22: =Hypothèses!D13 -> 0.075 | E22: =Hypothèses!E13 -> 0.07 | F22: =Hypothèses!F13 -> 0.07
A23: Taux de persistance Vie | B23: =1-Hypothèses!B13 -> 0.92 | C23: =1-Hypothèses!C13 -> 0.92 | D23: =1-Hypothèses!D13 -> 0.925 | E23: =1-Hypothèses!E13 -> 0.93 | F23: =1-Hypothèses!F13 -> 0.93
A25: 5. PLACEMENTS
A26: Rendement global placements | B26: =IFERROR(Placements!B21/Placements!B13,0) -> 0.059 | C26: =IFERROR(Placements!C21/Placements!C13,0) -> 0.059 | D26: =IFERROR(Placements!D21/Placements!D13,0) -> 0.05635 | E26: =IFERROR(Placements!E21/Placements!E13,0) -> 0.05635 | F26: =IFERROR(Placements!F21/Placements!F13,0) -> 0.0535
A27: RTE / Engagements | B27: =IFERROR(Placements!B25/'Provisions techniques'!B16,0) -> 0.77680007 | C27: =IFERROR(Placements!C25/'Provisions techniques'!C16,0) -> 0.76710813 | D27: =IFERROR(Placements!D25/'Provisions techniques'!D16,0) -> 0.75758355 | E27: =IFERROR(Placements!E25/'Provisions techniques'!E16,0) -> 0.84627867 | F27: =IFERROR(Placements!F25/'Provisions techniques'!F16,0) -> 0.82841787
A29: 6. SOLVABILITÉ CIMA
A30: Ratio marge solvabilité | B30: ='Marge solvabilité'!B14 -> 0.28878491 | C30: ='Marge solvabilité'!C14 -> -1.0502199 | D30: ='Marge solvabilité'!D14 -> -2.0307095 | E30: ='Marge solvabilité'!E14 -> -1.6619172 | F30: ='Marge solvabilité'!F14 -> -2.2304844

Sheet Stress tests
A1: STRESS TESTS PRUDENTIELS
B3: Y1 (2026) | C3: Y2 (2027) | D3: Y3 (2028) | E3: Y4 (2029) | F3: Y5 (2030)
A4: RÉFÉRENCE
A5: Résultat net de base (Md FCFA) | B5: ='P_L global'!B15 -> -6.0851294 | C5: ='P_L global'!C15 -> -6.6159413 | D5: ='P_L global'!D15 -> -7.1563692 | E5: ='P_L global'!E15 -> -7.5082077 | F5: ='P_L global'!F15 -> -8.1100983
A6: Ratio combiné de base | B6: =KPIs!B12 -> 1.1530252 | C6: =KPIs!C12 -> 1.1231633 | D6: =KPIs!D12 -> 1.0944802 | E6: =KPIs!E12 -> 1.076934 | F6: =KPIs!F12 -> 1.0535593
A8: STRESS 1 — CHOC SINISTRALITÉ (loss ratio +10pts)
A9: Sinistres stressés Non-Vie (+10pts) | B9: =Sinistres!B17+Primes!B11*0.1 -> 10.69924 | C9: =Sinistres!C17+Primes!C11*0.1 -> 12.596232 | D9: =Sinistres!D17+Primes!D11*0.1 -> 14.827552 | E9: =Sinistres!E17+Primes!E11*0.1 -> 17.557632 | F9: =Sinistres!F17+Primes!F11*0.1 -> 20.576168
A10: Impact RN (Md FCFA) | B10: =-Primes!B11*0.1*(1-Hypothèses!B6) -> -0.83076 | C10: =-Primes!C11*0.1*(1-Hypothèses!C6) -> -0.998844 | D10: =-Primes!D11*0.1*(1-Hypothèses!D6) -> -1.192688 | E10: =-Primes!E11*0.1*(1-Hypothèses!E6) -> -1.432256 | F10: =-Primes!F11*0.1*(1-Hypothèses!F6) -> -1.70338
A11: RN stressé | B11: =B5+B10 -> -6.9158894 | C11: =C5+C10 -> -7.6147853 | D11: =D5+D10 -> -8.3490572 | E11: =E5+E10 -> -8.9404637 | F11: =F5+F10 -> -9.8134783
A13: STRESS 2 — CHOC RENDEMENT PLACEMENTS (-200 bps)
A14: Perte rendement placements (-2%) | B14: =-Placements!B13*0.02 -> -0.612618 | C14: =-Placements!C13*0.02 -> -0.6550426 | D14: =-Placements!D13*0.02 -> -0.70418158 | E14: =-Placements!E13*0.02 -> -0.86232363 | F14: =-Placements!F13*0.02 -> -0.92862655
A15: Impact RN (après IS) | B15: =-Placements!B13*0.02*(1-Hypothèses!B6) -> -0.4288326 | C15: =-Placements!C13*0.02*(1-Hypothèses!C6) -> -0.45852982 | D15: =-Placements!D13*0.02*(1-Hypothèses!D6) -> -0.4929271 | E15: =-Placements!E13*0.02*(1-Hypothèses!E6) -> -0.60362654 | F15: =-Placements!F13*0.02*(1-Hypothèses!F6) -> -0.65003859
A17: STRESS 3 — VAGUE DE RACHATS VIE (+50%)
A18: Rachats supplémentaires (% PM) | B18: ='Provisions techniques'!B6*Hypothèses!B14*0.5 -> 0.6345 | C18: ='Provisions techniques'!C6*Hypothèses!C14*0.5 -> 0.6738075 | D18: ='Provisions techniques'!D6*Hypothèses!D14*0.5 -> 0.65907487 | E18: ='Provisions techniques'!E6*Hypothèses!E14*0.5 -> 0.64270453 | F18: ='Provisions techniques'!F6*Hypothèses!F14*0.5 -> 0.69324919
A19: Besoin de liquidité Vie (Md FCFA) | B19: =B18 -> 0.6345 | C19: =C18 -> 0.6738075 | D19: =D18 -> 0.65907487 | E19: =E18 -> 0.64270453 | F19: =F18 -> 0.69324919

Sheet Scénarios
A1: VUE COMPARÉE — SCÉNARIOS PESS/BASE/OPT
A3: Note : Vue synthétique. Les scénarios pessimiste et optimiste sont des sensibilités appliquées au scénario de base (Y5).
A5: KPI | B5: Pessimiste (Y5) | C5: Base (Y5) | D5: Optimiste (Y5) | F5: Sensibilité
A6: Primes Y5 (Md FCFA) | B6: =Primes!F7*0.85 -> 32.0195 | C6: =Primes!F7 -> 37.67 | D6: =Primes!F7*1.15 -> 43.3205 | F6: ±15%
A7: Résultat net Y5 (Md FCFA) | B7: ='P_L global'!F15*0.5 -> -4.0550492 | C7: ='P_L global'!F15 -> -8.1100983 | D7: ='P_L global'!F15*1.4 -> -11.354138 | F7: -50%/+40%
A8: Ratio combiné Y5 | B8: =KPIs!F12*1.1 -> 1.1589153 | C8: =KPIs!F12 -> 1.0535593 | D8: =KPIs!F12*0.93 -> 0.97981019 | F8: +10%/-7%
A9: ROE Y5 | B9: =KPIs!F19*0.5 -> 0.37799856 | C9: =KPIs!F19 -> 0.75599712 | D9: =KPIs!F19*1.4 -> 1.058396 | F9: -50%/+40%
A10: Marge solvabilité Y5 | B10: ='Marge solvabilité'!F14*0.75 -> -1.6728633 | C10: ='Marge solvabilité'!F14 -> -2.2304844 | D10: ='Marge solvabilité'!F14*1.2 -> -2.6765813 | F10: ±20-25%
A13: MÉTHODOLOGIE
A14: Pessimiste : sinistralité dégradée (+10pts loss ratio), baisse rendement placements (-200 bps), baisse souscription -15%.
A15: Optimiste : meilleure sélection (loss ratio -7pts), hausse rendement placements, gains de parts de marché.
