Workbook

Sheet 1. Notice
A1: MODÈLE FINANCIER FINTECH — Notice d'utilisation
A3: Objet du modèle
A5: Ce classeur modélise les revenus, charges et indicateurs de rentabilité d'une startup fintech
A6: opérant en zone UEMOA/CEMAC, sur 3 lignes de produits :
A7: • Transferts agent : Bank-to-Wallet (B2W) et Wallet-to-Bank (W2B)
A8: • Carte bancaire intégrée (émission, encours, transactions)
A9: • Achat de services (paiement marchand, bill payment, top-up)
A11: Horizon : 36 mois (Année 1 mensuelle + Années 2 et 3 trimestrielles consolidées)
A13: Structure du classeur
A15: Feuille | B15: Description
A16: 1. Notice | B16: Mode d'emploi et conventions
A17: 2. Hypothèses | B17: TOUTES les hypothèses pilotables (volumes, tarifs, coûts unitaires, %)
A18: 3. Revenus | B18: Modélisation détaillée du chiffre d'affaires par ligne de produit
A19: 4. Coûts variables | B19: Coûts directs proportionnels au volume d'activité
A20: 5. Charges fixes | B20: Masse salariale, loyers, IT, marketing, frais généraux
A21: 6. CAPEX & Amort. | B21: Investissements et plan d'amortissement
A22: 7. P&L | B22: Compte de résultat mensuel + annuel (3 ans)
A23: 8. Trésorerie | B23: Plan de trésorerie mensuel avec BFR
A24: 9. KPIs & Dashboard | B24: Indicateurs clés : CAC, LTV, marge contributive, break-even, runway
A25: 10. Scénarios | B25: Sensibilité : Pessimiste / Base / Optimiste
A28: Code couleurs des cellules
A29: Bleu sur fond jaune | B29: Valeur d'entrée modifiable (hypothèse)
A30: Noir | B30: Formule de calcul
A31: Vert | B31: Lien vers une autre feuille du classeur
A32: Blanc sur fond marine | B32: Total / sous-total

Sheet 2. Hypothèses
A1: HYPOTHÈSES DU MODÈLE — Toutes valeurs modifiables
A3: Paramètre | B3: Unité | C3: Année 1 | D3: Année 2 | E3: Année 3 | F3: Commentaire / Source
A4: 1. Hypothèses macro & monétaires
A5: Taux de change FCFA / USD | B5: FCFA | C5: 600 | D5: 605 | E5: 610 | F5: Référence BCEAO
A6: Inflation annuelle UEMOA | B6: % | C6: 0.035 | D6: 0.03 | E6: 0.03 | F6: Source : BCEAO – moyenne zone
A7: Taux d'impôt sur les sociétés (IS) | B7: % | C7: 0.3 | D7: 0.3 | E7: 0.3 | F7: Taux moyen UEMOA
A8: TVA collectée applicable | B8: % | C8: 0.18 | D8: 0.18 | E8: 0.18 | F8: Taux standard zone UEMOA
A9: 2. Acquisition & base utilisateurs
A10: Utilisateurs actifs au mois 1 (M1) | B10: users | C10: 5000 | D10: 0 | E10: 0 | F10: Base de départ (pré-lancement / soft launch)
A11: Acquisition nouveaux users / mois (Y1) | B11: users/mois | C11: 3500 | D11: 0 | E11: 0 | F11: Croissance organique + marketing
A12: Acquisition nouveaux users / mois (Y2) | B12: users/mois | C12: 0 | D12: 7500 | E12: 0 | F12: Accélération post-PMF
A13: Acquisition nouveaux users / mois (Y3) | B13: users/mois | C13: 0 | D13: 0 | E13: 12000 | F13: Scale-up régional
A14: Taux d'attrition mensuel (churn) | B14: % | C14: 0.035 | D14: 0.025 | E14: 0.02 | F14: Benchmark fintech Afrique
A15: Taux d'activation (MAU/Total) | B15: % | C15: 0.55 | D15: 0.62 | E15: 0.68 | F15: Utilisateurs actifs / inscrits
A16: 3. Ligne 1 — Transferts agent (Bank↔Wallet)
A17: Transactions B2W / user actif / mois | B17: tx | C17: 3.5 | D17: 4.5 | E17: 5.5 | F17: Bank-to-Wallet
A18: Montant moyen transaction B2W | B18: FCFA | C18: 25000 | D18: 28000 | E18: 30000 | F18: Ticket moyen
A19: Commission B2W (% montant) | B19: % | C19: 0.015 | D19: 0.015 | E19: 0.014 | F19: 1,5% – aligné concurrents
A20: Commission minimum B2W | B20: FCFA | C20: 100 | D20: 100 | E20: 100 | F20: Plancher
A21: Transactions W2B / user actif / mois | B21: tx | C21: 1.8 | D21: 2.5 | E21: 3.2 | F21: Wallet-to-Bank
A22: Montant moyen transaction W2B | B22: FCFA | C22: 35000 | D22: 40000 | E22: 45000 | F22: Ticket moyen
A23: Commission W2B (% montant) | B23: % | C23: 0.018 | D23: 0.018 | E23: 0.017 | F23: 1,8% (sortie wallet)
A24: Commission minimum W2B | B24: FCFA | C24: 150 | D24: 150 | E24: 150 | F24: Plancher
A25: Coût bancaire interchange (% volume) | B25: % | C25: 0.004 | D25: 0.0035 | E25: 0.003 | F25: Frais banque partenaire
A26: Commission agent réseau (% revenu) | B26: % | C26: 0.4 | D26: 0.38 | E26: 0.35 | F26: Rétrocession agent
A27: Coût SMS notification / transaction | B27: FCFA | C27: 12 | D27: 11 | E27: 10 | F27: OTP + confirmation
A28: 4. Ligne 2 — Carte bancaire intégrée
A29: Taux de pénétration carte (% users actifs) | B29: % | C29: 0.12 | D29: 0.22 | E29: 0.35 | F29: Adoption progressive
A30: Frais d'émission carte (one-shot) | B30: FCFA | C30: 2500 | D30: 2500 | E30: 2000 | F30: Facturé à la commande
A31: Abonnement mensuel carte | B31: FCFA | C31: 500 | D31: 500 | E31: 500 | F31: Tenue de compte carte
A32: Transactions carte / porteur / mois | B32: tx | C32: 8 | D32: 12 | E32: 16 | F32: Achats POS + e-commerce
A33: Montant moyen transaction carte | B33: FCFA | C33: 12000 | D33: 14000 | E33: 16000 | F33: Ticket moyen achat
A34: Commission interchange reçue (MDR) | B34: % | C34: 0.012 | D34: 0.012 | E34: 0.012 | F34: Part émetteur sur MDR
A35: Coût fabrication carte physique | B35: FCFA | C35: 1500 | D35: 1400 | E35: 1300 | F35: Plastique + personnalisation
A36: Frais scheme (Visa/Mastercard) /tx | B36: FCFA | C36: 25 | D36: 24 | E36: 22 | F36: Frais réseau
A37: Coût processing /tx | B37: FCFA | C37: 18 | D37: 17 | E37: 15 | F37: Processeur (TPS, etc.)
A38: 5. Ligne 3 — Achat de services (bill, top-up, marchand)
A39: Transactions services / user actif / mois | B39: tx | C39: 4.5 | D39: 6 | E39: 8 | F39: Bill pay + airtime + marchand
A40: Montant moyen transaction service | B40: FCFA | C40: 4500 | D40: 5000 | E40: 5500 | F40: Ticket moyen
A41: Commission service (% montant) | B41: % | C41: 0.02 | D41: 0.02 | E41: 0.019 | F41: 2% côté utilisateur
...

Sheet 3. Revenus
A1: MODÉLISATION DES REVENUS — 36 mois
B2: Année 1 (mensuel)
A3: Poste | B3: M1 | C3: M2 | D3: M3 | E3: M4 | F3: M5 | G3: M6 | H3: M7 | I3: M8 | J3: M9 | K3: M10 | L3: M11 | M3: M12 | N3: Total Y1 | O3: Année 2 | P3: Année 3 | Q3: Total 3 ans
A5: A. Base utilisateurs
A6: Utilisateurs inscrits (cumul fin de mois) | B6: ='2. Hypothèses'!$C$10+'2. Hypothèses'!$C$11 -> 8500 | C6: =B6*(1-'2. Hypothèses'!$C$14)+'2. Hypothèses'!$C$11 -> 11702.5 | D6: =C6*(1-'2. Hypothèses'!$C$14)+'2. Hypothèses'!$C$11 -> 14792.913 | E6: =D6*(1-'2. Hypothèses'!$C$14)+'2. Hypothèses'!$C$11 -> 17775.161 | F6: =E6*(1-'2. Hypothèses'!$C$14)+'2. Hypothèses'!$C$11 -> 20653.03 | G6: =F6*(1-'2. Hypothèses'!$C$14)+'2. Hypothèses'!$C$11 -> 23430.174 | H6: =G6*(1-'2. Hypothèses'!$C$14)+'2. Hypothèses'!$C$11 -> 26110.118 | I6: =H6*(1-'2. Hypothèses'!$C$14)+'2. Hypothèses'!$C$11 -> 28696.264 | J6: =I6*(1-'2. Hypothèses'!$C$14)+'2. Hypothèses'!$C$11 -> 31191.894 | ... M6: =L6*(1-'2. Hypothèses'!$C$14)+'2. Hypothèses'!$C$11 -> 38166.826 | N6: =M6 -> 38166.826 | O6: =M6*(1-'2. Hypothèses'!$D$14)^12+'2. Hypothèses'!$D$12*12 -> 118167.05 | P6: =O6*(1-'2. Hypothèses'!$E$14)^12+'2. Hypothèses'!$E$13*12 -> 236727.66 | Q6: =P6 -> 236727.66
A7: Utilisateurs actifs (MAU) | B7: =B6*'2. Hypothèses'!$C$15 -> 4675 | C7: =C6*'2. Hypothèses'!$C$15 -> 6436.375 | D7: =D6*'2. Hypothèses'!$C$15 -> 8136.1019 | E7: =E6*'2. Hypothèses'!$C$15 -> 9776.3383 | F7: =F6*'2. Hypothèses'!$C$15 -> 11359.166 | G7: =G6*'2. Hypothèses'!$C$15 -> 12886.596 | H7: =H6*'2. Hypothèses'!$C$15 -> 14360.565 | I7: =I6*'2. Hypothèses'!$C$15 -> 15782.945 | ... M7: =M6*'2. Hypothèses'!$C$15 -> 20991.754 | N7: =AVERAGE(B7:M7) -> 13316.565 | O7: =O6*'2. Hypothèses'!$D$15 -> 73263.574 | P7: =P6*'2. Hypothèses'!$E$15 -> 160974.81 | Q7: =AVERAGE(N7,O7,P7) -> 82518.317
A9: B. Ligne 1 — Transferts B2W & W2B
A10: Volume B2W (FCFA) | B10: =B7*'2. Hypothèses'!$C$17*'2. Hypothèses'!$C$18 -> 409062500 | C10: =C7*'2. Hypothèses'!$C$17*'2. Hypothèses'!$C$18 -> 5.6318281e+08 | D10: =D7*'2. Hypothèses'!$C$17*'2. Hypothèses'!$C$18 -> 7.1190891e+08 | E10: =E7*'2. Hypothèses'!$C$17*'2. Hypothèses'!$C$18 -> 8.554296e+08 | F10: =F7*'2. Hypothèses'!$C$17*'2. Hypothèses'!$C$18 -> 9.9392707e+08 | G10: =G7*'2. Hypothèses'!$C$17*'2. Hypothèses'!$C$18 -> 1.1275771e+09 | H10: =H7*'2. Hypothèses'!$C$17*'2. Hypothèses'!$C$18 -> 1.2565494e+09 | I10: =I7*'2. Hypothèses'!$C$17*'2. Hypothèses'!$C$18 -> 1.3810077e+09 | ... M10: =M7*'2. Hypothèses'!$C$17*'2. Hypothèses'!$C$18 -> 1.8367785e+09 | N10: =SUM(B10:M10) -> 1.3982393e+10 | O10: =O7*'2. Hypothèses'!$D$17*'2. Hypothèses'!$D$18*12 -> 1.1077452e+11 | P10: =P7*'2. Hypothèses'!$E$17*'2. Hypothèses'!$E$18*12 -> 3.1873013e+11 | Q10: =N10+O10+P10 -> 4.4348704e+11
A11: Revenu B2W (commissions) | B11: =B7*'2. Hypothèses'!$C$17*MAX('2. Hypothèses'!$C$18*'2. Hypothèses'!$C$19,'2. Hypothèses'!$C$20) -> 6135937.5 | C11: =C7*'2. Hypothèses'!$C$17*MAX('2. Hypothèses'!$C$18*'2. Hypothèses'!$C$19,'2. Hypothèses'!$C$20) -> 8447742.2 | D11: =D7*'2. Hypothèses'!$C$17*MAX('2. Hypothèses'!$C$18*'2. Hypothèses'!$C$19,'2. Hypothèses'!$C$20) -> 10678634 | E11: =E7*'2. Hypothèses'!$C$17*MAX('2. Hypothèses'!$C$18*'2. Hypothèses'!$C$19,'2. Hypothèses'!$C$20) -> 12831444 | F11: =F7*'2. Hypothèses'!$C$17*MAX('2. Hypothèses'!$C$18*'2. Hypothèses'!$C$19,'2. Hypothèses'!$C$20) -> 14908906 | G11: =G7*'2. Hypothèses'!$C$17*MAX('2. Hypothèses'!$C$18*'2. Hypothèses'!$C$19,'2. Hypothèses'!$C$20) -> 16913657 | H11: =H7*'2. Hypothèses'!$C$17*MAX('2. Hypothèses'!$C$18*'2. Hypothèses'!$C$19,'2. Hypothèses'!$C$20) -> 18848241 | I11: =I7*'2. Hypothèses'!$C$17*MAX('2. Hypothèses'!$C$18*'2. Hypothèses'!$C$19,'2. Hypothèses'!$C$20) -> 20715115 | ... M11: =M7*'2. Hypothèses'!$C$17*MAX('2. Hypothèses'!$C$18*'2. Hypothèses'!$C$19,'2. Hypothèses'!$C$20) -> 27551677 | N11: =SUM(B11:M11) -> 2.0973589e+08 | O11: =O7*'2. Hypothèses'!$D$17*MAX('2. Hypothèses'!$D$18*'2. Hypothèses'!$D$19,'2. Hypothèses'!$D$20)*12 -> 1.6616179e+09 | P11: =P7*'2. Hypothèses'!$E$17*MAX('2. Hypothèses'!$E$18*'2. Hypothèses'!$E$19,'2. Hypothèses'!$E$20)*12 -> 4.4622218e+09 | Q11: =N11+O11+P11 -> 6.3335755e+09
A12: Volume W2B (FCFA) | B12: =B7*'2. Hypothèses'!$C$21*'2. Hypothèses'!$C$22 -> 294525000 | C12: =C7*'2. Hypothèses'!$C$21*'2. Hypothèses'!$C$22 -> 405491625 | D12: =D7*'2. Hypothèses'!$C$21*'2. Hypothèses'!$C$22 -> 5.1257442e+08 | E12: =E7*'2. Hypothèses'!$C$21*'2. Hypothèses'!$C$22 -> 6.1590931e+08 | F12: =F7*'2. Hypothèses'!$C$21*'2. Hypothèses'!$C$22 -> 7.1562749e+08 | G12: =G7*'2. Hypothèses'!$C$21*'2. Hypothèses'!$C$22 -> 8.1185553e+08 | H12: =H7*'2. Hypothèses'!$C$21*'2. Hypothèses'!$C$22 -> 9.0471558e+08 | I12: =I7*'2. Hypothèses'!$C$21*'2. Hypothèses'!$C$22 -> 9.9432554e+08 | ... M12: =M7*'2. Hypothèses'!$C$21*'2. Hypothèses'!$C$22 -> 1.3224805e+09 | N12: =SUM(B12:M12) -> 1.0067323e+10 | O12: =O7*'2. Hypothèses'!$D$21*'2. Hypothèses'!$D$22*12 -> 8.7916288e+10 | P12: =P7*'2. Hypothèses'!$E$21*'2. Hypothèses'!$E$22*12 -> 2.7816447e+11 | Q12: =N12+O12+P12 -> 3.7614809e+11
A13: Revenu W2B (commissions) | B13: =B7*'2. Hypothèses'!$C$21*MAX('2. Hypothèses'!$C$22*'2. Hypothèses'!$C$23,'2. Hypothèses'!$C$24) -> 5301450 | C13: =C7*'2. Hypothèses'!$C$21*MAX('2. Hypothèses'!$C$22*'2. Hypothèses'!$C$23,'2. Hypothèses'!$C$24) -> 7298849.2 | D13: =D7*'2. Hypothèses'!$C$21*MAX('2. Hypothèses'!$C$22*'2. Hypothèses'!$C$23,'2. Hypothèses'!$C$24) -> 9226339.5 | E13: =E7*'2. Hypothèses'!$C$21*MAX('2. Hypothèses'!$C$22*'2. Hypothèses'!$C$23,'2. Hypothèses'!$C$24) -> 11086368 | F13: =F7*'2. Hypothèses'!$C$21*MAX('2. Hypothèses'!$C$22*'2. Hypothèses'!$C$23,'2. Hypothèses'!$C$24) -> 12881295 | G13: =G7*'2. Hypothèses'!$C$21*MAX('2. Hypothèses'!$C$22*'2. Hypothèses'!$C$23,'2. Hypothèses'!$C$24) -> 14613399 | H13: =H7*'2. Hypothèses'!$C$21*MAX('2. Hypothèses'!$C$22*'2. Hypothèses'!$C$23,'2. Hypothèses'!$C$24) -> 16284880 | I13: =I7*'2. Hypothèses'!$C$21*MAX('2. Hypothèses'!$C$22*'2. Hypothèses'!$C$23,'2. Hypothèses'!$C$24) -> 17897860 | ... M13: =M7*'2. Hypothèses'!$C$21*MAX('2. Hypothèses'!$C$22*'2. Hypothèses'!$C$23,'2. Hypothèses'!$C$24) -> 23804649 | N13: =SUM(B13:M13) -> 1.8121181e+08 | O13: =O7*'2. Hypothèses'!$D$21*MAX('2. Hypothèses'!$D$22*'2. Hypothèses'!$D$23,'2. Hypothèses'!$D$24)*12 -> 1.5824932e+09 | P13: =P7*'2. Hypothèses'!$E$21*MAX('2. Hypothèses'!$E$22*'2. Hypothèses'!$E$23,'2. Hypothèses'!$E$24)*12 -> 4.7287961e+09 | Q13: =N13+O13+P13 -> 6.4925011e+09
A14: Sous-total revenus Transferts | B14: =B11+B13 -> 11437388 | C14: =C11+C13 -> 15746591 | D14: =D11+D13 -> 19904973 | E14: =E11+E13 -> 23917812 | F14: =F11+F13 -> 27790201 | G14: =G11+G13 -> 31527056 | H14: =H11+H13 -> 35133122 | I14: =I11+I13 -> 38612975 | ... Q14: =Q11+Q13 -> 1.2826077e+10
A16: C. Ligne 2 — Carte bancaire
A17: Porteurs de carte (cumul) | B17: =B7*'2. Hypothèses'!$C$29 -> 561 | C17: =C7*'2. Hypothèses'!$C$29 -> 772.365 | D17: =D7*'2. Hypothèses'!$C$29 -> 976.33222 | E17: =E7*'2. Hypothèses'!$C$29 -> 1173.1606 | F17: =F7*'2. Hypothèses'!$C$29 -> 1363.1 | G17: =G7*'2. Hypothèses'!$C$29 -> 1546.3915 | H17: =H7*'2. Hypothèses'!$C$29 -> 1723.2678 | I17: =I7*'2. Hypothèses'!$C$29 -> 1893.9534 | ... M17: =M7*'2. Hypothèses'!$C$29 -> 2519.0105 | N17: =M17 -> 2519.0105 | O17: =O7*'2. Hypothèses'!$D$29 -> 16117.986 | P17: =P7*'2. Hypothèses'!$E$29 -> 56341.184 | Q17: =P17 -> 56341.184
A18: Nouvelles cartes émises (du mois) | B18: =B17 -> 561 | C18: =MAX(0,C17-B17) -> 211.365 | D18: =MAX(0,D17-C17) -> 203.96723 | E18: =MAX(0,E17-D17) -> 196.82837 | F18: =MAX(0,F17-E17) -> 189.93938 | G18: =MAX(0,G17-F17) -> 183.2915 | H18: =MAX(0,H17-G17) -> 176.8763 | I18: =MAX(0,I17-H17) -> 170.68563 | J18: =MAX(0,J17-I17) -> 164.71163 | ... M18: =MAX(0,M17-L17) -> 148.01516 | N18: =SUM(B18:M18) -> 2519.0105 | O18: =MAX(0,O17-M17) -> 13598.976 | P18: =MAX(0,P17-O17) -> 40223.198 | Q18: =N18+O18+P18 -> 56341.184
A19: Revenu frais d'émission carte | B19: =B18*'2. Hypothèses'!$C$30 -> 1402500 | C19: =C18*'2. Hypothèses'!$C$30 -> 528412.5 | D19: =D18*'2. Hypothèses'!$C$30 -> 509918.06 | E19: =E18*'2. Hypothèses'!$C$30 -> 492070.93 | F19: =F18*'2. Hypothèses'!$C$30 -> 474848.45 | G19: =G18*'2. Hypothèses'!$C$30 -> 458228.75 | H19: =H18*'2. Hypothèses'!$C$30 -> 442190.75 | I19: =I18*'2. Hypothèses'!$C$30 -> 426714.07 | ... M19: =M18*'2. Hypothèses'!$C$30 -> 370037.91 | N19: =SUM(B19:M19) -> 6297526.3 | O19: =O18*'2. Hypothèses'!$D$30 -> 33997439 | P19: =P18*'2. Hypothèses'!$E$30 -> 80446396 | Q19: =N19+O19+P19 -> 1.2074136e+08
A20: Revenu abonnement mensuel carte | B20: =B17*'2. Hypothèses'!$C$31 -> 280500 | C20: =C17*'2. Hypothèses'!$C$31 -> 386182.5 | D20: =D17*'2. Hypothèses'!$C$31 -> 488166.11 | E20: =E17*'2. Hypothèses'!$C$31 -> 586580.3 | F20: =F17*'2. Hypothèses'!$C$31 -> 681549.99 | G20: =G17*'2. Hypothèses'!$C$31 -> 773195.74 | H20: =H17*'2. Hypothèses'!$C$31 -> 861633.89 | I20: =I17*'2. Hypothèses'!$C$31 -> 946976.7 | ... M20: =M17*'2. Hypothèses'!$C$31 -> 1259505.3 | N20: =SUM(B20:M20) -> 9587926.6 | O20: =O17*'2. Hypothèses'!$D$31*12 -> 96707917 | P20: =P17*'2. Hypothèses'!$E$31*12 -> 3.380471e+08 | Q20: =N20+O20+P20 -> 4.4434295e+08
A21: Volume transactions carte (FCFA) | B21: =B17*'2. Hypothèses'!$C$32*'2. Hypothèses'!$C$33 -> 53856000 | C21: =C17*'2. Hypothèses'!$C$32*'2. Hypothèses'!$C$33 -> 74147040 | D21: =D17*'2. Hypothèses'!$C$32*'2. Hypothèses'!$C$33 -> 93727894 | E21: =E17*'2. Hypothèses'!$C$32*'2. Hypothèses'!$C$33 -> 1.1262342e+08 | F21: =F17*'2. Hypothèses'!$C$32*'2. Hypothèses'!$C$33 -> 1.308576e+08 | G21: =G17*'2. Hypothèses'!$C$32*'2. Hypothèses'!$C$33 -> 1.4845358e+08 | H21: =H17*'2. Hypothèses'!$C$32*'2. Hypothèses'!$C$33 -> 1.6543371e+08 | I21: =I17*'2. Hypothèses'!$C$32*'2. Hypothèses'!$C$33 -> 1.8181953e+08 | ... M21: =M17*'2. Hypothèses'!$C$32*'2. Hypothèses'!$C$33 -> 2.4182501e+08 | N21: =SUM(B21:M21) -> 1.8408819e+09 | O21: =O17*'2. Hypothèses'!$D$32*'2. Hypothèses'!$D$33*12 -> 3.249386e+10 | P21: =P17*'2. Hypothèses'!$E$32*'2. Hypothèses'!$E$33*12 -> 1.7308012e+11 | Q21: =N21+O21+P21 -> 2.0741486e+11
A22: Revenu interchange (MDR émetteur) | B22: =B21*'2. Hypothèses'!$C$34 -> 646272 | C22: =C21*'2. Hypothèses'!$C$34 -> 889764.48 | D22: =D21*'2. Hypothèses'!$C$34 -> 1124734.7 | E22: =E21*'2. Hypothèses'!$C$34 -> 1351481 | F22: =F21*'2. Hypothèses'!$C$34 -> 1570291.2 | G22: =G21*'2. Hypothèses'!$C$34 -> 1781443 | H22: =H21*'2. Hypothèses'!$C$34 -> 1985204.5 | I22: =I21*'2. Hypothèses'!$C$34 -> 2181834.3 | ... M22: =M21*'2. Hypothèses'!$C$34 -> 2901900.1 | N22: =SUM(B22:M22) -> 22090583 | O22: =O21*'2. Hypothèses'!$D$34 -> 3.8992632e+08 | P22: =P21*'2. Hypothèses'!$E$34 -> 2.0769614e+09 | Q22: =N22+O22+P22 -> 2.4889783e+09
A23: Sous-total revenus Carte | B23: =B19+B20+B22 -> 2329272 | C23: =C19+C20+C22 -> 1804359.5 | D23: =D19+D20+D22 -> 2122818.9 | E23: =E19+E20+E22 -> 2430132.2 | F23: =F19+F20+F22 -> 2726689.6 | G23: =G19+G20+G22 -> 3012867.5 | H23: =H19+H20+H22 -> 3289029.1 | I23: =I19+I20+I22 -> 3555525.1 | ... Q23: =Q19+Q20+Q22 -> 3.0540626e+09
A25: D. Ligne 3 — Achat de services
A26: Volume services (FCFA) | B26: =B7*'2. Hypothèses'!$C$39*'2. Hypothèses'!$C$40 -> 94668750 | C26: =C7*'2. Hypothèses'!$C$39*'2. Hypothèses'!$C$40 -> 1.3033659e+08 | D26: =D7*'2. Hypothèses'!$C$39*'2. Hypothèses'!$C$40 -> 1.6475606e+08 | E26: =E7*'2. Hypothèses'!$C$39*'2. Hypothèses'!$C$40 -> 1.9797085e+08 | F26: =F7*'2. Hypothèses'!$C$39*'2. Hypothèses'!$C$40 -> 2.3002312e+08 | G26: =G7*'2. Hypothèses'!$C$39*'2. Hypothèses'!$C$40 -> 2.6095356e+08 | H26: =H7*'2. Hypothèses'!$C$39*'2. Hypothèses'!$C$40 -> 2.9080144e+08 | I26: =I7*'2. Hypothèses'!$C$39*'2. Hypothèses'!$C$40 -> 3.1960464e+08 | ... M26: =M7*'2. Hypothèses'!$C$39*'2. Hypothèses'!$C$40 -> 4.2508302e+08 | N26: =SUM(B26:M26) -> 3.2359252e+09 | O26: =O7*'2. Hypothèses'!$D$39*'2. Hypothèses'!$D$40*12 -> 2.6374887e+10 | P26: =P7*'2. Hypothèses'!$E$39*'2. Hypothèses'!$E$40*12 -> 8.49947e+10 | Q26: =N26+O26+P26 -> 1.1460551e+11
A27: Revenu commission utilisateur | B27: =B26*'2. Hypothèses'!$C$41 -> 1893375 | C27: =C26*'2. Hypothèses'!$C$41 -> 2606731.9 | D27: =D26*'2. Hypothèses'!$C$41 -> 3295121.3 | E27: =E26*'2. Hypothèses'!$C$41 -> 3959417 | F27: =F26*'2. Hypothèses'!$C$41 -> 4600462.4 | G27: =G26*'2. Hypothèses'!$C$41 -> 5219071.2 | H27: =H26*'2. Hypothèses'!$C$41 -> 5816028.7 | I27: =I26*'2. Hypothèses'!$C$41 -> 6392092.7 | ... M27: =M26*'2. Hypothèses'!$C$41 -> 8501660.5 | N27: =SUM(B27:M27) -> 64718504 | O27: =O26*'2. Hypothèses'!$D$41 -> 5.2749773e+08 | P27: =P26*'2. Hypothèses'!$E$41 -> 1.6148993e+09 | Q27: =N27+O27+P27 -> 2.2071155e+09
A28: Revenu commission marchand | B28: =B26*'2. Hypothèses'!$C$42 -> 946687.5 | C28: =C26*'2. Hypothèses'!$C$42 -> 1303365.9 | D28: =D26*'2. Hypothèses'!$C$42 -> 1647560.6 | E28: =E26*'2. Hypothèses'!$C$42 -> 1979708.5 | F28: =F26*'2. Hypothèses'!$C$42 -> 2300231.2 | G28: =G26*'2. Hypothèses'!$C$42 -> 2609535.6 | H28: =H26*'2. Hypothèses'!$C$42 -> 2908014.4 | I28: =I26*'2. Hypothèses'!$C$42 -> 3196046.4 | ... M28: =M26*'2. Hypothèses'!$C$42 -> 4250830.2 | N28: =SUM(B28:M28) -> 32359252 | O28: =O26*'2. Hypothèses'!$D$42 -> 2.9012375e+08 | P28: =P26*'2. Hypothèses'!$E$42 -> 1.0199364e+09 | Q28: =N28+O28+P28 -> 1.3424194e+09
A29: Sous-total revenus Services | B29: =B27+B28 -> 2840062.5 | C29: =C27+C28 -> 3910097.8 | D29: =D27+D28 -> 4942681.9 | E29: =E27+E28 -> 5939125.5 | F29: =F27+F28 -> 6900693.6 | G29: =G27+G28 -> 7828606.9 | H29: =H27+H28 -> 8724043.1 | I29: =I27+I28 -> 9588139.1 | ... Q29: =Q27+Q28 -> 3.549535e+09
A31: E. TOTAL REVENUS
A32: CHIFFRE D'AFFAIRES TOTAL | B32: =B14+B23+B29 -> 16606722 | C32: =C14+C23+C29 -> 21461049 | D32: =D14+D23+D29 -> 26970474 | E32: =E14+E23+E29 -> 32287069 | F32: =F14+F23+F29 -> 37417584 | G32: =G14+G23+G29 -> 42368531 | H32: =H14+H23+H29 -> 47146194 | I32: =I14+I23+I29 -> 51756639 | ... Q32: =Q14+Q23+Q29 -> 1.9429674e+10
A33: Mix Transferts (% du CA) | B33: =IFERROR(B14/B32,0) -> 0.68872036 | C33: =IFERROR(C14/C32,0) -> 0.73372889 | D33: =IFERROR(D14/D32,0) -> 0.73802831 | E33: =IFERROR(E14/E32,0) -> 0.74078608 | F33: =IFERROR(F14/F32,0) -> 0.74270431 | G33: =IFERROR(G14/G32,0) -> 0.74411493 | H33: =IFERROR(H14/H32,0) -> 0.74519529 | I33: =IFERROR(I14/I32,0) -> 0.74604873 | ... Q33: =IFERROR(Q14/Q32,0) -> 0.66012824
A34: Mix Carte (% du CA) | B34: =IFERROR(B23/B32,0) -> 0.14026079 | C34: =IFERROR(C23/C32,0) -> 0.084076016 | D34: =IFERROR(D23/D32,0) -> 0.078708995 | E34: =IFERROR(E23/E32,0) -> 0.075266423 | F34: =IFERROR(F23/F32,0) -> 0.072871878 | G34: =IFERROR(G23/G32,0) -> 0.071110974 | H34: =IFERROR(H23/H32,0) -> 0.069762346 | I34: =IFERROR(I23/I32,0) -> 0.068696985 | ... Q34: =IFERROR(Q23/Q32,0) -> 0.15718548
A35: Mix Services (% du CA) | B35: =IFERROR(B29/B32,0) -> 0.17101885 | C35: =IFERROR(C29/C32,0) -> 0.1821951 | D35: =IFERROR(D29/D32,0) -> 0.1832627 | E35: =IFERROR(E29/E32,0) -> 0.18394749 | F35: =IFERROR(F29/F32,0) -> 0.18442382 | G35: =IFERROR(G29/G32,0) -> 0.18477409 | H35: =IFERROR(H29/H32,0) -> 0.18504236 | I35: =IFERROR(I29/I32,0) -> 0.18525428 | ... Q35: =IFERROR(Q29/Q32,0) -> 0.18268628

Sheet 4. Coûts variables
A1: COÛTS VARIABLES — Proportionnels au volume
B2: Année 1 (mensuel)
A3: Poste | B3: M1 | C3: M2 | D3: M3 | E3: M4 | F3: M5 | G3: M6 | H3: M7 | I3: M8 | J3: M9 | K3: M10 | L3: M11 | M3: M12 | N3: Total Y1 | O3: Année 2 | P3: Année 3 | Q3: Total 3 ans
A4: A. Coûts variables Transferts
A5: Coût bancaire / interchange (volume B2W+W2B) | B5: =('3. Revenus'!B10+'3. Revenus'!B12)*'2. Hypothèses'!$C$25 -> 2814350 | C5: =('3. Revenus'!C10+'3. Revenus'!C12)*'2. Hypothèses'!$C$25 -> 3874697.8 | D5: =('3. Revenus'!D10+'3. Revenus'!D12)*'2. Hypothèses'!$C$25 -> 4897933.3 | E5: =('3. Revenus'!E10+'3. Revenus'!E12)*'2. Hypothèses'!$C$25 -> 5885355.7 | F5: =('3. Revenus'!F10+'3. Revenus'!F12)*'2. Hypothèses'!$C$25 -> 6838218.2 | G5: =('3. Revenus'!G10+'3. Revenus'!G12)*'2. Hypothèses'!$C$25 -> 7757730.6 | H5: =('3. Revenus'!H10+'3. Revenus'!H12)*'2. Hypothèses'!$C$25 -> 8645060 | I5: =('3. Revenus'!I10+'3. Revenus'!I12)*'2. Hypothèses'!$C$25 -> 9501332.9 | ... M5: =('3. Revenus'!M10+'3. Revenus'!M12)*'2. Hypothèses'!$C$25 -> 12637036 | N5: =SUM(B5:M5) -> 96198863 | O5: =('3. Revenus'!O10+'3. Revenus'!O12)*'2. Hypothèses'!$D$25 -> 6.9541784e+08 | P5: =('3. Revenus'!P10+'3. Revenus'!P12)*'2. Hypothèses'!$E$25 -> 1.7906838e+09 | Q5: =N5+O5+P5 -> 2.5823005e+09
A6: Commissions agents réseau (% revenu transferts) | B6: ='3. Revenus'!B14*'2. Hypothèses'!$C$26 -> 4574955 | C6: ='3. Revenus'!C14*'2. Hypothèses'!$C$26 -> 6298636.6 | D6: ='3. Revenus'!D14*'2. Hypothèses'!$C$26 -> 7961989.3 | E6: ='3. Revenus'!E14*'2. Hypothèses'!$C$26 -> 9567124.7 | F6: ='3. Revenus'!F14*'2. Hypothèses'!$C$26 -> 11116080 | G6: ='3. Revenus'!G14*'2. Hypothèses'!$C$26 -> 12610822 | H6: ='3. Revenus'!H14*'2. Hypothèses'!$C$26 -> 14053249 | I6: ='3. Revenus'!I14*'2. Hypothèses'!$C$26 -> 15445190 | ... M6: ='3. Revenus'!M14*'2. Hypothèses'!$C$26 -> 20542531 | N6: =SUM(B6:M6) -> 1.5637908e+08 | O6: ='3. Revenus'!O14*'2. Hypothèses'!$D$26 -> 1.2327622e+09 | P6: ='3. Revenus'!P14*'2. Hypothèses'!$E$26 -> 3.2168562e+09 | Q6: =N6+O6+P6 -> 4.6059975e+09
A7: SMS notifications (B2W+W2B+services) | B7: ='3. Revenus'!B7*('2. Hypothèses'!$C$17+'2. Hypothèses'!$C$21+'2. Hypothèses'!$C$39)*'2. Hypothèses'!$C$27 -> 549780 | C7: ='3. Revenus'!C7*('2. Hypothèses'!$C$17+'2. Hypothèses'!$C$21+'2. Hypothèses'!$C$39)*'2. Hypothèses'!$C$27 -> 756917.7 | D7: ='3. Revenus'!D7*('2. Hypothèses'!$C$17+'2. Hypothèses'!$C$21+'2. Hypothèses'!$C$39)*'2. Hypothèses'!$C$27 -> 956805.58 | E7: ='3. Revenus'!E7*('2. Hypothèses'!$C$17+'2. Hypothèses'!$C$21+'2. Hypothèses'!$C$39)*'2. Hypothèses'!$C$27 -> 1149697.4 | F7: ='3. Revenus'!F7*('2. Hypothèses'!$C$17+'2. Hypothèses'!$C$21+'2. Hypothèses'!$C$39)*'2. Hypothèses'!$C$27 -> 1335838 | G7: ='3. Revenus'!G7*('2. Hypothèses'!$C$17+'2. Hypothèses'!$C$21+'2. Hypothèses'!$C$39)*'2. Hypothèses'!$C$27 -> 1515463.6 | H7: ='3. Revenus'!H7*('2. Hypothèses'!$C$17+'2. Hypothèses'!$C$21+'2. Hypothèses'!$C$39)*'2. Hypothèses'!$C$27 -> 1688802.4 | I7: ='3. Revenus'!I7*('2. Hypothèses'!$C$17+'2. Hypothèses'!$C$21+'2. Hypothèses'!$C$39)*'2. Hypothèses'!$C$27 -> 1856074.3 | ... M7: ='3. Revenus'!M7*('2. Hypothèses'!$C$17+'2. Hypothèses'!$C$21+'2. Hypothèses'!$C$39)*'2. Hypothèses'!$C$27 -> 2468630.3 | N7: =SUM(B7:M7) -> 18792336 | O7: ='3. Revenus'!O7*('2. Hypothèses'!$D$17+'2. Hypothèses'!$D$21+'2. Hypothèses'!$D$39)*'2. Hypothèses'!$D$27*12 -> 1.2572029e+08 | P7: ='3. Revenus'!P7*('2. Hypothèses'!$E$17+'2. Hypothèses'!$E$21+'2. Hypothèses'!$E$39)*'2. Hypothèses'!$E$27*12 -> 3.2259352e+08 | Q7: =N7+O7+P7 -> 4.6710615e+08
A9: B. Coûts variables Carte bancaire
A10: Coût fabrication cartes (nouvelles) | B10: ='3. Revenus'!B18*'2. Hypothèses'!$C$35 -> 841500 | C10: ='3. Revenus'!C18*'2. Hypothèses'!$C$35 -> 317047.5 | D10: ='3. Revenus'!D18*'2. Hypothèses'!$C$35 -> 305950.84 | E10: ='3. Revenus'!E18*'2. Hypothèses'!$C$35 -> 295242.56 | F10: ='3. Revenus'!F18*'2. Hypothèses'!$C$35 -> 284909.07 | G10: ='3. Revenus'!G18*'2. Hypothèses'!$C$35 -> 274937.25 | H10: ='3. Revenus'!H18*'2. Hypothèses'!$C$35 -> 265314.45 | I10: ='3. Revenus'!I18*'2. Hypothèses'!$C$35 -> 256028.44 | ... M10: ='3. Revenus'!M18*'2. Hypothèses'!$C$35 -> 222022.74 | N10: =SUM(B10:M10) -> 3778515.8 | O10: ='3. Revenus'!O18*'2. Hypothèses'!$D$35 -> 19038566 | P10: ='3. Revenus'!P18*'2. Hypothèses'!$E$35 -> 52290157 | Q10: =N10+O10+P10 -> 75107239
A11: Frais scheme (Visa/Mastercard) | B11: ='3. Revenus'!B17*'2. Hypothèses'!$C$32*'2. Hypothèses'!$C$36 -> 112200 | C11: ='3. Revenus'!C17*'2. Hypothèses'!$C$32*'2. Hypothèses'!$C$36 -> 154473 | D11: ='3. Revenus'!D17*'2. Hypothèses'!$C$32*'2. Hypothèses'!$C$36 -> 195266.45 | E11: ='3. Revenus'!E17*'2. Hypothèses'!$C$32*'2. Hypothèses'!$C$36 -> 234632.12 | F11: ='3. Revenus'!F17*'2. Hypothèses'!$C$32*'2. Hypothèses'!$C$36 -> 272620 | G11: ='3. Revenus'!G17*'2. Hypothèses'!$C$32*'2. Hypothèses'!$C$36 -> 309278.3 | H11: ='3. Revenus'!H17*'2. Hypothèses'!$C$32*'2. Hypothèses'!$C$36 -> 344653.56 | I11: ='3. Revenus'!I17*'2. Hypothèses'!$C$32*'2. Hypothèses'!$C$36 -> 378790.68 | ... M11: ='3. Revenus'!M17*'2. Hypothèses'!$C$32*'2. Hypothèses'!$C$36 -> 503802.1 | N11: =SUM(B11:M11) -> 3835170.6 | O11: ='3. Revenus'!O17*'2. Hypothèses'!$D$32*'2. Hypothèses'!$D$36*12 -> 55703760 | P11: ='3. Revenus'!P17*'2. Hypothèses'!$E$32*'2. Hypothèses'!$E$36*12 -> 2.3798516e+08 | Q11: =N11+O11+P11 -> 2.9752409e+08
A12: Coût processing transactions | B12: ='3. Revenus'!B17*'2. Hypothèses'!$C$32*'2. Hypothèses'!$C$37 -> 80784 | C12: ='3. Revenus'!C17*'2. Hypothèses'!$C$32*'2. Hypothèses'!$C$37 -> 111220.56 | D12: ='3. Revenus'!D17*'2. Hypothèses'!$C$32*'2. Hypothèses'!$C$37 -> 140591.84 | E12: ='3. Revenus'!E17*'2. Hypothèses'!$C$32*'2. Hypothèses'!$C$37 -> 168935.13 | F12: ='3. Revenus'!F17*'2. Hypothèses'!$C$32*'2. Hypothèses'!$C$37 -> 196286.4 | G12: ='3. Revenus'!G17*'2. Hypothèses'!$C$32*'2. Hypothèses'!$C$37 -> 222680.37 | H12: ='3. Revenus'!H17*'2. Hypothèses'!$C$32*'2. Hypothèses'!$C$37 -> 248150.56 | I12: ='3. Revenus'!I17*'2. Hypothèses'!$C$32*'2. Hypothèses'!$C$37 -> 272729.29 | ... M12: ='3. Revenus'!M17*'2. Hypothèses'!$C$32*'2. Hypothèses'!$C$37 -> 362737.51 | N12: =SUM(B12:M12) -> 2761322.8 | O12: ='3. Revenus'!O17*'2. Hypothèses'!$D$32*'2. Hypothèses'!$D$37*12 -> 39456830 | P12: ='3. Revenus'!P17*'2. Hypothèses'!$E$32*'2. Hypothèses'!$E$37*12 -> 1.6226261e+08 | Q12: =N12+O12+P12 -> 2.0448076e+08
A14: C. Coûts variables Services
A15: Rétrocession biller / agrégateur | B15: ='3. Revenus'!B29*'2. Hypothèses'!$C$43 -> 994021.88 | C15: ='3. Revenus'!C29*'2. Hypothèses'!$C$43 -> 1368534.2 | D15: ='3. Revenus'!D29*'2. Hypothèses'!$C$43 -> 1729938.7 | E15: ='3. Revenus'!E29*'2. Hypothèses'!$C$43 -> 2078693.9 | F15: ='3. Revenus'!F29*'2. Hypothèses'!$C$43 -> 2415242.8 | G15: ='3. Revenus'!G29*'2. Hypothèses'!$C$43 -> 2740012.4 | H15: ='3. Revenus'!H29*'2. Hypothèses'!$C$43 -> 3053415.1 | I15: ='3. Revenus'!I29*'2. Hypothèses'!$C$43 -> 3355848.7 | ... M15: ='3. Revenus'!M29*'2. Hypothèses'!$C$43 -> 4463371.7 | N15: =SUM(B15:M15) -> 33977215 | O15: ='3. Revenus'!O29*'2. Hypothèses'!$D$43 -> 2.6163887e+08 | P15: ='3. Revenus'!P29*'2. Hypothèses'!$E$43 -> 7.9045071e+08 | Q15: =N15+O15+P15 -> 1.0860668e+09
A17: D. Coût d'acquisition utilisateurs (CAC)
A18: CAC — nouveaux utilisateurs acquis | B18: ='2. Hypothèses'!$C$11*'2. Hypothèses'!$C$72 -> 12250000 | C18: ='2. Hypothèses'!$C$11*'2. Hypothèses'!$C$72 -> 12250000 | D18: ='2. Hypothèses'!$C$11*'2. Hypothèses'!$C$72 -> 12250000 | E18: ='2. Hypothèses'!$C$11*'2. Hypothèses'!$C$72 -> 12250000 | F18: ='2. Hypothèses'!$C$11*'2. Hypothèses'!$C$72 -> 12250000 | G18: ='2. Hypothèses'!$C$11*'2. Hypothèses'!$C$72 -> 12250000 | H18: ='2. Hypothèses'!$C$11*'2. Hypothèses'!$C$72 -> 12250000 | I18: ='2. Hypothèses'!$C$11*'2. Hypothèses'!$C$72 -> 12250000 | ... M18: ='2. Hypothèses'!$C$11*'2. Hypothèses'!$C$72 -> 12250000 | N18: =SUM(B18:M18) -> 147000000 | O18: ='2. Hypothèses'!$D$12*'2. Hypothèses'!$D$72*12 -> 270000000 | P18: ='2. Hypothèses'!$E$13*'2. Hypothèses'!$E$72*12 -> 360000000 | Q18: =N18+O18+P18 -> 777000000
A20: TOTAL COÛTS VARIABLES
A21: TOTAL COÛTS VARIABLES | B21: =B5+B6+B7+B10+B11+B12+B15+B18 -> 22217591 | C21: =C5+C6+C7+C10+C11+C12+C15+C18 -> 25131527 | D21: =D5+D6+D7+D10+D11+D12+D15+D18 -> 28438476 | E21: =E5+E6+E7+E10+E11+E12+E15+E18 -> 31629681 | F21: =F5+F6+F7+F10+F11+F12+F15+F18 -> 34709195 | G21: =G5+G6+G7+G10+G11+G12+G15+G18 -> 37680925 | H21: =H5+H6+H7+H10+H11+H12+H15+H18 -> 40548645 | I21: =I5+I6+I7+I10+I11+I12+I15+I18 -> 43315994 | ... Q21: =Q5+Q6+Q7+Q10+Q11+Q12+Q15+Q18 -> 1.0095583e+10
A22: Ratio Coûts Variables / CA | B22: =IFERROR(B21/'3. Revenus'!B32,0) -> 1.3378673 | C22: =IFERROR(C21/'3. Revenus'!C32,0) -> 1.1710298 | D22: =IFERROR(D21/'3. Revenus'!D32,0) -> 1.05443 | E22: =IFERROR(E21/'3. Revenus'!E32,0) -> 0.97963928 | F22: =IFERROR(F21/'3. Revenus'!F32,0) -> 0.92761721 | G22: =IFERROR(G21/'3. Revenus'!G32,0) -> 0.88936115 | H22: =IFERROR(H21/'3. Revenus'!H32,0) -> 0.86006189 | I22: =IFERROR(I21/'3. Revenus'!I32,0) -> 0.83691667 | ... Q22: =IFERROR(Q21/'3. Revenus'!Q32,0) -> 0.51959611
A23: MARGE CONTRIBUTIVE (CA - CV) | B23: ='3. Revenus'!B32-B21 -> -5610868.9 | C23: ='3. Revenus'!C32-C21 -> -3670478.6 | D23: ='3. Revenus'!D32-D21 -> -1468002 | E23: ='3. Revenus'!E32-E21 -> 657387.98 | F23: ='3. Revenus'!F32-F21 -> 2708389.3 | G23: ='3. Revenus'!G32-G21 -> 4687605.5 | H23: ='3. Revenus'!H32-H21 -> 6597549.2 | I23: ='3. Revenus'!I32-I21 -> 8440644.9 | ... Q23: ='3. Revenus'!Q32-Q21 -> 9.3340911e+09
A24: Taux de marge contributive | B24: =IFERROR(B23/'3. Revenus'!B32,0) -> -0.33786733 | C24: =IFERROR(C23/'3. Revenus'!C32,0) -> -0.17102979 | D24: =IFERROR(D23/'3. Revenus'!D32,0) -> -0.054429965 | E24: =IFERROR(E23/'3. Revenus'!E32,0) -> 0.02036072 | F24: =IFERROR(F23/'3. Revenus'!F32,0) -> 0.072382794 | G24: =IFERROR(G23/'3. Revenus'!G32,0) -> 0.11063885 | H24: =IFERROR(H23/'3. Revenus'!H32,0) -> 0.13993811 | I24: =IFERROR(I23/'3. Revenus'!I32,0) -> 0.16308333 | ... Q24: =IFERROR(Q23/'3. Revenus'!Q32,0) -> 0.48040389

Sheet 5. Charges fixes
A1: CHARGES FIXES — Structure de coûts
B2: Année 1 (mensuel)
A3: Poste | B3: M1 | C3: M2 | D3: M3 | E3: M4 | F3: M5 | G3: M6 | H3: M7 | I3: M8 | J3: M9 | K3: M10 | L3: M11 | M3: M12 | N3: Total Y1 | O3: Année 2 | P3: Année 3 | Q3: Total 3 ans
A4: A. Masse salariale (chargée)
A5: Masse salariale — Tech & Produit | B5: ='2. Hypothèses'!$C$45*'2. Hypothèses'!$C$49 -> 6800000 | C5: ='2. Hypothèses'!$C$45*'2. Hypothèses'!$C$49 -> 6800000 | D5: ='2. Hypothèses'!$C$45*'2. Hypothèses'!$C$49 -> 6800000 | E5: ='2. Hypothèses'!$C$45*'2. Hypothèses'!$C$49 -> 6800000 | F5: ='2. Hypothèses'!$C$45*'2. Hypothèses'!$C$49 -> 6800000 | G5: ='2. Hypothèses'!$C$45*'2. Hypothèses'!$C$49 -> 6800000 | H5: ='2. Hypothèses'!$C$45*'2. Hypothèses'!$C$49 -> 6800000 | I5: ='2. Hypothèses'!$C$45*'2. Hypothèses'!$C$49 -> 6800000 | ... M5: ='2. Hypothèses'!$C$45*'2. Hypothèses'!$C$49 -> 6800000 | N5: =SUM(B5:M5) -> 81600000 | O5: ='2. Hypothèses'!$D$45*'2. Hypothèses'!$D$49*12 -> 151200000 | P5: ='2. Hypothèses'!$E$45*'2. Hypothèses'!$E$49*12 -> 250800000 | Q5: =N5+O5+P5 -> 483600000
A6: Masse salariale — Commercial & Marketing | B6: ='2. Hypothèses'!$C$46*'2. Hypothèses'!$C$50 -> 3900000 | C6: ='2. Hypothèses'!$C$46*'2. Hypothèses'!$C$50 -> 3900000 | D6: ='2. Hypothèses'!$C$46*'2. Hypothèses'!$C$50 -> 3900000 | E6: ='2. Hypothèses'!$C$46*'2. Hypothèses'!$C$50 -> 3900000 | F6: ='2. Hypothèses'!$C$46*'2. Hypothèses'!$C$50 -> 3900000 | G6: ='2. Hypothèses'!$C$46*'2. Hypothèses'!$C$50 -> 3900000 | H6: ='2. Hypothèses'!$C$46*'2. Hypothèses'!$C$50 -> 3900000 | I6: ='2. Hypothèses'!$C$46*'2. Hypothèses'!$C$50 -> 3900000 | ... M6: ='2. Hypothèses'!$C$46*'2. Hypothèses'!$C$50 -> 3900000 | N6: =SUM(B6:M6) -> 46800000 | O6: ='2. Hypothèses'!$D$46*'2. Hypothèses'!$D$50*12 -> 100800000 | P6: ='2. Hypothèses'!$E$46*'2. Hypothèses'!$E$50*12 -> 180000000 | Q6: =N6+O6+P6 -> 327600000
A7: Masse salariale — Opérations & Support | B7: ='2. Hypothèses'!$C$47*'2. Hypothèses'!$C$51 -> 3150000 | C7: ='2. Hypothèses'!$C$47*'2. Hypothèses'!$C$51 -> 3150000 | D7: ='2. Hypothèses'!$C$47*'2. Hypothèses'!$C$51 -> 3150000 | E7: ='2. Hypothèses'!$C$47*'2. Hypothèses'!$C$51 -> 3150000 | F7: ='2. Hypothèses'!$C$47*'2. Hypothèses'!$C$51 -> 3150000 | G7: ='2. Hypothèses'!$C$47*'2. Hypothèses'!$C$51 -> 3150000 | H7: ='2. Hypothèses'!$C$47*'2. Hypothèses'!$C$51 -> 3150000 | I7: ='2. Hypothèses'!$C$47*'2. Hypothèses'!$C$51 -> 3150000 | ... M7: ='2. Hypothèses'!$C$47*'2. Hypothèses'!$C$51 -> 3150000 | N7: =SUM(B7:M7) -> 37800000 | O7: ='2. Hypothèses'!$D$47*'2. Hypothèses'!$D$51*12 -> 84000000 | P7: ='2. Hypothèses'!$E$47*'2. Hypothèses'!$E$51*12 -> 165000000 | Q7: =N7+O7+P7 -> 286800000
A8: Masse salariale — Corporate (Finance, RH, Direction) | B8: ='2. Hypothèses'!$C$48*'2. Hypothèses'!$C$52 -> 3800000 | C8: ='2. Hypothèses'!$C$48*'2. Hypothèses'!$C$52 -> 3800000 | D8: ='2. Hypothèses'!$C$48*'2. Hypothèses'!$C$52 -> 3800000 | E8: ='2. Hypothèses'!$C$48*'2. Hypothèses'!$C$52 -> 3800000 | F8: ='2. Hypothèses'!$C$48*'2. Hypothèses'!$C$52 -> 3800000 | G8: ='2. Hypothèses'!$C$48*'2. Hypothèses'!$C$52 -> 3800000 | H8: ='2. Hypothèses'!$C$48*'2. Hypothèses'!$C$52 -> 3800000 | I8: ='2. Hypothèses'!$C$48*'2. Hypothèses'!$C$52 -> 3800000 | ... M8: ='2. Hypothèses'!$C$48*'2. Hypothèses'!$C$52 -> 3800000 | N8: =SUM(B8:M8) -> 45600000 | O8: ='2. Hypothèses'!$D$48*'2. Hypothèses'!$D$52*12 -> 72000000 | P8: ='2. Hypothèses'!$E$48*'2. Hypothèses'!$E$52*12 -> 118800000 | Q8: =N8+O8+P8 -> 236400000
A9: Sous-total Masse salariale | B9: =B5+B6+B7+B8 -> 17650000 | C9: =C5+C6+C7+C8 -> 17650000 | D9: =D5+D6+D7+D8 -> 17650000 | E9: =E5+E6+E7+E8 -> 17650000 | F9: =F5+F6+F7+F8 -> 17650000 | G9: =G5+G6+G7+G8 -> 17650000 | H9: =H5+H6+H7+H8 -> 17650000 | I9: =I5+I6+I7+I8 -> 17650000 | ... Q9: =Q5+Q6+Q7+Q8 -> 1334400000
A10: Effectif total (ETP) | B10: ='2. Hypothèses'!$C$45+'2. Hypothèses'!$C$46+'2. Hypothèses'!$C$47+'2. Hypothèses'!$C$48 -> 25 | C10: ='2. Hypothèses'!$C$45+'2. Hypothèses'!$C$46+'2. Hypothèses'!$C$47+'2. Hypothèses'!$C$48 -> 25 | D10: ='2. Hypothèses'!$C$45+'2. Hypothèses'!$C$46+'2. Hypothèses'!$C$47+'2. Hypothèses'!$C$48 -> 25 | E10: ='2. Hypothèses'!$C$45+'2. Hypothèses'!$C$46+'2. Hypothèses'!$C$47+'2. Hypothèses'!$C$48 -> 25 | F10: ='2. Hypothèses'!$C$45+'2. Hypothèses'!$C$46+'2. Hypothèses'!$C$47+'2. Hypothèses'!$C$48 -> 25 | G10: ='2. Hypothèses'!$C$45+'2. Hypothèses'!$C$46+'2. Hypothèses'!$C$47+'2. Hypothèses'!$C$48 -> 25 | H10: ='2. Hypothèses'!$C$45+'2. Hypothèses'!$C$46+'2. Hypothèses'!$C$47+'2. Hypothèses'!$C$48 -> 25 | I10: ='2. Hypothèses'!$C$45+'2. Hypothèses'!$C$46+'2. Hypothèses'!$C$47+'2. Hypothèses'!$C$48 -> 25 | ... M10: ='2. Hypothèses'!$C$45+'2. Hypothèses'!$C$46+'2. Hypothèses'!$C$47+'2. Hypothèses'!$C$48 -> 25 | N10: =M10 -> 25 | O10: ='2. Hypothèses'!$D$45+'2. Hypothèses'!$D$46+'2. Hypothèses'!$D$47+'2. Hypothèses'!$D$48 -> 46 | P10: ='2. Hypothèses'!$E$45+'2. Hypothèses'!$E$46+'2. Hypothèses'!$E$47+'2. Hypothèses'!$E$48 -> 76 | Q10: =P10 -> 76
A12: B. Autres charges fixes (mensuel)
A13: Loyers & charges locatives | B13: ='2. Hypothèses'!$C$54 -> 1800000 | C13: ='2. Hypothèses'!$C$54 -> 1800000 | D13: ='2. Hypothèses'!$C$54 -> 1800000 | E13: ='2. Hypothèses'!$C$54 -> 1800000 | F13: ='2. Hypothèses'!$C$54 -> 1800000 | G13: ='2. Hypothèses'!$C$54 -> 1800000 | H13: ='2. Hypothèses'!$C$54 -> 1800000 | I13: ='2. Hypothèses'!$C$54 -> 1800000 | ... M13: ='2. Hypothèses'!$C$54 -> 1800000 | N13: =SUM(B13:M13) -> 21600000 | O13: ='2. Hypothèses'!$D$54*12 -> 28800000 | P13: ='2. Hypothèses'!$E$54*12 -> 42000000 | Q13: =N13+O13+P13 -> 92400000
A14: Infrastructure IT (cloud, SaaS) | B14: ='2. Hypothèses'!$C$55 -> 2200000 | C14: ='2. Hypothèses'!$C$55 -> 2200000 | D14: ='2. Hypothèses'!$C$55 -> 2200000 | E14: ='2. Hypothèses'!$C$55 -> 2200000 | F14: ='2. Hypothèses'!$C$55 -> 2200000 | G14: ='2. Hypothèses'!$C$55 -> 2200000 | H14: ='2. Hypothèses'!$C$55 -> 2200000 | I14: ='2. Hypothèses'!$C$55 -> 2200000 | ... M14: ='2. Hypothèses'!$C$55 -> 2200000 | N14: =SUM(B14:M14) -> 26400000 | O14: ='2. Hypothèses'!$D$55*12 -> 42000000 | P14: ='2. Hypothèses'!$E$55*12 -> 66000000 | Q14: =N14+O14+P14 -> 134400000
A15: Marketing & acquisition (campagnes) | B15: ='2. Hypothèses'!$C$56 -> 4500000 | C15: ='2. Hypothèses'!$C$56 -> 4500000 | D15: ='2. Hypothèses'!$C$56 -> 4500000 | E15: ='2. Hypothèses'!$C$56 -> 4500000 | F15: ='2. Hypothèses'!$C$56 -> 4500000 | G15: ='2. Hypothèses'!$C$56 -> 4500000 | H15: ='2. Hypothèses'!$C$56 -> 4500000 | I15: ='2. Hypothèses'!$C$56 -> 4500000 | ... M15: ='2. Hypothèses'!$C$56 -> 4500000 | N15: =SUM(B15:M15) -> 54000000 | O15: ='2. Hypothèses'!$D$56*12 -> 102000000 | P15: ='2. Hypothèses'!$E$56*12 -> 168000000 | Q15: =N15+O15+P15 -> 324000000
A16: Frais juridiques, conformité, audit | B16: ='2. Hypothèses'!$C$57 -> 1200000 | C16: ='2. Hypothèses'!$C$57 -> 1200000 | D16: ='2. Hypothèses'!$C$57 -> 1200000 | E16: ='2. Hypothèses'!$C$57 -> 1200000 | F16: ='2. Hypothèses'!$C$57 -> 1200000 | G16: ='2. Hypothèses'!$C$57 -> 1200000 | H16: ='2. Hypothèses'!$C$57 -> 1200000 | I16: ='2. Hypothèses'!$C$57 -> 1200000 | ... M16: ='2. Hypothèses'!$C$57 -> 1200000 | N16: =SUM(B16:M16) -> 14400000 | O16: ='2. Hypothèses'!$D$57*12 -> 18000000 | P16: ='2. Hypothèses'!$E$57*12 -> 24000000 | Q16: =N16+O16+P16 -> 56400000
A17: Télécoms, énergie, fournitures | B17: ='2. Hypothèses'!$C$58 -> 450000 | C17: ='2. Hypothèses'!$C$58 -> 450000 | D17: ='2. Hypothèses'!$C$58 -> 450000 | E17: ='2. Hypothèses'!$C$58 -> 450000 | F17: ='2. Hypothèses'!$C$58 -> 450000 | G17: ='2. Hypothèses'!$C$58 -> 450000 | H17: ='2. Hypothèses'!$C$58 -> 450000 | I17: ='2. Hypothèses'!$C$58 -> 450000 | ... M17: ='2. Hypothèses'!$C$58 -> 450000 | N17: =SUM(B17:M17) -> 5400000 | O17: ='2. Hypothèses'!$D$58*12 -> 7200000 | P17: ='2. Hypothèses'!$E$58*12 -> 10200000 | Q17: =N17+O17+P17 -> 22800000
A18: Autres frais généraux | B18: ='2. Hypothèses'!$C$59 -> 800000 | C18: ='2. Hypothèses'!$C$59 -> 800000 | D18: ='2. Hypothèses'!$C$59 -> 800000 | E18: ='2. Hypothèses'!$C$59 -> 800000 | F18: ='2. Hypothèses'!$C$59 -> 800000 | G18: ='2. Hypothèses'!$C$59 -> 800000 | H18: ='2. Hypothèses'!$C$59 -> 800000 | I18: ='2. Hypothèses'!$C$59 -> 800000 | ... M18: ='2. Hypothèses'!$C$59 -> 800000 | N18: =SUM(B18:M18) -> 9600000 | O18: ='2. Hypothèses'!$D$59*12 -> 12000000 | P18: ='2. Hypothèses'!$E$59*12 -> 18000000 | Q18: =N18+O18+P18 -> 39600000
A19: Sous-total Autres charges fixes | B19: =B13+B14+B15+B16+B17+B18 -> 10950000 | C19: =C13+C14+C15+C16+C17+C18 -> 10950000 | D19: =D13+D14+D15+D16+D17+D18 -> 10950000 | E19: =E13+E14+E15+E16+E17+E18 -> 10950000 | F19: =F13+F14+F15+F16+F17+F18 -> 10950000 | G19: =G13+G14+G15+G16+G17+G18 -> 10950000 | H19: =H13+H14+H15+H16+H17+H18 -> 10950000 | I19: =I13+I14+I15+I16+I17+I18 -> 10950000 | ... Q19: =Q13+Q14+Q15+Q16+Q17+Q18 -> 669600000
A21: TOTAL CHARGES FIXES
A22: TOTAL CHARGES FIXES | B22: =B9+B19 -> 28600000 | C22: =C9+C19 -> 28600000 | D22: =D9+D19 -> 28600000 | E22: =E9+E19 -> 28600000 | F22: =F9+F19 -> 28600000 | G22: =G9+G19 -> 28600000 | H22: =H9+H19 -> 28600000 | I22: =I9+I19 -> 28600000 | ... Q22: =Q9+Q19 -> 2004000000

Sheet 6. CAPEX & Amort.
A1: CAPEX & AMORTISSEMENTS
A3: Poste | B3: Année 1 | C3: Année 2 | D3: Année 3 | E3: Total 3 ans | F3: Durée (ans) | G3: Amort. annuel Y1 | H3: Amort. annuel Y2 | I3: Amort. annuel Y3
A4: CAPEX Tech (plateforme, dév. capitalisé) | B4: ='2. Hypothèses'!$C$61 -> 35000000 | C4: ='2. Hypothèses'!$D$61 -> 25000000 | D4: ='2. Hypothèses'!$E$61 -> 30000000 | E4: =B4+C4+D4 -> 90000000 | F4: ='2. Hypothèses'!$C$64 -> 5 | G4: =B4/F4 -> 7000000 | H4: =(B4+C4)/F4 -> 12000000 | I4: =(B4+C4+D4)/F4 -> 18000000
A5: CAPEX Équipements & aménagement | B5: ='2. Hypothèses'!$C$62 -> 18000000 | C5: ='2. Hypothèses'!$D$62 -> 12000000 | D5: ='2. Hypothèses'!$E$62 -> 20000000 | E5: =B5+C5+D5 -> 50000000 | F5: ='2. Hypothèses'!$C$64 -> 5 | G5: =B5/F5 -> 3600000 | H5: =(B5+C5)/F5 -> 6000000 | I5: =(B5+C5+D5)/F5 -> 10000000
A6: CAPEX Licences & agréments | B6: ='2. Hypothèses'!$C$63 -> 25000000 | C6: ='2. Hypothèses'!$D$63 -> 5000000 | D6: ='2. Hypothèses'!$E$63 -> 8000000 | E6: =B6+C6+D6 -> 38000000 | F6: ='2. Hypothèses'!$C$64 -> 5 | G6: =B6/F6 -> 5000000 | H6: =(B6+C6)/F6 -> 6000000 | I6: =(B6+C6+D6)/F6 -> 7600000
A7: TOTAL CAPEX / AMORTISSEMENTS | B7: =B4+B5+B6 -> 78000000 | C7: =C4+C5+C6 -> 42000000 | D7: =D4+D5+D6 -> 58000000 | E7: =E4+E5+E6 -> 178000000 | G7: =G4+G5+G6 -> 15600000 | H7: =H4+H5+H6 -> 24000000 | I7: =I4+I5+I6 -> 35600000

Sheet 7. P&L
A1: COMPTE DE RÉSULTAT (P&L) — 36 mois
B2: Année 1 (mensuel)
A3: Poste | B3: M1 | C3: M2 | D3: M3 | E3: M4 | F3: M5 | G3: M6 | H3: M7 | I3: M8 | J3: M9 | K3: M10 | L3: M11 | M3: M12 | N3: Total Y1 | O3: Année 2 | P3: Année 3 | Q3: Total 3 ans
A4: Chiffre d'affaires | B4: ='3. Revenus'!B32 -> 16606722 | C4: ='3. Revenus'!C32 -> 21461049 | D4: ='3. Revenus'!D32 -> 26970474 | E4: ='3. Revenus'!E32 -> 32287069 | F4: ='3. Revenus'!F32 -> 37417584 | G4: ='3. Revenus'!G32 -> 42368531 | H4: ='3. Revenus'!H32 -> 47146194 | I4: ='3. Revenus'!I32 -> 51756639 | ... M4: ='3. Revenus'!M32 -> 68640261 | N4: =SUM(B4:M4) -> 5.260015e+08 | O4: ='3. Revenus'!O32 -> 4.5823642e+09 | P4: ='3. Revenus'!P32 -> 1.4321308e+10 | Q4: =N4+O4+P4 -> 1.9429674e+10
A5: (-) Coûts variables | B5: =-'4. Coûts variables'!B21 -> -22217591 | C5: =-'4. Coûts variables'!C21 -> -25131527 | D5: =-'4. Coûts variables'!D21 -> -28438476 | E5: =-'4. Coûts variables'!E21 -> -31629681 | F5: =-'4. Coûts variables'!F21 -> -34709195 | G5: =-'4. Coûts variables'!G21 -> -37680925 | H5: =-'4. Coûts variables'!H21 -> -40548645 | I5: =-'4. Coûts variables'!I21 -> -43315994 | ... M5: =-'4. Coûts variables'!M21 -> -53450131 | N5: =SUM(B5:M5) -> -4.6272251e+08 | O5: =-'4. Coûts variables'!O21 -> -2.6997384e+09 | P5: =-'4. Coûts variables'!P21 -> -6.9331222e+09 | Q5: =N5+O5+P5 -> -1.0095583e+10
A6: MARGE CONTRIBUTIVE | B6: =B4+B5 -> -5610868.9 | C6: =C4+C5 -> -3670478.6 | D6: =D4+D5 -> -1468002 | E6: =E4+E5 -> 657387.98 | F6: =F4+F5 -> 2708389.3 | G6: =G4+G5 -> 4687605.5 | H6: =H4+H5 -> 6597549.2 | I6: =I4+I5 -> 8440644.9 | ... Q6: =Q4+Q5 -> 9.3340911e+09
A7: Taux de marge contributive | B7: =IFERROR(B6/B4,0) -> -0.33786733 | C7: =IFERROR(C6/C4,0) -> -0.17102979 | D7: =IFERROR(D6/D4,0) -> -0.054429965 | E7: =IFERROR(E6/E4,0) -> 0.02036072 | F7: =IFERROR(F6/F4,0) -> 0.072382794 | G7: =IFERROR(G6/G4,0) -> 0.11063885 | H7: =IFERROR(H6/H4,0) -> 0.13993811 | I7: =IFERROR(I6/I4,0) -> 0.16308333 | ... Q7: =IFERROR(Q6/Q4,0) -> 0.48040389
A9: (-) Charges fixes (masse salariale + autres) | B9: =-'5. Charges fixes'!B22 -> -28600000 | C9: =-'5. Charges fixes'!C22 -> -28600000 | D9: =-'5. Charges fixes'!D22 -> -28600000 | E9: =-'5. Charges fixes'!E22 -> -28600000 | F9: =-'5. Charges fixes'!F22 -> -28600000 | G9: =-'5. Charges fixes'!G22 -> -28600000 | H9: =-'5. Charges fixes'!H22 -> -28600000 | I9: =-'5. Charges fixes'!I22 -> -28600000 | ... M9: =-'5. Charges fixes'!M22 -> -28600000 | N9: =SUM(B9:M9) -> -343200000 | O9: =-'5. Charges fixes'!O22 -> -618000000 | P9: =-'5. Charges fixes'!P22 -> -1042800000 | Q9: =N9+O9+P9 -> -2004000000
A10: EBITDA (Excédent Brut d'Exploitation) | B10: =B6+B9 -> -34210869 | C10: =C6+C9 -> -32270479 | D10: =D6+D9 -> -30068002 | E10: =E6+E9 -> -27942612 | F10: =F6+F9 -> -25891611 | G10: =G6+G9 -> -23912394 | H10: =H6+H9 -> -22002451 | I10: =I6+I9 -> -20159355 | ... Q10: =Q6+Q9 -> 7.3300911e+09
A11: Marge EBITDA | B11: =IFERROR(B10/B4,0) -> -2.0600615 | C11: =IFERROR(C10/C4,0) -> -1.5036767 | D11: =IFERROR(D10/D4,0) -> -1.1148489 | E11: =IFERROR(E10/E4,0) -> -0.86544281 | F11: =IFERROR(F10/F4,0) -> -0.69196372 | G11: =IFERROR(G10/G4,0) -> -0.56439046 | H11: =IFERROR(H10/H4,0) -> -0.46668562 | I11: =IFERROR(I10/I4,0) -> -0.38950279 | ... Q11: =IFERROR(Q10/Q4,0) -> 0.37726269
A13: (-) Dotations aux amortissements | B13: =-'6. CAPEX & Amort.'!G7/12 -> -1300000 | C13: =-'6. CAPEX & Amort.'!G7/12 -> -1300000 | D13: =-'6. CAPEX & Amort.'!G7/12 -> -1300000 | E13: =-'6. CAPEX & Amort.'!G7/12 -> -1300000 | F13: =-'6. CAPEX & Amort.'!G7/12 -> -1300000 | G13: =-'6. CAPEX & Amort.'!G7/12 -> -1300000 | H13: =-'6. CAPEX & Amort.'!G7/12 -> -1300000 | I13: =-'6. CAPEX & Amort.'!G7/12 -> -1300000 | J13: =-'6. CAPEX & Amort.'!G7/12 -> -1300000 | K13: =-'6. CAPEX & Amort.'!G7/12 -> -1300000 | L13: =-'6. CAPEX & Amort.'!G7/12 -> -1300000 | M13: =-'6. CAPEX & Amort.'!G7/12 -> -1300000 | N13: =SUM(B13:M13) -> -15600000 | O13: =-'6. CAPEX & Amort.'!H7 -> -24000000 | P13: =-'6. CAPEX & Amort.'!I7 -> -35600000 | Q13: =N13+O13+P13 -> -75200000
A14: RÉSULTAT D'EXPLOITATION (EBIT) | B14: =B10+B13 -> -35510869 | C14: =C10+C13 -> -33570479 | D14: =D10+D13 -> -31368002 | E14: =E10+E13 -> -29242612 | F14: =F10+F13 -> -27191611 | G14: =G10+G13 -> -25212394 | H14: =H10+H13 -> -23302451 | I14: =I10+I13 -> -21459355 | ... Q14: =Q10+Q13 -> 7.2548911e+09
A16: (-) Impôt sur les sociétés (IS) | B16: =-MAX(0,B14*'2. Hypothèses'!$C$7) -> 0 | C16: =-MAX(0,C14*'2. Hypothèses'!$C$7) -> 0 | D16: =-MAX(0,D14*'2. Hypothèses'!$C$7) -> 0 | E16: =-MAX(0,E14*'2. Hypothèses'!$C$7) -> 0 | F16: =-MAX(0,F14*'2. Hypothèses'!$C$7) -> 0 | G16: =-MAX(0,G14*'2. Hypothèses'!$C$7) -> 0 | H16: =-MAX(0,H14*'2. Hypothèses'!$C$7) -> 0 | I16: =-MAX(0,I14*'2. Hypothèses'!$C$7) -> 0 | ... M16: =-MAX(0,M14*'2. Hypothèses'!$C$7) -> 0 | N16: =SUM(B16:M16) -> 0 | O16: =-MAX(0,O14*'2. Hypothèses'!$D$7) -> -3.7218775e+08 | P16: =-MAX(0,P14*'2. Hypothèses'!$E$7) -> -1.8929359e+09 | Q16: =N16+O16+P16 -> -2.2651236e+09
A17: RÉSULTAT NET | B17: =B14+B16 -> -35510869 | C17: =C14+C16 -> -33570479 | D17: =D14+D16 -> -31368002 | E17: =E14+E16 -> -29242612 | F17: =F14+F16 -> -27191611 | G17: =G14+G16 -> -25212394 | H17: =H14+H16 -> -23302451 | I17: =I14+I16 -> -21459355 | ... Q17: =Q14+Q16 -> 4.9897675e+09
A18: Marge nette | B18: =IFERROR(B17/B4,0) -> -2.1383431 | C18: =IFERROR(C17/C4,0) -> -1.5642515 | D18: =IFERROR(D17/D4,0) -> -1.1630497 | E18: =IFERROR(E17/E4,0) -> -0.9057066 | F18: =IFERROR(F17/F4,0) -> -0.72670675 | G18: =IFERROR(G17/G4,0) -> -0.59507361 | H18: =IFERROR(H17/H4,0) -> -0.49425943 | I18: =IFERROR(I17/I4,0) -> -0.41462034 | ... Q18: =IFERROR(Q17/Q4,0) -> 0.25681169

Sheet 8. Trésorerie
A1: PLAN DE TRÉSORERIE — 36 mois
B2: Année 1 (mensuel)
A3: Poste | B3: M1 | C3: M2 | D3: M3 | E3: M4 | F3: M5 | G3: M6 | H3: M7 | I3: M8 | J3: M9 | K3: M10 | L3: M11 | M3: M12 | N3: Total Y1 | O3: Année 2 | P3: Année 3 | Q3: Total 3 ans
A4: Trésorerie début de période | B4: ='2. Hypothèses'!$C$66 -> 350000000 | C4: =B18 -> 2.3778913e+08 | D4: =C18 -> 2.0551865e+08 | E4: =D18 -> 1.7545065e+08 | F4: =E18 -> 1.4750804e+08 | G4: =F18 -> 1.2161643e+08 | H4: =G18 -> 97704033 | I4: =H18 -> 75701583 | J4: =I18 -> 55542227 | ... M4: =L18 -> 5488862.4
A5: ENCAISSEMENTS
A6: Encaissements d'exploitation (CA) | B6: ='7. P&L'!B4 -> 16606722 | C6: ='7. P&L'!C4 -> 21461049 | D6: ='7. P&L'!D4 -> 26970474 | E6: ='7. P&L'!E4 -> 32287069 | F6: ='7. P&L'!F4 -> 37417584 | G6: ='7. P&L'!G4 -> 42368531 | H6: ='7. P&L'!H4 -> 47146194 | I6: ='7. P&L'!I4 -> 51756639 | ... M6: ='7. P&L'!M4 -> 68640261 | N6: =SUM(B6:M6) -> 5.260015e+08 | O6: ='7. P&L'!O4 -> 4.5823642e+09 | P6: ='7. P&L'!P4 -> 1.4321308e+10 | Q6: =N6+O6+P6 -> 1.9429674e+10
A7: Levées de fonds | B7: 0 | C7: 0 | D7: 0 | E7: 0 | F7: 0 | G7: 0 | H7: 0 | I7: 0 | J7: 0 | K7: 0 | L7: 0 | M7: 0 | N7: =SUM(B7:M7) -> 0 | O7: ='2. Hypothèses'!$D$67 -> 800000000 | P7: ='2. Hypothèses'!$E$68 -> 1500000000 | Q7: =N7+O7+P7 -> 2300000000
A8: Total encaissements | B8: =B6+B7 -> 16606722 | C8: =C6+C7 -> 21461049 | D8: =D6+D7 -> 26970474 | E8: =E6+E7 -> 32287069 | F8: =F6+F7 -> 37417584 | G8: =G6+G7 -> 42368531 | H8: =H6+H7 -> 47146194 | I8: =I6+I7 -> 51756639 | ... Q8: =Q6+Q7 -> 2.1729674e+10
A10: DÉCAISSEMENTS
A11: Coûts variables | B11: =-'7. P&L'!B5 -> 22217591 | C11: =-'7. P&L'!C5 -> 25131527 | D11: =-'7. P&L'!D5 -> 28438476 | E11: =-'7. P&L'!E5 -> 31629681 | F11: =-'7. P&L'!F5 -> 34709195 | G11: =-'7. P&L'!G5 -> 37680925 | H11: =-'7. P&L'!H5 -> 40548645 | I11: =-'7. P&L'!I5 -> 43315994 | ... M11: =-'7. P&L'!M5 -> 53450131 | N11: =SUM(B11:M11) -> 4.6272251e+08 | O11: =-'7. P&L'!O5 -> 2.6997384e+09 | P11: =-'7. P&L'!P5 -> 6.9331222e+09 | Q11: =N11+O11+P11 -> 1.0095583e+10
A12: Charges fixes | B12: =-'7. P&L'!B9 -> 28600000 | C12: =-'7. P&L'!C9 -> 28600000 | D12: =-'7. P&L'!D9 -> 28600000 | E12: =-'7. P&L'!E9 -> 28600000 | F12: =-'7. P&L'!F9 -> 28600000 | G12: =-'7. P&L'!G9 -> 28600000 | H12: =-'7. P&L'!H9 -> 28600000 | I12: =-'7. P&L'!I9 -> 28600000 | ... M12: =-'7. P&L'!M9 -> 28600000 | N12: =SUM(B12:M12) -> 343200000 | O12: =-'7. P&L'!O9 -> 618000000 | P12: =-'7. P&L'!P9 -> 1042800000 | Q12: =N12+O12+P12 -> 2004000000
A13: Impôts (IS) | B13: =-'7. P&L'!B16 -> 0 | C13: =-'7. P&L'!C16 -> 0 | D13: =-'7. P&L'!D16 -> 0 | E13: =-'7. P&L'!E16 -> 0 | F13: =-'7. P&L'!F16 -> 0 | G13: =-'7. P&L'!G16 -> 0 | H13: =-'7. P&L'!H16 -> 0 | I13: =-'7. P&L'!I16 -> 0 | ... M13: =-'7. P&L'!M16 -> 0 | N13: =SUM(B13:M13) -> 0 | O13: =-'7. P&L'!O16 -> 3.7218775e+08 | P13: =-'7. P&L'!P16 -> 1.8929359e+09 | Q13: =N13+O13+P13 -> 2.2651236e+09
A14: Investissements (CAPEX) | B14: ='6. CAPEX & Amort.'!B7 -> 78000000 | C14: 0 | D14: 0 | E14: 0 | F14: 0 | G14: 0 | H14: 0 | I14: 0 | J14: 0 | K14: 0 | L14: 0 | M14: 0 | N14: =SUM(B14:M14) -> 78000000 | O14: ='6. CAPEX & Amort.'!C7 -> 42000000 | P14: ='6. CAPEX & Amort.'!D7 -> 58000000 | Q14: =N14+O14+P14 -> 178000000
A15: Total décaissements | B15: =B11+B12+B13+B14 -> 1.2881759e+08 | C15: =C11+C12+C13+C14 -> 53731527 | D15: =D11+D12+D13+D14 -> 57038476 | E15: =E11+E12+E13+E14 -> 60229681 | F15: =F11+F12+F13+F14 -> 63309195 | G15: =G11+G12+G13+G14 -> 66280925 | H15: =H11+H12+H13+H14 -> 69148645 | I15: =I11+I12+I13+I14 -> 71915994 | ... Q15: =Q11+Q12+Q13+Q14 -> 1.4542707e+10
A17: VARIATION DE TRÉSORERIE | B17: =B8-B15 -> -1.1221087e+08 | C17: =C8-C15 -> -32270479 | D17: =D8-D15 -> -30068002 | E17: =E8-E15 -> -27942612 | F17: =F8-F15 -> -25891611 | G17: =G8-G15 -> -23912394 | H17: =H8-H15 -> -22002451 | I17: =I8-I15 -> -20159355 | ... Q17: =Q8-Q15 -> 7.1869675e+09
A18: TRÉSORERIE FIN DE PÉRIODE | B18: =B4+B17 -> 2.3778913e+08 | C18: =C4+C17 -> 2.0551865e+08 | D18: =D4+D17 -> 1.7545065e+08 | E18: =E4+E17 -> 1.4750804e+08 | F18: =F4+F17 -> 1.2161643e+08 | G18: =G4+G17 -> 97704033 | H18: =H4+H17 -> 75701583 | I18: =I4+I17 -> 55542227 | ... M18: =M4+M17 -> -7921008.1 | N18: =M18 -> -7921008.1 | O18: =N18+O17 -> 1.6425171e+09 | P18: =O18+P17 -> 7.5369675e+09 | Q18: =P18 -> 7.5369675e+09

Sheet 9. KPIs Dashboard
A1: DASHBOARD KPIs & INDICATEURS DE PILOTAGE
A3: Indicateur | B3: Unité | C3: Année 1 | D3: Année 2 | E3: Année 3 | F3: Commentaire
A4: Croissance & Base utilisateurs
A5: Utilisateurs inscrits (fin de période) | B5: users | C5: ='3. Revenus'!N7/'2. Hypothèses'!$C$15 -> 24211.936 | D5: ='3. Revenus'!O7/'2. Hypothèses'!$D$15 -> 118167.05 | E5: ='3. Revenus'!P7/'2. Hypothèses'!$E$15 -> 236727.66 | F5: Cumul d'inscrits
A6: MAU moyen | B6: users | C6: ='3. Revenus'!N7 -> 13316.565 | D6: ='3. Revenus'!O7 -> 73263.574 | E6: ='3. Revenus'!P7 -> 160974.81 | F6: Utilisateurs actifs moyens
A7: Croissance MAU YoY | B7: % | C7: ="N/A" -> N/A | D7: =D6/C6-1 -> 4.5016872 | E7: =E6/D6-1 -> 1.1972012 | F7: Taux de croissance annuel
A8: Churn mensuel | B8: % | C8: ='2. Hypothèses'!$C$14 -> 0.035 | D8: ='2. Hypothèses'!$D$14 -> 0.025 | E8: ='2. Hypothèses'!$E$14 -> 0.02 | F8: Taux de désabonnement
A9: Revenus & Rentabilité
A10: Chiffre d'affaires | B10: FCFA | C10: ='7. P&L'!N4 -> 5.260015e+08 | D10: ='7. P&L'!O4 -> 4.5823642e+09 | E10: ='7. P&L'!P4 -> 1.4321308e+10 | F10: CA total annuel
A11: Croissance CA YoY | B11: % | C11: ="N/A" -> N/A | D11: =D10/C10-1 -> 7.7116942 | E11: =E10/D10-1 -> 2.12531 | F11: Taux de croissance CA
A12: ARPU (Revenu / user actif / mois) | B12: FCFA | C12: ='7. P&L'!N4/'3. Revenus'!N7/12 -> 3291.6491 | D12: ='7. P&L'!O4/'3. Revenus'!O7/12 -> 5212.1902 | E12: ='7. P&L'!P4/'3. Revenus'!P7/12 -> 7413.8454 | F12: Revenu par utilisateur actif
A13: Marge contributive | B13: FCFA | C13: ='7. P&L'!N6 -> 63278992 | D13: ='7. P&L'!O6 -> 1.8826258e+09 | E13: ='7. P&L'!P6 -> 7.3881862e+09 | F13: CA - Coûts variables
A14: Taux de marge contributive | B14: % | C14: =IFERROR('7. P&L'!N6/'7. P&L'!N4,0) -> 0.12030192 | D14: =IFERROR('7. P&L'!O6/'7. P&L'!O4,0) -> 0.4108416 | E14: =IFERROR('7. P&L'!P6/'7. P&L'!P4,0) -> 0.51588766 | F14: Marge variable
A15: EBITDA | B15: FCFA | C15: ='7. P&L'!N10 -> -2.7992101e+08 | D15: ='7. P&L'!O10 -> 1.2646258e+09 | E15: ='7. P&L'!P10 -> 6.3453862e+09 | F15: Excédent brut d'exploitation
A16: Marge EBITDA | B16: % | C16: =IFERROR('7. P&L'!N10/'7. P&L'!N4,0) -> -0.5321677 | D16: =IFERROR('7. P&L'!O10/'7. P&L'!O4,0) -> 0.27597672 | E16: =IFERROR('7. P&L'!P10/'7. P&L'!P4,0) -> 0.44307308 | F16: Rentabilité opérationnelle
A17: Résultat net | B17: FCFA | C17: ='7. P&L'!N17 -> -2.9552101e+08 | D17: ='7. P&L'!O17 -> 8.6843809e+08 | E17: ='7. P&L'!P17 -> 4.4168504e+09 | F17: Bottom line
A18: Unit Economics
A19: CAC (Coût acquisition client) | B19: FCFA | C19: ='2. Hypothèses'!$C$72 -> 3500 | D19: ='2. Hypothèses'!$D$72 -> 3000 | E19: ='2. Hypothèses'!$E$72 -> 2500 | F19: Marketing + acquisition par user
A20: ARPU annuel | B20: FCFA | C20: ='7. P&L'!N4/'3. Revenus'!N7 -> 39499.789 | D20: ='7. P&L'!O4/'3. Revenus'!O7 -> 62546.283 | E20: ='7. P&L'!P4/'3. Revenus'!P7 -> 88966.145 | F20: Revenu annuel par user
A21: Marge contributive par user (annuelle) | B21: FCFA | C21: ='7. P&L'!N6/'3. Revenus'!N7 -> 4751.9006 | D21: ='7. P&L'!O6/'3. Revenus'!O7 -> 25696.615 | E21: ='7. P&L'!P6/'3. Revenus'!P7 -> 45896.536 | F21: Contribution unitaire
A22: LTV (Lifetime Value) | B22: FCFA | C22: =(C21/12)*(1/'2. Hypothèses'!$C$14) -> 11314.049 | D22: =(D21/12)*(1/'2. Hypothèses'!$D$14) -> 85655.383 | E22: =(E21/12)*(1/'2. Hypothèses'!$E$14) -> 191235.57 | F22: Marge mensuelle × durée de vie
A23: Ratio LTV/CAC | B23: x | C23: =IFERROR(C22/'2. Hypothèses'!$C$72,0) -> 3.2325855 | D23: =IFERROR(D22/'2. Hypothèses'!$D$72,0) -> 28.551794 | E23: =IFERROR(E22/'2. Hypothèses'!$E$72,0) -> 76.494227 | F23: Doit être > 3x (benchmark SaaS/fintech)
A24: Payback CAC (mois) | B24: mois | C24: =IFERROR('2. Hypothèses'!$C$72/(C21/12),0) -> 8.8385687 | D24: =IFERROR('2. Hypothèses'!$D$72/(D21/12),0) -> 1.4009627 | E24: =IFERROR('2. Hypothèses'!$E$72/(E21/12),0) -> 0.6536441 | F24: Délai de récupération du CAC
A25: Structure de coûts
A26: Coûts variables | B26: FCFA | C26: =-'7. P&L'!N5 -> 4.6272251e+08 | D26: =-'7. P&L'!O5 -> 2.6997384e+09 | E26: =-'7. P&L'!P5 -> 6.9331222e+09 | F26: Total CV
A27: Charges fixes | B27: FCFA | C27: =-'7. P&L'!N9 -> 343200000 | D27: =-'7. P&L'!O9 -> 618000000 | E27: =-'7. P&L'!P9 -> 1042800000 | F27: Total CF
A28: Ratio CF / CA | B28: % | C28: =IFERROR(-'7. P&L'!N9/'7. P&L'!N4,0) -> 0.65246963 | D28: =IFERROR(-'7. P&L'!O9/'7. P&L'!O4,0) -> 0.13486488 | E28: =IFERROR(-'7. P&L'!P9/'7. P&L'!P4,0) -> 0.072814576 | F28: Poids charges fixes
A29: Seuil de rentabilité (CA break-even) | B29: FCFA | C29: =IFERROR(-'7. P&L'!N9/('7. P&L'!N6/'7. P&L'!N4),0) -> 2.8528222e+09 | D29: =IFERROR(-'7. P&L'!O9/('7. P&L'!O6/'7. P&L'!O4),0) -> 1.5042294e+09 | E29: =IFERROR(-'7. P&L'!P9/('7. P&L'!P6/'7. P&L'!P4),0) -> 2.0213703e+09 | F29: CA minimum pour couvrir CF
A30: Trésorerie & Runway
A31: Trésorerie fin de période | B31: FCFA | C31: ='8. Trésorerie'!N18 -> -7921008.1 | D31: ='8. Trésorerie'!O18 -> 1.6425171e+09 | E31: ='8. Trésorerie'!P18 -> 7.5369675e+09 | F31: Cash disponible
A32: Cash burn / brûlure (annuel) | B32: FCFA | C32: =MIN(0,'7. P&L'!N10) -> -2.7992101e+08 | D32: =MIN(0,'7. P&L'!O10) -> 0 | E32: =MIN(0,'7. P&L'!P10) -> 0 | F32: EBITDA si négatif
A33: Cash burn mensuel moyen | B33: FCFA | C33: =C32/12 -> -23326751 | D33: =D32/12 -> 0 | E33: =E32/12 -> 0 | F33: Si pertes
A34: Runway (mois) | B34: mois | C34: =IFERROR(IF(C33<0,C31/-C33,"Profitable"),0) -> -0.33956757 | D34: =IFERROR(IF(D33<0,D31/-D33,"Profitable"),0) -> Profitable | E34: =IFERROR(IF(E33<0,E31/-E33,"Profitable"),0) -> Profitable | F34: Mois restants avant cash-out
A35: Productivité & Efficience
A36: Effectif total (ETP) | B36: ETP | C36: ='2. Hypothèses'!$C$45+'2. Hypothèses'!$C$46+'2. Hypothèses'!$C$47+'2. Hypothèses'!$C$48 -> 25 | D36: ='2. Hypothèses'!$D$45+'2. Hypothèses'!$D$46+'2. Hypothèses'!$D$47+'2. Hypothèses'!$D$48 -> 46 | E36: ='2. Hypothèses'!$E$45+'2. Hypothèses'!$E$46+'2. Hypothèses'!$E$47+'2. Hypothèses'!$E$48 -> 76 | F36: Headcount total
A37: CA par ETP (annuel) | B37: FCFA | C37: ='7. P&L'!N4/C36 -> 21040060 | D37: ='7. P&L'!O4/D36 -> 99616613 | E37: ='7. P&L'!P4/E36 -> 1.8843827e+08 | F37: Productivité par tête
A38: MAU par ETP | B38: users | C38: ='3. Revenus'!N7/C36 -> 532.66259 | D38: ='3. Revenus'!O7/D36 -> 1592.6864 | E38: ='3. Revenus'!P7/E36 -> 2118.0896 | F38: Levier opérationnel

Sheet 10. Scénarios
A1: ANALYSE DE SCÉNARIOS — Sensibilité
A3: Ce tableau présente l'impact sur la rentabilité de variations des hypothèses clés. Pour basculer entre scénarios, modifier manuellement les valeurs dans la feuille 'Hypothèses'. Les colonnes ci-dessous montrent l'effet attendu de chaque scénario.
A6: Indicateur Année 3 | B6: Unité | C6: Pessimiste | D6: Base (actuel) | E6: Optimiste | F6: Δ Pess. vs Base | G6: Δ Opt. vs Base | H6: Commentaire
A7: MAU fin Année 3 | B7: users | C7: ='3. Revenus'!P7*0.7*(1-('2. Hypothèses'!$E$14*1.5-'2. Hypothèses'!$E$14)) -> 111555.54 | D7: ='3. Revenus'!P7 -> 160974.81 | E7: ='3. Revenus'!P7*1.25*(1+('2. Hypothèses'!$E$14-'2. Hypothèses'!$E$14*0.7)) -> 202425.83 | F7: =C7/D7-1 -> -0.307 | G7: =E7/D7-1 -> 0.2575 | H7: Sensibilité acquisition × churn
A8: Chiffre d'affaires Année 3 | B8: FCFA | C8: =C7*('7. P&L'!P4/'3. Revenus'!P7)*0.85 -> 8.4359667e+09 | D8: ='7. P&L'!P4 -> 1.4321308e+10 | E8: =E7*('7. P&L'!P4/'3. Revenus'!P7)*1.15 -> 2.0710402e+10 | F8: =C8/D8-1 -> -0.41095 | G8: =E8/D8-1 -> 0.446125 | H8: Effet volume × ARPU
A9: Marge contributive Année 3 | B9: FCFA | C9: =C8*('7. P&L'!P6/'7. P&L'!P4) -> 4.3520111e+09 | D9: ='7. P&L'!P6 -> 7.3881862e+09 | E9: =E8*('7. P&L'!P6/'7. P&L'!P4) -> 1.0684241e+10 | F9: =C9/D9-1 -> -0.41095 | G9: =E9/D9-1 -> 0.446125 | H9: Linéaire au CA
A10: Charges fixes Année 3 | B10: FCFA | C10: =-'7. P&L'!P9*1.2 -> 1251360000 | D10: =-'7. P&L'!P9 -> 1042800000 | E10: =-'7. P&L'!P9*0.9 -> 938520000 | F10: =C10/D10-1 -> 0.2 | G10: =E10/D10-1 -> -0.1 | H10: Variation maîtrise des charges
A11: EBITDA Année 3 | B11: FCFA | C11: =C9-C10 -> 3.1006511e+09 | D11: =D9-D10 -> 6.3453862e+09 | E11: =E9-E10 -> 9.7457208e+09 | F11: =IFERROR(C11/D11-1,0) -> -0.51135345 | G11: =IFERROR(E11/D11-1,0) -> 0.53587512 | H11: Résultat opérationnel
A12: Marge EBITDA Année 3 | B12: % | C12: =IFERROR(C11/C8,0) -> 0.36755137 | D12: =IFERROR(D11/D8,0) -> 0.44307308 | E12: =IFERROR(E11/E8,0) -> 0.4705713 | H12: Rentabilité opérationnelle
A14: Hypothèses appliquées par scénario
A15: Acquisition utilisateurs | C15: -30% | D15: Référence | E15: +25% | H15: % variation vs base
A16: Churn mensuel | C16: +50% | D16: Référence | E16: -30% | H16: % variation vs base
A17: ARPU (revenu / user) | C17: -15% | D17: Référence | E17: +15% | H17: % variation vs base
