Workbook

Sheet 1. Notice
A1: MODÈLE FINANCIER ETI BTP BÂTIMENTS — NOTICE D'UTILISATION
A3: Périmètre | B3: Entreprise de BTP — Spécialité Bâtiments (publics, logements, tertiaire) — Zone UEMOA/CEMAC
A4: Profil | B4: ETI — 10-20 chantiers actifs, CA 20-80 Md FCFA/an, marchés publics et institutionnels
A5: Horizon | B5: 5 années (Y1 mensuel + Y2 à Y5 annuels) — projets pluriannuels
A6: Devise | B6: FCFA — Reconnaissance CA à l'avancement (POC) selon IFRS 15 / SYSCOHADA
A8: STRUCTURE DU CLASSEUR
A9: Feuille | B9: Contenu
A10: 1. Notice | B10: Mode d'emploi, code couleurs, hypothèses-clés
A11: 2. Hypothèses | B11: Tous les inputs pilotables : macro, commercial, opérations, financement
A12: 3. Pipeline & Backlog | B12: Carnet de commandes, taux de transformation appels d'offres
A13: 4. Portefeuille chantiers | B13: Catalogue détaillé des 12 chantiers types avec planning d'avancement
A14: 5. Décomptes & encaissements | B14: Reconnaissance CA mensuelle + plan d'encaissement (avances, RG, délais Etat)
A15: 6. BFR & cautions | B15: Avance démarrage, retenues garantie, cautions bancaires et leurs coûts
A16: 7. Sous-traitance & cotraitance | B16: Quote-part ST/CT, marge groupement, coûts associés
A17: 8. Parc matériel | B17: Engins, amortissements, location vs propriété, ratios d'utilisation
A18: 9. Charges fixes & RH | B18: Masse salariale par pôle, charges structure
A19: 10. CAPEX & Amortissements | B19: Investissements matériel et structure, plan d'amortissement
A20: 11. P&L | B20: Compte de résultat — CA → Marge brute chantier → EBITDA → EBIT → Net
... A23: 14. Scénarios | B23: Pessimiste / Base / Optimiste — sensibilité sur paramètres clés
A26: CODE COULEURS (conventions financières)
A27: Convention | B27: Signification
A28: Cellule bleue sur fond jaune | B28: Input modifiable — hypothèse à piloter
A29: Texte noir | B29: Formule de calcul interne à la feuille
A30: Texte vert | B30: Lien vers une autre feuille du classeur
A31: Fond marine + texte blanc | B31: Total ou sous-total agrégé
A32: Fond or pâle + texte marine | B32: Sous-total intermédiaire
A35: POINTS DE VIGILANCE BTP
A36: • Reconnaissance CA à l'avancement (POC) : le revenu comptable diffère du flux de trésorerie ; bien distinguer P&L et trésorerie.
A37: • Délais de paiement Etat (DSO) : 90 à 180 jours en moyenne UEMOA/CEMAC, parfois plus selon arriérés budgétaires.
A38: • Retenue de garantie (5 à 10%) : libérée après réception définitive (DGD), généralement 12 mois après réception provisoire.
A39: • Cautions bancaires : commissions 1-3% l'an + dépôt de contre-garantie 10-25% → coût financier significatif à intégrer.
A40: • BFR négatif possible en phase d'avance de démarrage, fortement positif en pleine exécution → tension de trésorerie.
A41: • Avenants & révision de prix : prévoir 5 à 15% du marché initial, formule de révision indexée (généralement P0+P1·M/M0+P2·S/S0).
A42: • Marge brute chantier visée 12-18% ; après FG et frais financiers, marge nette cible 4-8%.

Sheet 2. Hypothèses
A1: HYPOTHÈSES — PARAMÈTRES PILOTABLES (5 ans)
A3: Paramètre | B3: Unité | C3: Année 1 | D3: Année 2 | E3: Année 3 | F3: Année 4 | G3: Année 5 | H3: Commentaire
A4: MACRO-ÉCONOMIE & FISCAL
A5: Taux d'inflation (BTP) | B5: % | C5: 0.045 | D5: 0.04 | E5: 0.035 | F5: 0.035 | G5: 0.03 | H5: Indice BT général UEMOA
A6: Taux d'IS | B6: % | C6: 0.3 | D6: 0.3 | E6: 0.3 | F6: 0.3 | G6: 0.3 | H6: Impôt sur les sociétés zone UEMOA/CEMAC
A7: Taux TVA | B7: % | C7: 0.18 | D7: 0.18 | E7: 0.18 | F7: 0.18 | G7: 0.18 | H7: TVA standard
A8: Taux Euribor / référence | B8: % | C8: 0.04 | D8: 0.04 | E8: 0.035 | F8: 0.035 | G8: 0.03 | H8: Référence financière
A9: COMMERCIAL & PIPELINE
A10: Appels d'offres soumis | B10: nb/an | C10: 28 | D10: 35 | E10: 42 | F10: 48 | G10: 55 | H10: Volume d'AO étudiés et chiffrés
A11: Taux de transformation AO | B11: % | C11: 0.32 | D11: 0.35 | E11: 0.38 | F11: 0.4 | G11: 0.42 | H11: Hit-rate moyen
A12: Valeur moyenne chantier signé | B12: FCFA | C12: 3500000000 | D12: 4200000000 | E12: 5000000000 | F12: 5800000000 | G12: 6500000000 | H12: Ticket moyen marché
A13: Durée moyenne chantier | B13: mois | C13: 18 | D13: 20 | E13: 22 | F13: 24 | G13: 24 | H13: Exécution physique
A14: Backlog initial (carnet entrée Y1) | B14: FCFA | C14: 35000000000 | D14: 0 | E14: 0 | F14: 0 | G14: 0 | H14: Carnet de commandes au 01/01
A15: Coût commercial / AO étudié | B15: FCFA | C15: 4500000 | D15: 4800000 | E15: 5200000 | F15: 5500000 | G15: 5800000 | H15: Coût bureau d'études + ingénierie d'offres
A16: STRUCTURE PRIX & MARGES CHANTIER
A17: Marge brute chantier visée | B17: % | C17: 0.14 | D17: 0.15 | E17: 0.16 | F17: 0.16 | G17: 0.17 | H17: Cible avant FG et frais financiers
A18: Avenants & révision prix | B18: % du marché | C18: 0.08 | D18: 0.09 | E18: 0.1 | F18: 0.1 | G18: 0.1 | H18: Avenants techniques + révision prix formule P0/P1/P2/S
A19: Marge sur avenants | B19: % | C19: 0.18 | D19: 0.19 | E19: 0.2 | F19: 0.2 | G19: 0.2 | H19: Meilleure marge sur avenants (moins compétitif)
A20: Réclamations recouvrées | B20: % du marché | C20: 0.015 | D20: 0.02 | E20: 0.02 | F20: 0.02 | G20: 0.02 | H20: Claims aboutis / marché initial
A21: DÉCOMPOSITION COÛTS DIRECTS CHANTIER
A22: Part matériaux | B22: % des coûts directs | C22: 0.36 | D22: 0.36 | E22: 0.35 | F22: 0.35 | G22: 0.35 | H22: Ciment, acier, agrégats, second œuvre
A23: Part main d'œuvre directe | B23: % des coûts directs | C23: 0.22 | D23: 0.22 | E23: 0.21 | F23: 0.21 | G23: 0.2 | H23: Ouvriers, chefs d'équipe
A24: Part sous-traitance | B24: % des coûts directs | C24: 0.22 | D24: 0.23 | E24: 0.24 | F24: 0.25 | G24: 0.26 | H24: ST lots techniques
A25: Part matériel & engins | B25: % des coûts directs | C25: 0.1 | D25: 0.1 | E25: 0.11 | F25: 0.11 | G25: 0.12 | H25: Location + amort + carburant
A26: Part frais de chantier | B26: % des coûts directs | C26: 0.1 | D26: 0.09 | E26: 0.09 | F26: 0.08 | G26: 0.07 | H26: Installation, encadrement, sécurité, divers
A27: SOUS-TRAITANCE & COTRAITANCE
A28: Marge ST récupérée (mark-up) | B28: % | C28: 0.08 | D28: 0.09 | E28: 0.1 | F28: 0.1 | G28: 0.1 | H28: Marge dégagée sur la ST par rapport au coût
A29: Part chantiers en cotraitance | B29: % | C29: 0.25 | D29: 0.3 | E29: 0.32 | F29: 0.35 | G29: 0.35 | H29: Chantiers exécutés en groupement
A30: Quote-part moyenne en cotraitance | B30: % | C30: 0.55 | D30: 0.55 | E30: 0.55 | F30: 0.55 | G30: 0.55 | H30: Quote-part de l'entreprise dans groupement
A31: Caution sous-traitants vs nous | B31: % | C31: 0.05 | D31: 0.05 | E31: 0.05 | F31: 0.05 | G31: 0.05 | H31: Retenue garantie sur ST
A32: BFR & CONDITIONS DE PAIEMENT
A33: Avance de démarrage | B33: % du marché | C33: 0.15 | D33: 0.15 | E33: 0.15 | F33: 0.15 | G33: 0.15 | H33: Versée à la signature
A34: Retenue de garantie | B34: % des décomptes | C34: 0.07 | D34: 0.07 | E34: 0.07 | F34: 0.07 | G34: 0.07 | H34: Retenue sur chaque CP, libérée au DGD
A35: Délai retenue de garantie | B35: mois après réception | C35: 12 | D35: 12 | E35: 12 | F35: 12 | G35: 12 | H35: Délai libération RG
A36: Délai moyen paiement Etat (DSO) | B36: jours | C36: 120 | D36: 110 | E36: 100 | F36: 95 | G36: 90 | H36: Délai de règlement décompte certifié
A37: Délai fournisseurs (DPO) | B37: jours | C37: 60 | D37: 65 | E37: 65 | F37: 70 | G37: 70 | H37: Délai de paiement fournisseurs
A38: Délai paiement ST (DPO-ST) | B38: jours | C38: 75 | D38: 75 | E38: 75 | F38: 75 | G38: 75 | H38: Délai paiement sous-traitants
A39: CAUTIONS BANCAIRES
A40: Caution de soumission | B40: % AO soumis | C40: 0.015 | D40: 0.015 | E40: 0.015 | F40: 0.015 | G40: 0.015 | H40: 1,5% du montant pour les AO
A41: Caution restitution avance | B41: % du marché | C41: 0.15 | D41: 0.15 | E41: 0.15 | F41: 0.15 | G41: 0.15 | H41: Égale à l'avance reçue
...

Sheet 3. Pipeline & Backlog
A1: PIPELINE COMMERCIAL & CARNET DE COMMANDES (BACKLOG)
A3: Indicateur | B3: Année 1 | C3: Année 2 | D3: Année 3 | E3: Année 4 | F3: Année 5 | H3: Commentaire
A4: ACTIVITÉ COMMERCIALE
A5: AO étudiés | B5: ='2. Hypothèses'!$C$10 -> 28 | C5: ='2. Hypothèses'!$D$10 -> 35 | D5: ='2. Hypothèses'!$E$10 -> 42 | E5: ='2. Hypothèses'!$F$10 -> 48 | F5: ='2. Hypothèses'!$G$10 -> 55 | H5: Appels d'offres soumis
A6: Taux de transformation | B6: ='2. Hypothèses'!$C$11 -> 0.32 | C6: ='2. Hypothèses'!$D$11 -> 0.35 | D6: ='2. Hypothèses'!$E$11 -> 0.38 | E6: ='2. Hypothèses'!$F$11 -> 0.4 | F6: ='2. Hypothèses'!$G$11 -> 0.42 | H6: Hit-rate
A7: Chantiers gagnés / an | B7: =ROUND(B5*B6,0) -> 9 | C7: =ROUND(C5*C6,0) -> 12 | D7: =ROUND(D5*D6,0) -> 16 | E7: =ROUND(E5*E6,0) -> 19 | F7: =ROUND(F5*F6,0) -> 23 | H7: Nb de nouveaux chantiers signés
A8: Valeur moyenne chantier | B8: ='2. Hypothèses'!$C$12 -> 3500000000 | C8: ='2. Hypothèses'!$D$12 -> 4200000000 | D8: ='2. Hypothèses'!$E$12 -> 5000000000 | E8: ='2. Hypothèses'!$F$12 -> 5800000000 | F8: ='2. Hypothèses'!$G$12 -> 6500000000 | H8: Ticket moyen
A9: PRISES DE COMMANDES & BACKLOG
A10: Prises de commandes / an | B10: =B7*B8 -> 31500000000 | C10: =C7*C8 -> 50400000000 | D10: =D7*D8 -> 80000000000 | E10: =E7*E8 -> 110200000000 | F10: =F7*F8 -> 149500000000 | H10: Valeur nouveaux marchés signés
A11: Backlog début de période | B11: ='2. Hypothèses'!$C$14 -> 35000000000 | C11: =B13 -> 5.3721682e+10 | D11: =C13 -> 6.2903732e+10 | E11: =D13 -> 7.8847269e+10 | F11: =E13 -> 9.5417481e+10 | H11: Carnet à l'ouverture
A12: CA reconnu (déversement) | B12: ='4. Portefeuille chantiers'!B23 -> 1.2778318e+10 | C12: ='4. Portefeuille chantiers'!C23 -> 41217950000 | D12: ='4. Portefeuille chantiers'!D23 -> 6.4056463e+10 | E12: ='4. Portefeuille chantiers'!E23 -> 9.3629787e+10 | F12: ='4. Portefeuille chantiers'!F23 -> 1.2671817e+11 | H12: CA reconnu à l'avancement
A13: Backlog fin de période | B13: =B11+B10-B12 -> 5.3721682e+10 | C13: =C11+C10-C12 -> 6.2903732e+10 | D13: =D11+D10-D12 -> 7.8847269e+10 | E13: =E11+E10-E12 -> 9.5417481e+10 | F13: =F11+F10-F12 -> 1.1819931e+11 | H13: Carnet de commandes à la clôture
A14: INDICATEURS PIPELINE
A15: Book-to-bill ratio | B15: =IFERROR(B10/B12,0) -> 2.4651131 | C15: =IFERROR(C10/C12,0) -> 1.2227682 | D15: =IFERROR(D10/D12,0) -> 1.2488982 | E15: =IFERROR(E10/E12,0) -> 1.1769759 | F15: =IFERROR(F10/F12,0) -> 1.1797835 | H15: Prises / CA reconnu (>1 = croissance)
A16: Couverture backlog (mois) | B16: =IFERROR(B13/(B12/12),0) -> 50.449533 | C16: =IFERROR(C13/(C12/12),0) -> 18.313496 | D16: =IFERROR(D13/(D12/12),0) -> 14.770832 | E16: =IFERROR(E13/(E12/12),0) -> 12.229119 | F16: =IFERROR(F13/(F12/12),0) -> 11.193279 | H16: Backlog / (CA / 12)
A17: Coût commercial total / an | B17: ='2. Hypothèses'!$C$15*'2. Hypothèses'!$C$10 -> 126000000 | C17: ='2. Hypothèses'!$D$15*'2. Hypothèses'!$D$10 -> 168000000 | D17: ='2. Hypothèses'!$E$15*'2. Hypothèses'!$E$10 -> 218400000 | E17: ='2. Hypothèses'!$F$15*'2. Hypothèses'!$F$10 -> 264000000 | F17: ='2. Hypothèses'!$G$15*'2. Hypothèses'!$G$10 -> 319000000 | H17: Coût bureau d'études d'offres
A18: Coût d'acquisition par chantier | B18: =IFERROR(B17/B7,0) -> 14000000 | C18: =IFERROR(C17/C7,0) -> 14000000 | D18: =IFERROR(D17/D7,0) -> 13650000 | E18: =IFERROR(E17/E7,0) -> 13894737 | F18: =IFERROR(F17/F7,0) -> 13869565 | H18: Coût AO / nb chantiers gagnés

Sheet 4. Portefeuille chantiers
A1: PORTEFEUILLE DES CHANTIERS — VUE PROJET
A3: Code | B3: Désignation | C3: Type | D3: Mois démarrage | E3: Durée (mois) | F3: Valeur (FCFA) | G3: M01 | H3: M02 | I3: M03 | J3: M04 | K3: M05 | L3: M06 | M3: M07 | N3: M08 | O3: M09 | P3: M10 | Q3: M11 | R3: M12 | S3: M13 | T3: M14 | U3: M15 | V3: M16 | W3: M17 | X3: M18 | Y3: M19 | Z3: M20 | AA3: M21 | AB3: M22 | AC3: M23 | AD3: M24 | AE3: M25 | AF3: M26 | AG3: M27 | AH3: M28 | AI3: M29 | AJ3: M30 | AK3: M31 | AL3: M32 | AM3: M33 | AN3: M34 | AO3: M35 | AP3: M36 | AQ3: M37 | AR3: M38 | AS3: M39 | AT3: M40 | AU3: M41 | AV3: M42 | AW3: M43 | AX3: M44 | AY3: M45 | AZ3: M46 | BA3: M47 | BB3: M48 | BC3: M49 | BD3: M50 | BE3: M51 | BF3: M52 | BG3: M53 | BH3: M54 | BI3: M55 | BJ3: M56 | BK3: M57 | BL3: M58 | BM3: M59 | BN3: M60
A4: CH-01 | B4: Logements sociaux Phase 1 | C4: Bâtiment public | D4: 1 | E4: 18 | F4: 4200000000 | G4: =IF(AND(1>=$D$4,1<=$D$4+$E$4-1),$F$4/$E$4,0) -> 2.3333333e+08 | H4: =IF(AND(2>=$D$4,2<=$D$4+$E$4-1),$F$4/$E$4,0) -> 2.3333333e+08 | I4: =IF(AND(3>=$D$4,3<=$D$4+$E$4-1),$F$4/$E$4,0) -> 2.3333333e+08 | J4: =IF(AND(4>=$D$4,4<=$D$4+$E$4-1),$F$4/$E$4,0) -> 2.3333333e+08 | K4: =IF(AND(5>=$D$4,5<=$D$4+$E$4-1),$F$4/$E$4,0) -> 2.3333333e+08 | L4: =IF(AND(6>=$D$4,6<=$D$4+$E$4-1),$F$4/$E$4,0) -> 2.3333333e+08 | M4: =IF(AND(7>=$D$4,7<=$D$4+$E$4-1),$F$4/$E$4,0) -> 2.3333333e+08 | N4: =IF(AND(8>=$D$4,8<=$D$4+$E$4-1),$F$4/$E$4,0) -> 2.3333333e+08 | O4: =IF(AND(9>=$D$4,9<=$D$4+$E$4-1),$F$4/$E$4,0) -> 2.3333333e+08 | P4: =IF(AND(10>=$D$4,10<=$D$4+$E$4-1),$F$4/$E$4,0) -> 2.3333333e+08 | Q4: =IF(AND(11>=$D$4,11<=$D$4+$E$4-1),$F$4/$E$4,0) -> 2.3333333e+08 | R4: =IF(AND(12>=$D$4,12<=$D$4+$E$4-1),$F$4/$E$4,0) -> 2.3333333e+08 | S4: =IF(AND(13>=$D$4,13<=$D$4+$E$4-1),$F$4/$E$4,0) -> 2.3333333e+08 | T4: =IF(AND(14>=$D$4,14<=$D$4+$E$4-1),$F$4/$E$4,0) -> 2.3333333e+08 | U4: =IF(AND(15>=$D$4,15<=$D$4+$E$4-1),$F$4/$E$4,0) -> 2.3333333e+08 | V4: =IF(AND(16>=$D$4,16<=$D$4+$E$4-1),$F$4/$E$4,0) -> 2.3333333e+08 | W4: =IF(AND(17>=$D$4,17<=$D$4+$E$4-1),$F$4/$E$4,0) -> 2.3333333e+08 | X4: =IF(AND(18>=$D$4,18<=$D$4+$E$4-1),$F$4/$E$4,0) -> 2.3333333e+08 | Y4: =IF(AND(19>=$D$4,19<=$D$4+$E$4-1),$F$4/$E$4,0) -> 0 | Z4: =IF(AND(20>=$D$4,20<=$D$4+$E$4-1),$F$4/$E$4,0) -> 0 | AA4: =IF(AND(21>=$D$4,21<=$D$4+$E$4-1),$F$4/$E$4,0) -> 0 | AB4: =IF(AND(22>=$D$4,22<=$D$4+$E$4-1),$F$4/$E$4,0) -> 0 | AC4: =IF(AND(23>=$D$4,23<=$D$4+$E$4-1),$F$4/$E$4,0) -> 0 | AD4: =IF(AND(24>=$D$4,24<=$D$4+$E$4-1),$F$4/$E$4,0) -> 0 | AE4: =IF(AND(25>=$D$4,25<=$D$4+$E$4-1),$F$4/$E$4,0) -> 0 | AF4: =IF(AND(26>=$D$4,26<=$D$4+$E$4-1),$F$4/$E$4,0) -> 0 | AG4: =IF(AND(27>=$D$4,27<=$D$4+$E$4-1),$F$4/$E$4,0) -> 0 | AH4: =IF(AND(28>=$D$4,28<=$D$4+$E$4-1),$F$4/$E$4,0) -> 0 | AI4: =IF(AND(29>=$D$4,29<=$D$4+$E$4-1),$F$4/$E$4,0) -> 0 | AJ4: =IF(AND(30>=$D$4,30<=$D$4+$E$4-1),$F$4/$E$4,0) -> 0 | AK4: =IF(AND(31>=$D$4,31<=$D$4+$E$4-1),$F$4/$E$4,0) -> 0 | AL4: =IF(AND(32>=$D$4,32<=$D$4+$E$4-1),$F$4/$E$4,0) -> 0 | AM4: =IF(AND(33>=$D$4,33<=$D$4+$E$4-1),$F$4/$E$4,0) -> 0 | AN4: =IF(AND(34>=$D$4,34<=$D$4+$E$4-1),$F$4/$E$4,0) -> 0 | AO4: =IF(AND(35>=$D$4,35<=$D$4+$E$4-1),$F$4/$E$4,0) -> 0 | AP4: =IF(AND(36>=$D$4,36<=$D$4+$E$4-1),$F$4/$E$4,0) -> 0 | AQ4: =IF(AND(37>=$D$4,37<=$D$4+$E$4-1),$F$4/$E$4,0) -> 0 | AR4: =IF(AND(38>=$D$4,38<=$D$4+$E$4-1),$F$4/$E$4,0) -> 0 | AS4: =IF(AND(39>=$D$4,39<=$D$4+$E$4-1),$F$4/$E$4,0) -> 0 | AT4: =IF(AND(40>=$D$4,40<=$D$4+$E$4-1),$F$4/$E$4,0) -> 0 | AU4: =IF(AND(41>=$D$4,41<=$D$4+$E$4-1),$F$4/$E$4,0) -> 0 | AV4: =IF(AND(42>=$D$4,42<=$D$4+$E$4-1),$F$4/$E$4,0) -> 0 | AW4: =IF(AND(43>=$D$4,43<=$D$4+$E$4-1),$F$4/$E$4,0) -> 0 | AX4: =IF(AND(44>=$D$4,44<=$D$4+$E$4-1),$F$4/$E$4,0) -> 0 | AY4: =IF(AND(45>=$D$4,45<=$D$4+$E$4-1),$F$4/$E$4,0) -> 0 | AZ4: =IF(AND(46>=$D$4,46<=$D$4+$E$4-1),$F$4/$E$4,0) -> 0 | BA4: =IF(AND(47>=$D$4,47<=$D$4+$E$4-1),$F$4/$E$4,0) -> 0 | BB4: =IF(AND(48>=$D$4,48<=$D$4+$E$4-1),$F$4/$E$4,0) -> 0 | BC4: =IF(AND(49>=$D$4,49<=$D$4+$E$4-1),$F$4/$E$4,0) -> 0 | BD4: =IF(AND(50>=$D$4,50<=$D$4+$E$4-1),$F$4/$E$4,0) -> 0 | BE4: =IF(AND(51>=$D$4,51<=$D$4+$E$4-1),$F$4/$E$4,0) -> 0 | BF4: =IF(AND(52>=$D$4,52<=$D$4+$E$4-1),$F$4/$E$4,0) -> 0 | BG4: =IF(AND(53>=$D$4,53<=$D$4+$E$4-1),$F$4/$E$4,0) -> 0 | BH4: =IF(AND(54>=$D$4,54<=$D$4+$E$4-1),$F$4/$E$4,0) -> 0 | BI4: =IF(AND(55>=$D$4,55<=$D$4+$E$4-1),$F$4/$E$4,0) -> 0 | BJ4: =IF(AND(56>=$D$4,56<=$D$4+$E$4-1),$F$4/$E$4,0) -> 0 | BK4: =IF(AND(57>=$D$4,57<=$D$4+$E$4-1),$F$4/$E$4,0) -> 0 | BL4: =IF(AND(58>=$D$4,58<=$D$4+$E$4-1),$F$4/$E$4,0) -> 0 | BM4: =IF(AND(59>=$D$4,59<=$D$4+$E$4-1),$F$4/$E$4,0) -> 0 | BN4: =IF(AND(60>=$D$4,60<=$D$4+$E$4-1),$F$4/$E$4,0) -> 0
A5: CH-02 | B5: Centre administratif régional | C5: Tertiaire public | D5: 1 | E5: 22 | F5: 6500000000 | G5: =IF(AND(1>=$D$5,1<=$D$5+$E$5-1),$F$5/$E$5,0) -> 2.9545455e+08 | H5: =IF(AND(2>=$D$5,2<=$D$5+$E$5-1),$F$5/$E$5,0) -> 2.9545455e+08 | I5: =IF(AND(3>=$D$5,3<=$D$5+$E$5-1),$F$5/$E$5,0) -> 2.9545455e+08 | J5: =IF(AND(4>=$D$5,4<=$D$5+$E$5-1),$F$5/$E$5,0) -> 2.9545455e+08 | K5: =IF(AND(5>=$D$5,5<=$D$5+$E$5-1),$F$5/$E$5,0) -> 2.9545455e+08 | L5: =IF(AND(6>=$D$5,6<=$D$5+$E$5-1),$F$5/$E$5,0) -> 2.9545455e+08 | M5: =IF(AND(7>=$D$5,7<=$D$5+$E$5-1),$F$5/$E$5,0) -> 2.9545455e+08 | N5: =IF(AND(8>=$D$5,8<=$D$5+$E$5-1),$F$5/$E$5,0) -> 2.9545455e+08 | O5: =IF(AND(9>=$D$5,9<=$D$5+$E$5-1),$F$5/$E$5,0) -> 2.9545455e+08 | P5: =IF(AND(10>=$D$5,10<=$D$5+$E$5-1),$F$5/$E$5,0) -> 2.9545455e+08 | Q5: =IF(AND(11>=$D$5,11<=$D$5+$E$5-1),$F$5/$E$5,0) -> 2.9545455e+08 | R5: =IF(AND(12>=$D$5,12<=$D$5+$E$5-1),$F$5/$E$5,0) -> 2.9545455e+08 | S5: =IF(AND(13>=$D$5,13<=$D$5+$E$5-1),$F$5/$E$5,0) -> 2.9545455e+08 | T5: =IF(AND(14>=$D$5,14<=$D$5+$E$5-1),$F$5/$E$5,0) -> 2.9545455e+08 | U5: =IF(AND(15>=$D$5,15<=$D$5+$E$5-1),$F$5/$E$5,0) -> 2.9545455e+08 | V5: =IF(AND(16>=$D$5,16<=$D$5+$E$5-1),$F$5/$E$5,0) -> 2.9545455e+08 | W5: =IF(AND(17>=$D$5,17<=$D$5+$E$5-1),$F$5/$E$5,0) -> 2.9545455e+08 | X5: =IF(AND(18>=$D$5,18<=$D$5+$E$5-1),$F$5/$E$5,0) -> 2.9545455e+08 | Y5: =IF(AND(19>=$D$5,19<=$D$5+$E$5-1),$F$5/$E$5,0) -> 2.9545455e+08 | Z5: =IF(AND(20>=$D$5,20<=$D$5+$E$5-1),$F$5/$E$5,0) -> 2.9545455e+08 | AA5: =IF(AND(21>=$D$5,21<=$D$5+$E$5-1),$F$5/$E$5,0) -> 2.9545455e+08 | AB5: =IF(AND(22>=$D$5,22<=$D$5+$E$5-1),$F$5/$E$5,0) -> 2.9545455e+08 | AC5: =IF(AND(23>=$D$5,23<=$D$5+$E$5-1),$F$5/$E$5,0) -> 0 | AD5: =IF(AND(24>=$D$5,24<=$D$5+$E$5-1),$F$5/$E$5,0) -> 0 | AE5: =IF(AND(25>=$D$5,25<=$D$5+$E$5-1),$F$5/$E$5,0) -> 0 | AF5: =IF(AND(26>=$D$5,26<=$D$5+$E$5-1),$F$5/$E$5,0) -> 0 | AG5: =IF(AND(27>=$D$5,27<=$D$5+$E$5-1),$F$5/$E$5,0) -> 0 | AH5: =IF(AND(28>=$D$5,28<=$D$5+$E$5-1),$F$5/$E$5,0) -> 0 | AI5: =IF(AND(29>=$D$5,29<=$D$5+$E$5-1),$F$5/$E$5,0) -> 0 | AJ5: =IF(AND(30>=$D$5,30<=$D$5+$E$5-1),$F$5/$E$5,0) -> 0 | AK5: =IF(AND(31>=$D$5,31<=$D$5+$E$5-1),$F$5/$E$5,0) -> 0 | AL5: =IF(AND(32>=$D$5,32<=$D$5+$E$5-1),$F$5/$E$5,0) -> 0 | AM5: =IF(AND(33>=$D$5,33<=$D$5+$E$5-1),$F$5/$E$5,0) -> 0 | AN5: =IF(AND(34>=$D$5,34<=$D$5+$E$5-1),$F$5/$E$5,0) -> 0 | AO5: =IF(AND(35>=$D$5,35<=$D$5+$E$5-1),$F$5/$E$5,0) -> 0 | AP5: =IF(AND(36>=$D$5,36<=$D$5+$E$5-1),$F$5/$E$5,0) -> 0 | AQ5: =IF(AND(37>=$D$5,37<=$D$5+$E$5-1),$F$5/$E$5,0) -> 0 | AR5: =IF(AND(38>=$D$5,38<=$D$5+$E$5-1),$F$5/$E$5,0) -> 0 | AS5: =IF(AND(39>=$D$5,39<=$D$5+$E$5-1),$F$5/$E$5,0) -> 0 | AT5: =IF(AND(40>=$D$5,40<=$D$5+$E$5-1),$F$5/$E$5,0) -> 0 | AU5: =IF(AND(41>=$D$5,41<=$D$5+$E$5-1),$F$5/$E$5,0) -> 0 | AV5: =IF(AND(42>=$D$5,42<=$D$5+$E$5-1),$F$5/$E$5,0) -> 0 | AW5: =IF(AND(43>=$D$5,43<=$D$5+$E$5-1),$F$5/$E$5,0) -> 0 | AX5: =IF(AND(44>=$D$5,44<=$D$5+$E$5-1),$F$5/$E$5,0) -> 0 | AY5: =IF(AND(45>=$D$5,45<=$D$5+$E$5-1),$F$5/$E$5,0) -> 0 | AZ5: =IF(AND(46>=$D$5,46<=$D$5+$E$5-1),$F$5/$E$5,0) -> 0 | BA5: =IF(AND(47>=$D$5,47<=$D$5+$E$5-1),$F$5/$E$5,0) -> 0 | BB5: =IF(AND(48>=$D$5,48<=$D$5+$E$5-1),$F$5/$E$5,0) -> 0 | BC5: =IF(AND(49>=$D$5,49<=$D$5+$E$5-1),$F$5/$E$5,0) -> 0 | BD5: =IF(AND(50>=$D$5,50<=$D$5+$E$5-1),$F$5/$E$5,0) -> 0 | BE5: =IF(AND(51>=$D$5,51<=$D$5+$E$5-1),$F$5/$E$5,0) -> 0 | BF5: =IF(AND(52>=$D$5,52<=$D$5+$E$5-1),$F$5/$E$5,0) -> 0 | BG5: =IF(AND(53>=$D$5,53<=$D$5+$E$5-1),$F$5/$E$5,0) -> 0 | BH5: =IF(AND(54>=$D$5,54<=$D$5+$E$5-1),$F$5/$E$5,0) -> 0 | BI5: =IF(AND(55>=$D$5,55<=$D$5+$E$5-1),$F$5/$E$5,0) -> 0 | BJ5: =IF(AND(56>=$D$5,56<=$D$5+$E$5-1),$F$5/$E$5,0) -> 0 | BK5: =IF(AND(57>=$D$5,57<=$D$5+$E$5-1),$F$5/$E$5,0) -> 0 | BL5: =IF(AND(58>=$D$5,58<=$D$5+$E$5-1),$F$5/$E$5,0) -> 0 | BM5: =IF(AND(59>=$D$5,59<=$D$5+$E$5-1),$F$5/$E$5,0) -> 0 | BN5: =IF(AND(60>=$D$5,60<=$D$5+$E$5-1),$F$5/$E$5,0) -> 0
A6: CH-03 | B6: Lycée technique national | C6: Public | D6: 3 | E6: 20 | F6: 3800000000 | G6: =IF(AND(1>=$D$6,1<=$D$6+$E$6-1),$F$6/$E$6,0) -> 0 | H6: =IF(AND(2>=$D$6,2<=$D$6+$E$6-1),$F$6/$E$6,0) -> 0 | I6: =IF(AND(3>=$D$6,3<=$D$6+$E$6-1),$F$6/$E$6,0) -> 190000000 | J6: =IF(AND(4>=$D$6,4<=$D$6+$E$6-1),$F$6/$E$6,0) -> 190000000 | K6: =IF(AND(5>=$D$6,5<=$D$6+$E$6-1),$F$6/$E$6,0) -> 190000000 | L6: =IF(AND(6>=$D$6,6<=$D$6+$E$6-1),$F$6/$E$6,0) -> 190000000 | M6: =IF(AND(7>=$D$6,7<=$D$6+$E$6-1),$F$6/$E$6,0) -> 190000000 | N6: =IF(AND(8>=$D$6,8<=$D$6+$E$6-1),$F$6/$E$6,0) -> 190000000 | O6: =IF(AND(9>=$D$6,9<=$D$6+$E$6-1),$F$6/$E$6,0) -> 190000000 | P6: =IF(AND(10>=$D$6,10<=$D$6+$E$6-1),$F$6/$E$6,0) -> 190000000 | Q6: =IF(AND(11>=$D$6,11<=$D$6+$E$6-1),$F$6/$E$6,0) -> 190000000 | R6: =IF(AND(12>=$D$6,12<=$D$6+$E$6-1),$F$6/$E$6,0) -> 190000000 | S6: =IF(AND(13>=$D$6,13<=$D$6+$E$6-1),$F$6/$E$6,0) -> 190000000 | T6: =IF(AND(14>=$D$6,14<=$D$6+$E$6-1),$F$6/$E$6,0) -> 190000000 | U6: =IF(AND(15>=$D$6,15<=$D$6+$E$6-1),$F$6/$E$6,0) -> 190000000 | V6: =IF(AND(16>=$D$6,16<=$D$6+$E$6-1),$F$6/$E$6,0) -> 190000000 | W6: =IF(AND(17>=$D$6,17<=$D$6+$E$6-1),$F$6/$E$6,0) -> 190000000 | X6: =IF(AND(18>=$D$6,18<=$D$6+$E$6-1),$F$6/$E$6,0) -> 190000000 | Y6: =IF(AND(19>=$D$6,19<=$D$6+$E$6-1),$F$6/$E$6,0) -> 190000000 | Z6: =IF(AND(20>=$D$6,20<=$D$6+$E$6-1),$F$6/$E$6,0) -> 190000000 | AA6: =IF(AND(21>=$D$6,21<=$D$6+$E$6-1),$F$6/$E$6,0) -> 190000000 | AB6: =IF(AND(22>=$D$6,22<=$D$6+$E$6-1),$F$6/$E$6,0) -> 190000000 | AC6: =IF(AND(23>=$D$6,23<=$D$6+$E$6-1),$F$6/$E$6,0) -> 0 | AD6: =IF(AND(24>=$D$6,24<=$D$6+$E$6-1),$F$6/$E$6,0) -> 0 | AE6: =IF(AND(25>=$D$6,25<=$D$6+$E$6-1),$F$6/$E$6,0) -> 0 | AF6: =IF(AND(26>=$D$6,26<=$D$6+$E$6-1),$F$6/$E$6,0) -> 0 | AG6: =IF(AND(27>=$D$6,27<=$D$6+$E$6-1),$F$6/$E$6,0) -> 0 | AH6: =IF(AND(28>=$D$6,28<=$D$6+$E$6-1),$F$6/$E$6,0) -> 0 | AI6: =IF(AND(29>=$D$6,29<=$D$6+$E$6-1),$F$6/$E$6,0) -> 0 | AJ6: =IF(AND(30>=$D$6,30<=$D$6+$E$6-1),$F$6/$E$6,0) -> 0 | AK6: =IF(AND(31>=$D$6,31<=$D$6+$E$6-1),$F$6/$E$6,0) -> 0 | AL6: =IF(AND(32>=$D$6,32<=$D$6+$E$6-1),$F$6/$E$6,0) -> 0 | AM6: =IF(AND(33>=$D$6,33<=$D$6+$E$6-1),$F$6/$E$6,0) -> 0 | AN6: =IF(AND(34>=$D$6,34<=$D$6+$E$6-1),$F$6/$E$6,0) -> 0 | AO6: =IF(AND(35>=$D$6,35<=$D$6+$E$6-1),$F$6/$E$6,0) -> 0 | AP6: =IF(AND(36>=$D$6,36<=$D$6+$E$6-1),$F$6/$E$6,0) -> 0 | AQ6: =IF(AND(37>=$D$6,37<=$D$6+$E$6-1),$F$6/$E$6,0) -> 0 | AR6: =IF(AND(38>=$D$6,38<=$D$6+$E$6-1),$F$6/$E$6,0) -> 0 | AS6: =IF(AND(39>=$D$6,39<=$D$6+$E$6-1),$F$6/$E$6,0) -> 0 | AT6: =IF(AND(40>=$D$6,40<=$D$6+$E$6-1),$F$6/$E$6,0) -> 0 | AU6: =IF(AND(41>=$D$6,41<=$D$6+$E$6-1),$F$6/$E$6,0) -> 0 | AV6: =IF(AND(42>=$D$6,42<=$D$6+$E$6-1),$F$6/$E$6,0) -> 0 | AW6: =IF(AND(43>=$D$6,43<=$D$6+$E$6-1),$F$6/$E$6,0) -> 0 | AX6: =IF(AND(44>=$D$6,44<=$D$6+$E$6-1),$F$6/$E$6,0) -> 0 | AY6: =IF(AND(45>=$D$6,45<=$D$6+$E$6-1),$F$6/$E$6,0) -> 0 | AZ6: =IF(AND(46>=$D$6,46<=$D$6+$E$6-1),$F$6/$E$6,0) -> 0 | BA6: =IF(AND(47>=$D$6,47<=$D$6+$E$6-1),$F$6/$E$6,0) -> 0 | BB6: =IF(AND(48>=$D$6,48<=$D$6+$E$6-1),$F$6/$E$6,0) -> 0 | BC6: =IF(AND(49>=$D$6,49<=$D$6+$E$6-1),$F$6/$E$6,0) -> 0 | BD6: =IF(AND(50>=$D$6,50<=$D$6+$E$6-1),$F$6/$E$6,0) -> 0 | BE6: =IF(AND(51>=$D$6,51<=$D$6+$E$6-1),$F$6/$E$6,0) -> 0 | BF6: =IF(AND(52>=$D$6,52<=$D$6+$E$6-1),$F$6/$E$6,0) -> 0 | BG6: =IF(AND(53>=$D$6,53<=$D$6+$E$6-1),$F$6/$E$6,0) -> 0 | BH6: =IF(AND(54>=$D$6,54<=$D$6+$E$6-1),$F$6/$E$6,0) -> 0 | BI6: =IF(AND(55>=$D$6,55<=$D$6+$E$6-1),$F$6/$E$6,0) -> 0 | BJ6: =IF(AND(56>=$D$6,56<=$D$6+$E$6-1),$F$6/$E$6,0) -> 0 | BK6: =IF(AND(57>=$D$6,57<=$D$6+$E$6-1),$F$6/$E$6,0) -> 0 | BL6: =IF(AND(58>=$D$6,58<=$D$6+$E$6-1),$F$6/$E$6,0) -> 0 | BM6: =IF(AND(59>=$D$6,59<=$D$6+$E$6-1),$F$6/$E$6,0) -> 0 | BN6: =IF(AND(60>=$D$6,60<=$D$6+$E$6-1),$F$6/$E$6,0) -> 0
A7: CH-04 | B7: Hôpital de district | C7: Santé publique | D7: 5 | E7: 24 | F7: 5500000000 | G7: =IF(AND(1>=$D$7,1<=$D$7+$E$7-1),$F$7/$E$7,0) -> 0 | H7: =IF(AND(2>=$D$7,2<=$D$7+$E$7-1),$F$7/$E$7,0) -> 0 | I7: =IF(AND(3>=$D$7,3<=$D$7+$E$7-1),$F$7/$E$7,0) -> 0 | J7: =IF(AND(4>=$D$7,4<=$D$7+$E$7-1),$F$7/$E$7,0) -> 0 | K7: =IF(AND(5>=$D$7,5<=$D$7+$E$7-1),$F$7/$E$7,0) -> 2.2916667e+08 | L7: =IF(AND(6>=$D$7,6<=$D$7+$E$7-1),$F$7/$E$7,0) -> 2.2916667e+08 | M7: =IF(AND(7>=$D$7,7<=$D$7+$E$7-1),$F$7/$E$7,0) -> 2.2916667e+08 | N7: =IF(AND(8>=$D$7,8<=$D$7+$E$7-1),$F$7/$E$7,0) -> 2.2916667e+08 | O7: =IF(AND(9>=$D$7,9<=$D$7+$E$7-1),$F$7/$E$7,0) -> 2.2916667e+08 | P7: =IF(AND(10>=$D$7,10<=$D$7+$E$7-1),$F$7/$E$7,0) -> 2.2916667e+08 | Q7: =IF(AND(11>=$D$7,11<=$D$7+$E$7-1),$F$7/$E$7,0) -> 2.2916667e+08 | R7: =IF(AND(12>=$D$7,12<=$D$7+$E$7-1),$F$7/$E$7,0) -> 2.2916667e+08 | S7: =IF(AND(13>=$D$7,13<=$D$7+$E$7-1),$F$7/$E$7,0) -> 2.2916667e+08 | T7: =IF(AND(14>=$D$7,14<=$D$7+$E$7-1),$F$7/$E$7,0) -> 2.2916667e+08 | U7: =IF(AND(15>=$D$7,15<=$D$7+$E$7-1),$F$7/$E$7,0) -> 2.2916667e+08 | V7: =IF(AND(16>=$D$7,16<=$D$7+$E$7-1),$F$7/$E$7,0) -> 2.2916667e+08 | W7: =IF(AND(17>=$D$7,17<=$D$7+$E$7-1),$F$7/$E$7,0) -> 2.2916667e+08 | X7: =IF(AND(18>=$D$7,18<=$D$7+$E$7-1),$F$7/$E$7,0) -> 2.2916667e+08 | Y7: =IF(AND(19>=$D$7,19<=$D$7+$E$7-1),$F$7/$E$7,0) -> 2.2916667e+08 | Z7: =IF(AND(20>=$D$7,20<=$D$7+$E$7-1),$F$7/$E$7,0) -> 2.2916667e+08 | AA7: =IF(AND(21>=$D$7,21<=$D$7+$E$7-1),$F$7/$E$7,0) -> 2.2916667e+08 | AB7: =IF(AND(22>=$D$7,22<=$D$7+$E$7-1),$F$7/$E$7,0) -> 2.2916667e+08 | AC7: =IF(AND(23>=$D$7,23<=$D$7+$E$7-1),$F$7/$E$7,0) -> 2.2916667e+08 | AD7: =IF(AND(24>=$D$7,24<=$D$7+$E$7-1),$F$7/$E$7,0) -> 2.2916667e+08 | AE7: =IF(AND(25>=$D$7,25<=$D$7+$E$7-1),$F$7/$E$7,0) -> 2.2916667e+08 | AF7: =IF(AND(26>=$D$7,26<=$D$7+$E$7-1),$F$7/$E$7,0) -> 2.2916667e+08 | AG7: =IF(AND(27>=$D$7,27<=$D$7+$E$7-1),$F$7/$E$7,0) -> 2.2916667e+08 | AH7: =IF(AND(28>=$D$7,28<=$D$7+$E$7-1),$F$7/$E$7,0) -> 2.2916667e+08 | AI7: =IF(AND(29>=$D$7,29<=$D$7+$E$7-1),$F$7/$E$7,0) -> 0 | AJ7: =IF(AND(30>=$D$7,30<=$D$7+$E$7-1),$F$7/$E$7,0) -> 0 | AK7: =IF(AND(31>=$D$7,31<=$D$7+$E$7-1),$F$7/$E$7,0) -> 0 | AL7: =IF(AND(32>=$D$7,32<=$D$7+$E$7-1),$F$7/$E$7,0) -> 0 | AM7: =IF(AND(33>=$D$7,33<=$D$7+$E$7-1),$F$7/$E$7,0) -> 0 | AN7: =IF(AND(34>=$D$7,34<=$D$7+$E$7-1),$F$7/$E$7,0) -> 0 | AO7: =IF(AND(35>=$D$7,35<=$D$7+$E$7-1),$F$7/$E$7,0) -> 0 | AP7: =IF(AND(36>=$D$7,36<=$D$7+$E$7-1),$F$7/$E$7,0) -> 0 | AQ7: =IF(AND(37>=$D$7,37<=$D$7+$E$7-1),$F$7/$E$7,0) -> 0 | AR7: =IF(AND(38>=$D$7,38<=$D$7+$E$7-1),$F$7/$E$7,0) -> 0 | AS7: =IF(AND(39>=$D$7,39<=$D$7+$E$7-1),$F$7/$E$7,0) -> 0 | AT7: =IF(AND(40>=$D$7,40<=$D$7+$E$7-1),$F$7/$E$7,0) -> 0 | AU7: =IF(AND(41>=$D$7,41<=$D$7+$E$7-1),$F$7/$E$7,0) -> 0 | AV7: =IF(AND(42>=$D$7,42<=$D$7+$E$7-1),$F$7/$E$7,0) -> 0 | AW7: =IF(AND(43>=$D$7,43<=$D$7+$E$7-1),$F$7/$E$7,0) -> 0 | AX7: =IF(AND(44>=$D$7,44<=$D$7+$E$7-1),$F$7/$E$7,0) -> 0 | AY7: =IF(AND(45>=$D$7,45<=$D$7+$E$7-1),$F$7/$E$7,0) -> 0 | AZ7: =IF(AND(46>=$D$7,46<=$D$7+$E$7-1),$F$7/$E$7,0) -> 0 | BA7: =IF(AND(47>=$D$7,47<=$D$7+$E$7-1),$F$7/$E$7,0) -> 0 | BB7: =IF(AND(48>=$D$7,48<=$D$7+$E$7-1),$F$7/$E$7,0) -> 0 | BC7: =IF(AND(49>=$D$7,49<=$D$7+$E$7-1),$F$7/$E$7,0) -> 0 | BD7: =IF(AND(50>=$D$7,50<=$D$7+$E$7-1),$F$7/$E$7,0) -> 0 | BE7: =IF(AND(51>=$D$7,51<=$D$7+$E$7-1),$F$7/$E$7,0) -> 0 | BF7: =IF(AND(52>=$D$7,52<=$D$7+$E$7-1),$F$7/$E$7,0) -> 0 | BG7: =IF(AND(53>=$D$7,53<=$D$7+$E$7-1),$F$7/$E$7,0) -> 0 | BH7: =IF(AND(54>=$D$7,54<=$D$7+$E$7-1),$F$7/$E$7,0) -> 0 | BI7: =IF(AND(55>=$D$7,55<=$D$7+$E$7-1),$F$7/$E$7,0) -> 0 | BJ7: =IF(AND(56>=$D$7,56<=$D$7+$E$7-1),$F$7/$E$7,0) -> 0 | BK7: =IF(AND(57>=$D$7,57<=$D$7+$E$7-1),$F$7/$E$7,0) -> 0 | BL7: =IF(AND(58>=$D$7,58<=$D$7+$E$7-1),$F$7/$E$7,0) -> 0 | BM7: =IF(AND(59>=$D$7,59<=$D$7+$E$7-1),$F$7/$E$7,0) -> 0 | BN7: =IF(AND(60>=$D$7,60<=$D$7+$E$7-1),$F$7/$E$7,0) -> 0
A8: CH-05 | B8: Siège institution financière | C8: Tertiaire | D8: 8 | E8: 22 | F8: 4800000000 | G8: =IF(AND(1>=$D$8,1<=$D$8+$E$8-1),$F$8/$E$8,0) -> 0 | H8: =IF(AND(2>=$D$8,2<=$D$8+$E$8-1),$F$8/$E$8,0) -> 0 | I8: =IF(AND(3>=$D$8,3<=$D$8+$E$8-1),$F$8/$E$8,0) -> 0 | J8: =IF(AND(4>=$D$8,4<=$D$8+$E$8-1),$F$8/$E$8,0) -> 0 | K8: =IF(AND(5>=$D$8,5<=$D$8+$E$8-1),$F$8/$E$8,0) -> 0 | L8: =IF(AND(6>=$D$8,6<=$D$8+$E$8-1),$F$8/$E$8,0) -> 0 | M8: =IF(AND(7>=$D$8,7<=$D$8+$E$8-1),$F$8/$E$8,0) -> 0 | N8: =IF(AND(8>=$D$8,8<=$D$8+$E$8-1),$F$8/$E$8,0) -> 2.1818182e+08 | O8: =IF(AND(9>=$D$8,9<=$D$8+$E$8-1),$F$8/$E$8,0) -> 2.1818182e+08 | P8: =IF(AND(10>=$D$8,10<=$D$8+$E$8-1),$F$8/$E$8,0) -> 2.1818182e+08 | Q8: =IF(AND(11>=$D$8,11<=$D$8+$E$8-1),$F$8/$E$8,0) -> 2.1818182e+08 | R8: =IF(AND(12>=$D$8,12<=$D$8+$E$8-1),$F$8/$E$8,0) -> 2.1818182e+08 | S8: =IF(AND(13>=$D$8,13<=$D$8+$E$8-1),$F$8/$E$8,0) -> 2.1818182e+08 | T8: =IF(AND(14>=$D$8,14<=$D$8+$E$8-1),$F$8/$E$8,0) -> 2.1818182e+08 | U8: =IF(AND(15>=$D$8,15<=$D$8+$E$8-1),$F$8/$E$8,0) -> 2.1818182e+08 | V8: =IF(AND(16>=$D$8,16<=$D$8+$E$8-1),$F$8/$E$8,0) -> 2.1818182e+08 | W8: =IF(AND(17>=$D$8,17<=$D$8+$E$8-1),$F$8/$E$8,0) -> 2.1818182e+08 | X8: =IF(AND(18>=$D$8,18<=$D$8+$E$8-1),$F$8/$E$8,0) -> 2.1818182e+08 | Y8: =IF(AND(19>=$D$8,19<=$D$8+$E$8-1),$F$8/$E$8,0) -> 2.1818182e+08 | Z8: =IF(AND(20>=$D$8,20<=$D$8+$E$8-1),$F$8/$E$8,0) -> 2.1818182e+08 | AA8: =IF(AND(21>=$D$8,21<=$D$8+$E$8-1),$F$8/$E$8,0) -> 2.1818182e+08 | AB8: =IF(AND(22>=$D$8,22<=$D$8+$E$8-1),$F$8/$E$8,0) -> 2.1818182e+08 | AC8: =IF(AND(23>=$D$8,23<=$D$8+$E$8-1),$F$8/$E$8,0) -> 2.1818182e+08 | AD8: =IF(AND(24>=$D$8,24<=$D$8+$E$8-1),$F$8/$E$8,0) -> 2.1818182e+08 | AE8: =IF(AND(25>=$D$8,25<=$D$8+$E$8-1),$F$8/$E$8,0) -> 2.1818182e+08 | AF8: =IF(AND(26>=$D$8,26<=$D$8+$E$8-1),$F$8/$E$8,0) -> 2.1818182e+08 | AG8: =IF(AND(27>=$D$8,27<=$D$8+$E$8-1),$F$8/$E$8,0) -> 2.1818182e+08 | AH8: =IF(AND(28>=$D$8,28<=$D$8+$E$8-1),$F$8/$E$8,0) -> 2.1818182e+08 | AI8: =IF(AND(29>=$D$8,29<=$D$8+$E$8-1),$F$8/$E$8,0) -> 2.1818182e+08 | AJ8: =IF(AND(30>=$D$8,30<=$D$8+$E$8-1),$F$8/$E$8,0) -> 0 | AK8: =IF(AND(31>=$D$8,31<=$D$8+$E$8-1),$F$8/$E$8,0) -> 0 | AL8: =IF(AND(32>=$D$8,32<=$D$8+$E$8-1),$F$8/$E$8,0) -> 0 | AM8: =IF(AND(33>=$D$8,33<=$D$8+$E$8-1),$F$8/$E$8,0) -> 0 | AN8: =IF(AND(34>=$D$8,34<=$D$8+$E$8-1),$F$8/$E$8,0) -> 0 | AO8: =IF(AND(35>=$D$8,35<=$D$8+$E$8-1),$F$8/$E$8,0) -> 0 | AP8: =IF(AND(36>=$D$8,36<=$D$8+$E$8-1),$F$8/$E$8,0) -> 0 | AQ8: =IF(AND(37>=$D$8,37<=$D$8+$E$8-1),$F$8/$E$8,0) -> 0 | AR8: =IF(AND(38>=$D$8,38<=$D$8+$E$8-1),$F$8/$E$8,0) -> 0 | AS8: =IF(AND(39>=$D$8,39<=$D$8+$E$8-1),$F$8/$E$8,0) -> 0 | AT8: =IF(AND(40>=$D$8,40<=$D$8+$E$8-1),$F$8/$E$8,0) -> 0 | AU8: =IF(AND(41>=$D$8,41<=$D$8+$E$8-1),$F$8/$E$8,0) -> 0 | AV8: =IF(AND(42>=$D$8,42<=$D$8+$E$8-1),$F$8/$E$8,0) -> 0 | AW8: =IF(AND(43>=$D$8,43<=$D$8+$E$8-1),$F$8/$E$8,0) -> 0 | AX8: =IF(AND(44>=$D$8,44<=$D$8+$E$8-1),$F$8/$E$8,0) -> 0 | AY8: =IF(AND(45>=$D$8,45<=$D$8+$E$8-1),$F$8/$E$8,0) -> 0 | AZ8: =IF(AND(46>=$D$8,46<=$D$8+$E$8-1),$F$8/$E$8,0) -> 0 | BA8: =IF(AND(47>=$D$8,47<=$D$8+$E$8-1),$F$8/$E$8,0) -> 0 | BB8: =IF(AND(48>=$D$8,48<=$D$8+$E$8-1),$F$8/$E$8,0) -> 0 | BC8: =IF(AND(49>=$D$8,49<=$D$8+$E$8-1),$F$8/$E$8,0) -> 0 | BD8: =IF(AND(50>=$D$8,50<=$D$8+$E$8-1),$F$8/$E$8,0) -> 0 | BE8: =IF(AND(51>=$D$8,51<=$D$8+$E$8-1),$F$8/$E$8,0) -> 0 | BF8: =IF(AND(52>=$D$8,52<=$D$8+$E$8-1),$F$8/$E$8,0) -> 0 | BG8: =IF(AND(53>=$D$8,53<=$D$8+$E$8-1),$F$8/$E$8,0) -> 0 | BH8: =IF(AND(54>=$D$8,54<=$D$8+$E$8-1),$F$8/$E$8,0) -> 0 | BI8: =IF(AND(55>=$D$8,55<=$D$8+$E$8-1),$F$8/$E$8,0) -> 0 | BJ8: =IF(AND(56>=$D$8,56<=$D$8+$E$8-1),$F$8/$E$8,0) -> 0 | BK8: =IF(AND(57>=$D$8,57<=$D$8+$E$8-1),$F$8/$E$8,0) -> 0 | BL8: =IF(AND(58>=$D$8,58<=$D$8+$E$8-1),$F$8/$E$8,0) -> 0 | BM8: =IF(AND(59>=$D$8,59<=$D$8+$E$8-1),$F$8/$E$8,0) -> 0 | BN8: =IF(AND(60>=$D$8,60<=$D$8+$E$8-1),$F$8/$E$8,0) -> 0
A9: CH-06 | B9: Logements sociaux Phase 2 | C9: Bâtiment public | D9: 11 | E9: 18 | F9: 4500000000 | G9: =IF(AND(1>=$D$9,1<=$D$9+$E$9-1),$F$9/$E$9,0) -> 0 | H9: =IF(AND(2>=$D$9,2<=$D$9+$E$9-1),$F$9/$E$9,0) -> 0 | I9: =IF(AND(3>=$D$9,3<=$D$9+$E$9-1),$F$9/$E$9,0) -> 0 | J9: =IF(AND(4>=$D$9,4<=$D$9+$E$9-1),$F$9/$E$9,0) -> 0 | K9: =IF(AND(5>=$D$9,5<=$D$9+$E$9-1),$F$9/$E$9,0) -> 0 | L9: =IF(AND(6>=$D$9,6<=$D$9+$E$9-1),$F$9/$E$9,0) -> 0 | M9: =IF(AND(7>=$D$9,7<=$D$9+$E$9-1),$F$9/$E$9,0) -> 0 | N9: =IF(AND(8>=$D$9,8<=$D$9+$E$9-1),$F$9/$E$9,0) -> 0 | O9: =IF(AND(9>=$D$9,9<=$D$9+$E$9-1),$F$9/$E$9,0) -> 0 | P9: =IF(AND(10>=$D$9,10<=$D$9+$E$9-1),$F$9/$E$9,0) -> 0 | Q9: =IF(AND(11>=$D$9,11<=$D$9+$E$9-1),$F$9/$E$9,0) -> 250000000 | R9: =IF(AND(12>=$D$9,12<=$D$9+$E$9-1),$F$9/$E$9,0) -> 250000000 | S9: =IF(AND(13>=$D$9,13<=$D$9+$E$9-1),$F$9/$E$9,0) -> 250000000 | T9: =IF(AND(14>=$D$9,14<=$D$9+$E$9-1),$F$9/$E$9,0) -> 250000000 | U9: =IF(AND(15>=$D$9,15<=$D$9+$E$9-1),$F$9/$E$9,0) -> 250000000 | V9: =IF(AND(16>=$D$9,16<=$D$9+$E$9-1),$F$9/$E$9,0) -> 250000000 | W9: =IF(AND(17>=$D$9,17<=$D$9+$E$9-1),$F$9/$E$9,0) -> 250000000 | X9: =IF(AND(18>=$D$9,18<=$D$9+$E$9-1),$F$9/$E$9,0) -> 250000000 | Y9: =IF(AND(19>=$D$9,19<=$D$9+$E$9-1),$F$9/$E$9,0) -> 250000000 | Z9: =IF(AND(20>=$D$9,20<=$D$9+$E$9-1),$F$9/$E$9,0) -> 250000000 | AA9: =IF(AND(21>=$D$9,21<=$D$9+$E$9-1),$F$9/$E$9,0) -> 250000000 | AB9: =IF(AND(22>=$D$9,22<=$D$9+$E$9-1),$F$9/$E$9,0) -> 250000000 | AC9: =IF(AND(23>=$D$9,23<=$D$9+$E$9-1),$F$9/$E$9,0) -> 250000000 | AD9: =IF(AND(24>=$D$9,24<=$D$9+$E$9-1),$F$9/$E$9,0) -> 250000000 | AE9: =IF(AND(25>=$D$9,25<=$D$9+$E$9-1),$F$9/$E$9,0) -> 250000000 | AF9: =IF(AND(26>=$D$9,26<=$D$9+$E$9-1),$F$9/$E$9,0) -> 250000000 | AG9: =IF(AND(27>=$D$9,27<=$D$9+$E$9-1),$F$9/$E$9,0) -> 250000000 | AH9: =IF(AND(28>=$D$9,28<=$D$9+$E$9-1),$F$9/$E$9,0) -> 250000000 | AI9: =IF(AND(29>=$D$9,29<=$D$9+$E$9-1),$F$9/$E$9,0) -> 0 | AJ9: =IF(AND(30>=$D$9,30<=$D$9+$E$9-1),$F$9/$E$9,0) -> 0 | AK9: =IF(AND(31>=$D$9,31<=$D$9+$E$9-1),$F$9/$E$9,0) -> 0 | AL9: =IF(AND(32>=$D$9,32<=$D$9+$E$9-1),$F$9/$E$9,0) -> 0 | AM9: =IF(AND(33>=$D$9,33<=$D$9+$E$9-1),$F$9/$E$9,0) -> 0 | AN9: =IF(AND(34>=$D$9,34<=$D$9+$E$9-1),$F$9/$E$9,0) -> 0 | AO9: =IF(AND(35>=$D$9,35<=$D$9+$E$9-1),$F$9/$E$9,0) -> 0 | AP9: =IF(AND(36>=$D$9,36<=$D$9+$E$9-1),$F$9/$E$9,0) -> 0 | AQ9: =IF(AND(37>=$D$9,37<=$D$9+$E$9-1),$F$9/$E$9,0) -> 0 | AR9: =IF(AND(38>=$D$9,38<=$D$9+$E$9-1),$F$9/$E$9,0) -> 0 | AS9: =IF(AND(39>=$D$9,39<=$D$9+$E$9-1),$F$9/$E$9,0) -> 0 | AT9: =IF(AND(40>=$D$9,40<=$D$9+$E$9-1),$F$9/$E$9,0) -> 0 | AU9: =IF(AND(41>=$D$9,41<=$D$9+$E$9-1),$F$9/$E$9,0) -> 0 | AV9: =IF(AND(42>=$D$9,42<=$D$9+$E$9-1),$F$9/$E$9,0) -> 0 | AW9: =IF(AND(43>=$D$9,43<=$D$9+$E$9-1),$F$9/$E$9,0) -> 0 | AX9: =IF(AND(44>=$D$9,44<=$D$9+$E$9-1),$F$9/$E$9,0) -> 0 | AY9: =IF(AND(45>=$D$9,45<=$D$9+$E$9-1),$F$9/$E$9,0) -> 0 | AZ9: =IF(AND(46>=$D$9,46<=$D$9+$E$9-1),$F$9/$E$9,0) -> 0 | BA9: =IF(AND(47>=$D$9,47<=$D$9+$E$9-1),$F$9/$E$9,0) -> 0 | BB9: =IF(AND(48>=$D$9,48<=$D$9+$E$9-1),$F$9/$E$9,0) -> 0 | BC9: =IF(AND(49>=$D$9,49<=$D$9+$E$9-1),$F$9/$E$9,0) -> 0 | BD9: =IF(AND(50>=$D$9,50<=$D$9+$E$9-1),$F$9/$E$9,0) -> 0 | BE9: =IF(AND(51>=$D$9,51<=$D$9+$E$9-1),$F$9/$E$9,0) -> 0 | BF9: =IF(AND(52>=$D$9,52<=$D$9+$E$9-1),$F$9/$E$9,0) -> 0 | BG9: =IF(AND(53>=$D$9,53<=$D$9+$E$9-1),$F$9/$E$9,0) -> 0 | BH9: =IF(AND(54>=$D$9,54<=$D$9+$E$9-1),$F$9/$E$9,0) -> 0 | BI9: =IF(AND(55>=$D$9,55<=$D$9+$E$9-1),$F$9/$E$9,0) -> 0 | BJ9: =IF(AND(56>=$D$9,56<=$D$9+$E$9-1),$F$9/$E$9,0) -> 0 | BK9: =IF(AND(57>=$D$9,57<=$D$9+$E$9-1),$F$9/$E$9,0) -> 0 | BL9: =IF(AND(58>=$D$9,58<=$D$9+$E$9-1),$F$9/$E$9,0) -> 0 | BM9: =IF(AND(59>=$D$9,59<=$D$9+$E$9-1),$F$9/$E$9,0) -> 0 | BN9: =IF(AND(60>=$D$9,60<=$D$9+$E$9-1),$F$9/$E$9,0) -> 0
A10: CH-07 | B10: Ministère - extension | C10: Tertiaire public | D10: 14 | E10: 16 | F10: 3200000000 | G10: =IF(AND(1>=$D$10,1<=$D$10+$E$10-1),$F$10/$E$10,0) -> 0 | H10: =IF(AND(2>=$D$10,2<=$D$10+$E$10-1),$F$10/$E$10,0) -> 0 | I10: =IF(AND(3>=$D$10,3<=$D$10+$E$10-1),$F$10/$E$10,0) -> 0 | J10: =IF(AND(4>=$D$10,4<=$D$10+$E$10-1),$F$10/$E$10,0) -> 0 | K10: =IF(AND(5>=$D$10,5<=$D$10+$E$10-1),$F$10/$E$10,0) -> 0 | L10: =IF(AND(6>=$D$10,6<=$D$10+$E$10-1),$F$10/$E$10,0) -> 0 | M10: =IF(AND(7>=$D$10,7<=$D$10+$E$10-1),$F$10/$E$10,0) -> 0 | N10: =IF(AND(8>=$D$10,8<=$D$10+$E$10-1),$F$10/$E$10,0) -> 0 | O10: =IF(AND(9>=$D$10,9<=$D$10+$E$10-1),$F$10/$E$10,0) -> 0 | P10: =IF(AND(10>=$D$10,10<=$D$10+$E$10-1),$F$10/$E$10,0) -> 0 | Q10: =IF(AND(11>=$D$10,11<=$D$10+$E$10-1),$F$10/$E$10,0) -> 0 | R10: =IF(AND(12>=$D$10,12<=$D$10+$E$10-1),$F$10/$E$10,0) -> 0 | S10: =IF(AND(13>=$D$10,13<=$D$10+$E$10-1),$F$10/$E$10,0) -> 0 | T10: =IF(AND(14>=$D$10,14<=$D$10+$E$10-1),$F$10/$E$10,0) -> 200000000 | U10: =IF(AND(15>=$D$10,15<=$D$10+$E$10-1),$F$10/$E$10,0) -> 200000000 | V10: =IF(AND(16>=$D$10,16<=$D$10+$E$10-1),$F$10/$E$10,0) -> 200000000 | W10: =IF(AND(17>=$D$10,17<=$D$10+$E$10-1),$F$10/$E$10,0) -> 200000000 | X10: =IF(AND(18>=$D$10,18<=$D$10+$E$10-1),$F$10/$E$10,0) -> 200000000 | Y10: =IF(AND(19>=$D$10,19<=$D$10+$E$10-1),$F$10/$E$10,0) -> 200000000 | Z10: =IF(AND(20>=$D$10,20<=$D$10+$E$10-1),$F$10/$E$10,0) -> 200000000 | AA10: =IF(AND(21>=$D$10,21<=$D$10+$E$10-1),$F$10/$E$10,0) -> 200000000 | AB10: =IF(AND(22>=$D$10,22<=$D$10+$E$10-1),$F$10/$E$10,0) -> 200000000 | AC10: =IF(AND(23>=$D$10,23<=$D$10+$E$10-1),$F$10/$E$10,0) -> 200000000 | AD10: =IF(AND(24>=$D$10,24<=$D$10+$E$10-1),$F$10/$E$10,0) -> 200000000 | AE10: =IF(AND(25>=$D$10,25<=$D$10+$E$10-1),$F$10/$E$10,0) -> 200000000 | AF10: =IF(AND(26>=$D$10,26<=$D$10+$E$10-1),$F$10/$E$10,0) -> 200000000 | AG10: =IF(AND(27>=$D$10,27<=$D$10+$E$10-1),$F$10/$E$10,0) -> 200000000 | AH10: =IF(AND(28>=$D$10,28<=$D$10+$E$10-1),$F$10/$E$10,0) -> 200000000 | AI10: =IF(AND(29>=$D$10,29<=$D$10+$E$10-1),$F$10/$E$10,0) -> 200000000 | AJ10: =IF(AND(30>=$D$10,30<=$D$10+$E$10-1),$F$10/$E$10,0) -> 0 | AK10: =IF(AND(31>=$D$10,31<=$D$10+$E$10-1),$F$10/$E$10,0) -> 0 | AL10: =IF(AND(32>=$D$10,32<=$D$10+$E$10-1),$F$10/$E$10,0) -> 0 | AM10: =IF(AND(33>=$D$10,33<=$D$10+$E$10-1),$F$10/$E$10,0) -> 0 | AN10: =IF(AND(34>=$D$10,34<=$D$10+$E$10-1),$F$10/$E$10,0) -> 0 | AO10: =IF(AND(35>=$D$10,35<=$D$10+$E$10-1),$F$10/$E$10,0) -> 0 | AP10: =IF(AND(36>=$D$10,36<=$D$10+$E$10-1),$F$10/$E$10,0) -> 0 | AQ10: =IF(AND(37>=$D$10,37<=$D$10+$E$10-1),$F$10/$E$10,0) -> 0 | AR10: =IF(AND(38>=$D$10,38<=$D$10+$E$10-1),$F$10/$E$10,0) -> 0 | AS10: =IF(AND(39>=$D$10,39<=$D$10+$E$10-1),$F$10/$E$10,0) -> 0 | AT10: =IF(AND(40>=$D$10,40<=$D$10+$E$10-1),$F$10/$E$10,0) -> 0 | AU10: =IF(AND(41>=$D$10,41<=$D$10+$E$10-1),$F$10/$E$10,0) -> 0 | AV10: =IF(AND(42>=$D$10,42<=$D$10+$E$10-1),$F$10/$E$10,0) -> 0 | AW10: =IF(AND(43>=$D$10,43<=$D$10+$E$10-1),$F$10/$E$10,0) -> 0 | AX10: =IF(AND(44>=$D$10,44<=$D$10+$E$10-1),$F$10/$E$10,0) -> 0 | AY10: =IF(AND(45>=$D$10,45<=$D$10+$E$10-1),$F$10/$E$10,0) -> 0 | AZ10: =IF(AND(46>=$D$10,46<=$D$10+$E$10-1),$F$10/$E$10,0) -> 0 | BA10: =IF(AND(47>=$D$10,47<=$D$10+$E$10-1),$F$10/$E$10,0) -> 0 | BB10: =IF(AND(48>=$D$10,48<=$D$10+$E$10-1),$F$10/$E$10,0) -> 0 | BC10: =IF(AND(49>=$D$10,49<=$D$10+$E$10-1),$F$10/$E$10,0) -> 0 | BD10: =IF(AND(50>=$D$10,50<=$D$10+$E$10-1),$F$10/$E$10,0) -> 0 | BE10: =IF(AND(51>=$D$10,51<=$D$10+$E$10-1),$F$10/$E$10,0) -> 0 | BF10: =IF(AND(52>=$D$10,52<=$D$10+$E$10-1),$F$10/$E$10,0) -> 0 | BG10: =IF(AND(53>=$D$10,53<=$D$10+$E$10-1),$F$10/$E$10,0) -> 0 | BH10: =IF(AND(54>=$D$10,54<=$D$10+$E$10-1),$F$10/$E$10,0) -> 0 | BI10: =IF(AND(55>=$D$10,55<=$D$10+$E$10-1),$F$10/$E$10,0) -> 0 | BJ10: =IF(AND(56>=$D$10,56<=$D$10+$E$10-1),$F$10/$E$10,0) -> 0 | BK10: =IF(AND(57>=$D$10,57<=$D$10+$E$10-1),$F$10/$E$10,0) -> 0 | BL10: =IF(AND(58>=$D$10,58<=$D$10+$E$10-1),$F$10/$E$10,0) -> 0 | BM10: =IF(AND(59>=$D$10,59<=$D$10+$E$10-1),$F$10/$E$10,0) -> 0 | BN10: =IF(AND(60>=$D$10,60<=$D$10+$E$10-1),$F$10/$E$10,0) -> 0
A11: CH-08 | B11: Université - bloc pédagogique | C11: Public | D11: 18 | E11: 20 | F11: 5200000000 | G11: =IF(AND(1>=$D$11,1<=$D$11+$E$11-1),$F$11/$E$11,0) -> 0 | H11: =IF(AND(2>=$D$11,2<=$D$11+$E$11-1),$F$11/$E$11,0) -> 0 | I11: =IF(AND(3>=$D$11,3<=$D$11+$E$11-1),$F$11/$E$11,0) -> 0 | J11: =IF(AND(4>=$D$11,4<=$D$11+$E$11-1),$F$11/$E$11,0) -> 0 | K11: =IF(AND(5>=$D$11,5<=$D$11+$E$11-1),$F$11/$E$11,0) -> 0 | L11: =IF(AND(6>=$D$11,6<=$D$11+$E$11-1),$F$11/$E$11,0) -> 0 | M11: =IF(AND(7>=$D$11,7<=$D$11+$E$11-1),$F$11/$E$11,0) -> 0 | N11: =IF(AND(8>=$D$11,8<=$D$11+$E$11-1),$F$11/$E$11,0) -> 0 | O11: =IF(AND(9>=$D$11,9<=$D$11+$E$11-1),$F$11/$E$11,0) -> 0 | P11: =IF(AND(10>=$D$11,10<=$D$11+$E$11-1),$F$11/$E$11,0) -> 0 | Q11: =IF(AND(11>=$D$11,11<=$D$11+$E$11-1),$F$11/$E$11,0) -> 0 | R11: =IF(AND(12>=$D$11,12<=$D$11+$E$11-1),$F$11/$E$11,0) -> 0 | S11: =IF(AND(13>=$D$11,13<=$D$11+$E$11-1),$F$11/$E$11,0) -> 0 | T11: =IF(AND(14>=$D$11,14<=$D$11+$E$11-1),$F$11/$E$11,0) -> 0 | U11: =IF(AND(15>=$D$11,15<=$D$11+$E$11-1),$F$11/$E$11,0) -> 0 | V11: =IF(AND(16>=$D$11,16<=$D$11+$E$11-1),$F$11/$E$11,0) -> 0 | W11: =IF(AND(17>=$D$11,17<=$D$11+$E$11-1),$F$11/$E$11,0) -> 0 | X11: =IF(AND(18>=$D$11,18<=$D$11+$E$11-1),$F$11/$E$11,0) -> 260000000 | Y11: =IF(AND(19>=$D$11,19<=$D$11+$E$11-1),$F$11/$E$11,0) -> 260000000 | Z11: =IF(AND(20>=$D$11,20<=$D$11+$E$11-1),$F$11/$E$11,0) -> 260000000 | AA11: =IF(AND(21>=$D$11,21<=$D$11+$E$11-1),$F$11/$E$11,0) -> 260000000 | AB11: =IF(AND(22>=$D$11,22<=$D$11+$E$11-1),$F$11/$E$11,0) -> 260000000 | AC11: =IF(AND(23>=$D$11,23<=$D$11+$E$11-1),$F$11/$E$11,0) -> 260000000 | AD11: =IF(AND(24>=$D$11,24<=$D$11+$E$11-1),$F$11/$E$11,0) -> 260000000 | AE11: =IF(AND(25>=$D$11,25<=$D$11+$E$11-1),$F$11/$E$11,0) -> 260000000 | AF11: =IF(AND(26>=$D$11,26<=$D$11+$E$11-1),$F$11/$E$11,0) -> 260000000 | AG11: =IF(AND(27>=$D$11,27<=$D$11+$E$11-1),$F$11/$E$11,0) -> 260000000 | AH11: =IF(AND(28>=$D$11,28<=$D$11+$E$11-1),$F$11/$E$11,0) -> 260000000 | AI11: =IF(AND(29>=$D$11,29<=$D$11+$E$11-1),$F$11/$E$11,0) -> 260000000 | AJ11: =IF(AND(30>=$D$11,30<=$D$11+$E$11-1),$F$11/$E$11,0) -> 260000000 | AK11: =IF(AND(31>=$D$11,31<=$D$11+$E$11-1),$F$11/$E$11,0) -> 260000000 | AL11: =IF(AND(32>=$D$11,32<=$D$11+$E$11-1),$F$11/$E$11,0) -> 260000000 | AM11: =IF(AND(33>=$D$11,33<=$D$11+$E$11-1),$F$11/$E$11,0) -> 260000000 | AN11: =IF(AND(34>=$D$11,34<=$D$11+$E$11-1),$F$11/$E$11,0) -> 260000000 | AO11: =IF(AND(35>=$D$11,35<=$D$11+$E$11-1),$F$11/$E$11,0) -> 260000000 | AP11: =IF(AND(36>=$D$11,36<=$D$11+$E$11-1),$F$11/$E$11,0) -> 260000000 | AQ11: =IF(AND(37>=$D$11,37<=$D$11+$E$11-1),$F$11/$E$11,0) -> 260000000 | AR11: =IF(AND(38>=$D$11,38<=$D$11+$E$11-1),$F$11/$E$11,0) -> 0 | AS11: =IF(AND(39>=$D$11,39<=$D$11+$E$11-1),$F$11/$E$11,0) -> 0 | AT11: =IF(AND(40>=$D$11,40<=$D$11+$E$11-1),$F$11/$E$11,0) -> 0 | AU11: =IF(AND(41>=$D$11,41<=$D$11+$E$11-1),$F$11/$E$11,0) -> 0 | AV11: =IF(AND(42>=$D$11,42<=$D$11+$E$11-1),$F$11/$E$11,0) -> 0 | AW11: =IF(AND(43>=$D$11,43<=$D$11+$E$11-1),$F$11/$E$11,0) -> 0 | AX11: =IF(AND(44>=$D$11,44<=$D$11+$E$11-1),$F$11/$E$11,0) -> 0 | AY11: =IF(AND(45>=$D$11,45<=$D$11+$E$11-1),$F$11/$E$11,0) -> 0 | AZ11: =IF(AND(46>=$D$11,46<=$D$11+$E$11-1),$F$11/$E$11,0) -> 0 | BA11: =IF(AND(47>=$D$11,47<=$D$11+$E$11-1),$F$11/$E$11,0) -> 0 | BB11: =IF(AND(48>=$D$11,48<=$D$11+$E$11-1),$F$11/$E$11,0) -> 0 | BC11: =IF(AND(49>=$D$11,49<=$D$11+$E$11-1),$F$11/$E$11,0) -> 0 | BD11: =IF(AND(50>=$D$11,50<=$D$11+$E$11-1),$F$11/$E$11,0) -> 0 | BE11: =IF(AND(51>=$D$11,51<=$D$11+$E$11-1),$F$11/$E$11,0) -> 0 | BF11: =IF(AND(52>=$D$11,52<=$D$11+$E$11-1),$F$11/$E$11,0) -> 0 | BG11: =IF(AND(53>=$D$11,53<=$D$11+$E$11-1),$F$11/$E$11,0) -> 0 | BH11: =IF(AND(54>=$D$11,54<=$D$11+$E$11-1),$F$11/$E$11,0) -> 0 | BI11: =IF(AND(55>=$D$11,55<=$D$11+$E$11-1),$F$11/$E$11,0) -> 0 | BJ11: =IF(AND(56>=$D$11,56<=$D$11+$E$11-1),$F$11/$E$11,0) -> 0 | BK11: =IF(AND(57>=$D$11,57<=$D$11+$E$11-1),$F$11/$E$11,0) -> 0 | BL11: =IF(AND(58>=$D$11,58<=$D$11+$E$11-1),$F$11/$E$11,0) -> 0 | BM11: =IF(AND(59>=$D$11,59<=$D$11+$E$11-1),$F$11/$E$11,0) -> 0 | BN11: =IF(AND(60>=$D$11,60<=$D$11+$E$11-1),$F$11/$E$11,0) -> 0
A12: CH-09 | B12: Centre des congrès | C12: Tertiaire public | D12: 22 | E12: 24 | F12: 7800000000 | G12: =IF(AND(1>=$D$12,1<=$D$12+$E$12-1),$F$12/$E$12,0) -> 0 | H12: =IF(AND(2>=$D$12,2<=$D$12+$E$12-1),$F$12/$E$12,0) -> 0 | I12: =IF(AND(3>=$D$12,3<=$D$12+$E$12-1),$F$12/$E$12,0) -> 0 | J12: =IF(AND(4>=$D$12,4<=$D$12+$E$12-1),$F$12/$E$12,0) -> 0 | K12: =IF(AND(5>=$D$12,5<=$D$12+$E$12-1),$F$12/$E$12,0) -> 0 | L12: =IF(AND(6>=$D$12,6<=$D$12+$E$12-1),$F$12/$E$12,0) -> 0 | M12: =IF(AND(7>=$D$12,7<=$D$12+$E$12-1),$F$12/$E$12,0) -> 0 | N12: =IF(AND(8>=$D$12,8<=$D$12+$E$12-1),$F$12/$E$12,0) -> 0 | O12: =IF(AND(9>=$D$12,9<=$D$12+$E$12-1),$F$12/$E$12,0) -> 0 | P12: =IF(AND(10>=$D$12,10<=$D$12+$E$12-1),$F$12/$E$12,0) -> 0 | Q12: =IF(AND(11>=$D$12,11<=$D$12+$E$12-1),$F$12/$E$12,0) -> 0 | R12: =IF(AND(12>=$D$12,12<=$D$12+$E$12-1),$F$12/$E$12,0) -> 0 | S12: =IF(AND(13>=$D$12,13<=$D$12+$E$12-1),$F$12/$E$12,0) -> 0 | T12: =IF(AND(14>=$D$12,14<=$D$12+$E$12-1),$F$12/$E$12,0) -> 0 | U12: =IF(AND(15>=$D$12,15<=$D$12+$E$12-1),$F$12/$E$12,0) -> 0 | V12: =IF(AND(16>=$D$12,16<=$D$12+$E$12-1),$F$12/$E$12,0) -> 0 | W12: =IF(AND(17>=$D$12,17<=$D$12+$E$12-1),$F$12/$E$12,0) -> 0 | X12: =IF(AND(18>=$D$12,18<=$D$12+$E$12-1),$F$12/$E$12,0) -> 0 | Y12: =IF(AND(19>=$D$12,19<=$D$12+$E$12-1),$F$12/$E$12,0) -> 0 | Z12: =IF(AND(20>=$D$12,20<=$D$12+$E$12-1),$F$12/$E$12,0) -> 0 | AA12: =IF(AND(21>=$D$12,21<=$D$12+$E$12-1),$F$12/$E$12,0) -> 0 | AB12: =IF(AND(22>=$D$12,22<=$D$12+$E$12-1),$F$12/$E$12,0) -> 325000000 | AC12: =IF(AND(23>=$D$12,23<=$D$12+$E$12-1),$F$12/$E$12,0) -> 325000000 | AD12: =IF(AND(24>=$D$12,24<=$D$12+$E$12-1),$F$12/$E$12,0) -> 325000000 | AE12: =IF(AND(25>=$D$12,25<=$D$12+$E$12-1),$F$12/$E$12,0) -> 325000000 | AF12: =IF(AND(26>=$D$12,26<=$D$12+$E$12-1),$F$12/$E$12,0) -> 325000000 | AG12: =IF(AND(27>=$D$12,27<=$D$12+$E$12-1),$F$12/$E$12,0) -> 325000000 | AH12: =IF(AND(28>=$D$12,28<=$D$12+$E$12-1),$F$12/$E$12,0) -> 325000000 | AI12: =IF(AND(29>=$D$12,29<=$D$12+$E$12-1),$F$12/$E$12,0) -> 325000000 | AJ12: =IF(AND(30>=$D$12,30<=$D$12+$E$12-1),$F$12/$E$12,0) -> 325000000 | AK12: =IF(AND(31>=$D$12,31<=$D$12+$E$12-1),$F$12/$E$12,0) -> 325000000 | AL12: =IF(AND(32>=$D$12,32<=$D$12+$E$12-1),$F$12/$E$12,0) -> 325000000 | AM12: =IF(AND(33>=$D$12,33<=$D$12+$E$12-1),$F$12/$E$12,0) -> 325000000 | AN12: =IF(AND(34>=$D$12,34<=$D$12+$E$12-1),$F$12/$E$12,0) -> 325000000 | AO12: =IF(AND(35>=$D$12,35<=$D$12+$E$12-1),$F$12/$E$12,0) -> 325000000 | AP12: =IF(AND(36>=$D$12,36<=$D$12+$E$12-1),$F$12/$E$12,0) -> 325000000 | AQ12: =IF(AND(37>=$D$12,37<=$D$12+$E$12-1),$F$12/$E$12,0) -> 325000000 | AR12: =IF(AND(38>=$D$12,38<=$D$12+$E$12-1),$F$12/$E$12,0) -> 325000000 | AS12: =IF(AND(39>=$D$12,39<=$D$12+$E$12-1),$F$12/$E$12,0) -> 325000000 | AT12: =IF(AND(40>=$D$12,40<=$D$12+$E$12-1),$F$12/$E$12,0) -> 325000000 | AU12: =IF(AND(41>=$D$12,41<=$D$12+$E$12-1),$F$12/$E$12,0) -> 325000000 | AV12: =IF(AND(42>=$D$12,42<=$D$12+$E$12-1),$F$12/$E$12,0) -> 325000000 | AW12: =IF(AND(43>=$D$12,43<=$D$12+$E$12-1),$F$12/$E$12,0) -> 325000000 | AX12: =IF(AND(44>=$D$12,44<=$D$12+$E$12-1),$F$12/$E$12,0) -> 325000000 | AY12: =IF(AND(45>=$D$12,45<=$D$12+$E$12-1),$F$12/$E$12,0) -> 325000000 | AZ12: =IF(AND(46>=$D$12,46<=$D$12+$E$12-1),$F$12/$E$12,0) -> 0 | BA12: =IF(AND(47>=$D$12,47<=$D$12+$E$12-1),$F$12/$E$12,0) -> 0 | BB12: =IF(AND(48>=$D$12,48<=$D$12+$E$12-1),$F$12/$E$12,0) -> 0 | BC12: =IF(AND(49>=$D$12,49<=$D$12+$E$12-1),$F$12/$E$12,0) -> 0 | BD12: =IF(AND(50>=$D$12,50<=$D$12+$E$12-1),$F$12/$E$12,0) -> 0 | BE12: =IF(AND(51>=$D$12,51<=$D$12+$E$12-1),$F$12/$E$12,0) -> 0 | BF12: =IF(AND(52>=$D$12,52<=$D$12+$E$12-1),$F$12/$E$12,0) -> 0 | BG12: =IF(AND(53>=$D$12,53<=$D$12+$E$12-1),$F$12/$E$12,0) -> 0 | BH12: =IF(AND(54>=$D$12,54<=$D$12+$E$12-1),$F$12/$E$12,0) -> 0 | BI12: =IF(AND(55>=$D$12,55<=$D$12+$E$12-1),$F$12/$E$12,0) -> 0 | BJ12: =IF(AND(56>=$D$12,56<=$D$12+$E$12-1),$F$12/$E$12,0) -> 0 | BK12: =IF(AND(57>=$D$12,57<=$D$12+$E$12-1),$F$12/$E$12,0) -> 0 | BL12: =IF(AND(58>=$D$12,58<=$D$12+$E$12-1),$F$12/$E$12,0) -> 0 | BM12: =IF(AND(59>=$D$12,59<=$D$12+$E$12-1),$F$12/$E$12,0) -> 0 | BN12: =IF(AND(60>=$D$12,60<=$D$12+$E$12-1),$F$12/$E$12,0) -> 0
A13: CH-10 | B13: Logements résidentiels haut-standing | C13: Logement | D13: 28 | E13: 20 | F13: 5500000000 | G13: =IF(AND(1>=$D$13,1<=$D$13+$E$13-1),$F$13/$E$13,0) -> 0 | H13: =IF(AND(2>=$D$13,2<=$D$13+$E$13-1),$F$13/$E$13,0) -> 0 | I13: =IF(AND(3>=$D$13,3<=$D$13+$E$13-1),$F$13/$E$13,0) -> 0 | J13: =IF(AND(4>=$D$13,4<=$D$13+$E$13-1),$F$13/$E$13,0) -> 0 | K13: =IF(AND(5>=$D$13,5<=$D$13+$E$13-1),$F$13/$E$13,0) -> 0 | L13: =IF(AND(6>=$D$13,6<=$D$13+$E$13-1),$F$13/$E$13,0) -> 0 | M13: =IF(AND(7>=$D$13,7<=$D$13+$E$13-1),$F$13/$E$13,0) -> 0 | N13: =IF(AND(8>=$D$13,8<=$D$13+$E$13-1),$F$13/$E$13,0) -> 0 | O13: =IF(AND(9>=$D$13,9<=$D$13+$E$13-1),$F$13/$E$13,0) -> 0 | P13: =IF(AND(10>=$D$13,10<=$D$13+$E$13-1),$F$13/$E$13,0) -> 0 | Q13: =IF(AND(11>=$D$13,11<=$D$13+$E$13-1),$F$13/$E$13,0) -> 0 | R13: =IF(AND(12>=$D$13,12<=$D$13+$E$13-1),$F$13/$E$13,0) -> 0 | S13: =IF(AND(13>=$D$13,13<=$D$13+$E$13-1),$F$13/$E$13,0) -> 0 | T13: =IF(AND(14>=$D$13,14<=$D$13+$E$13-1),$F$13/$E$13,0) -> 0 | U13: =IF(AND(15>=$D$13,15<=$D$13+$E$13-1),$F$13/$E$13,0) -> 0 | V13: =IF(AND(16>=$D$13,16<=$D$13+$E$13-1),$F$13/$E$13,0) -> 0 | W13: =IF(AND(17>=$D$13,17<=$D$13+$E$13-1),$F$13/$E$13,0) -> 0 | X13: =IF(AND(18>=$D$13,18<=$D$13+$E$13-1),$F$13/$E$13,0) -> 0 | Y13: =IF(AND(19>=$D$13,19<=$D$13+$E$13-1),$F$13/$E$13,0) -> 0 | Z13: =IF(AND(20>=$D$13,20<=$D$13+$E$13-1),$F$13/$E$13,0) -> 0 | AA13: =IF(AND(21>=$D$13,21<=$D$13+$E$13-1),$F$13/$E$13,0) -> 0 | AB13: =IF(AND(22>=$D$13,22<=$D$13+$E$13-1),$F$13/$E$13,0) -> 0 | AC13: =IF(AND(23>=$D$13,23<=$D$13+$E$13-1),$F$13/$E$13,0) -> 0 | AD13: =IF(AND(24>=$D$13,24<=$D$13+$E$13-1),$F$13/$E$13,0) -> 0 | AE13: =IF(AND(25>=$D$13,25<=$D$13+$E$13-1),$F$13/$E$13,0) -> 0 | AF13: =IF(AND(26>=$D$13,26<=$D$13+$E$13-1),$F$13/$E$13,0) -> 0 | AG13: =IF(AND(27>=$D$13,27<=$D$13+$E$13-1),$F$13/$E$13,0) -> 0 | AH13: =IF(AND(28>=$D$13,28<=$D$13+$E$13-1),$F$13/$E$13,0) -> 275000000 | AI13: =IF(AND(29>=$D$13,29<=$D$13+$E$13-1),$F$13/$E$13,0) -> 275000000 | AJ13: =IF(AND(30>=$D$13,30<=$D$13+$E$13-1),$F$13/$E$13,0) -> 275000000 | AK13: =IF(AND(31>=$D$13,31<=$D$13+$E$13-1),$F$13/$E$13,0) -> 275000000 | AL13: =IF(AND(32>=$D$13,32<=$D$13+$E$13-1),$F$13/$E$13,0) -> 275000000 | AM13: =IF(AND(33>=$D$13,33<=$D$13+$E$13-1),$F$13/$E$13,0) -> 275000000 | AN13: =IF(AND(34>=$D$13,34<=$D$13+$E$13-1),$F$13/$E$13,0) -> 275000000 | AO13: =IF(AND(35>=$D$13,35<=$D$13+$E$13-1),$F$13/$E$13,0) -> 275000000 | AP13: =IF(AND(36>=$D$13,36<=$D$13+$E$13-1),$F$13/$E$13,0) -> 275000000 | AQ13: =IF(AND(37>=$D$13,37<=$D$13+$E$13-1),$F$13/$E$13,0) -> 275000000 | AR13: =IF(AND(38>=$D$13,38<=$D$13+$E$13-1),$F$13/$E$13,0) -> 275000000 | AS13: =IF(AND(39>=$D$13,39<=$D$13+$E$13-1),$F$13/$E$13,0) -> 275000000 | AT13: =IF(AND(40>=$D$13,40<=$D$13+$E$13-1),$F$13/$E$13,0) -> 275000000 | AU13: =IF(AND(41>=$D$13,41<=$D$13+$E$13-1),$F$13/$E$13,0) -> 275000000 | AV13: =IF(AND(42>=$D$13,42<=$D$13+$E$13-1),$F$13/$E$13,0) -> 275000000 | AW13: =IF(AND(43>=$D$13,43<=$D$13+$E$13-1),$F$13/$E$13,0) -> 275000000 | AX13: =IF(AND(44>=$D$13,44<=$D$13+$E$13-1),$F$13/$E$13,0) -> 275000000 | AY13: =IF(AND(45>=$D$13,45<=$D$13+$E$13-1),$F$13/$E$13,0) -> 275000000 | AZ13: =IF(AND(46>=$D$13,46<=$D$13+$E$13-1),$F$13/$E$13,0) -> 275000000 | BA13: =IF(AND(47>=$D$13,47<=$D$13+$E$13-1),$F$13/$E$13,0) -> 275000000 | BB13: =IF(AND(48>=$D$13,48<=$D$13+$E$13-1),$F$13/$E$13,0) -> 0 | BC13: =IF(AND(49>=$D$13,49<=$D$13+$E$13-1),$F$13/$E$13,0) -> 0 | BD13: =IF(AND(50>=$D$13,50<=$D$13+$E$13-1),$F$13/$E$13,0) -> 0 | BE13: =IF(AND(51>=$D$13,51<=$D$13+$E$13-1),$F$13/$E$13,0) -> 0 | BF13: =IF(AND(52>=$D$13,52<=$D$13+$E$13-1),$F$13/$E$13,0) -> 0 | BG13: =IF(AND(53>=$D$13,53<=$D$13+$E$13-1),$F$13/$E$13,0) -> 0 | BH13: =IF(AND(54>=$D$13,54<=$D$13+$E$13-1),$F$13/$E$13,0) -> 0 | BI13: =IF(AND(55>=$D$13,55<=$D$13+$E$13-1),$F$13/$E$13,0) -> 0 | BJ13: =IF(AND(56>=$D$13,56<=$D$13+$E$13-1),$F$13/$E$13,0) -> 0 | BK13: =IF(AND(57>=$D$13,57<=$D$13+$E$13-1),$F$13/$E$13,0) -> 0 | BL13: =IF(AND(58>=$D$13,58<=$D$13+$E$13-1),$F$13/$E$13,0) -> 0 | BM13: =IF(AND(59>=$D$13,59<=$D$13+$E$13-1),$F$13/$E$13,0) -> 0 | BN13: =IF(AND(60>=$D$13,60<=$D$13+$E$13-1),$F$13/$E$13,0) -> 0
A14: CH-11 | B14: Hôpital régional | C14: Santé publique | D14: 32 | E14: 26 | F14: 8500000000 | G14: =IF(AND(1>=$D$14,1<=$D$14+$E$14-1),$F$14/$E$14,0) -> 0 | H14: =IF(AND(2>=$D$14,2<=$D$14+$E$14-1),$F$14/$E$14,0) -> 0 | I14: =IF(AND(3>=$D$14,3<=$D$14+$E$14-1),$F$14/$E$14,0) -> 0 | J14: =IF(AND(4>=$D$14,4<=$D$14+$E$14-1),$F$14/$E$14,0) -> 0 | K14: =IF(AND(5>=$D$14,5<=$D$14+$E$14-1),$F$14/$E$14,0) -> 0 | L14: =IF(AND(6>=$D$14,6<=$D$14+$E$14-1),$F$14/$E$14,0) -> 0 | M14: =IF(AND(7>=$D$14,7<=$D$14+$E$14-1),$F$14/$E$14,0) -> 0 | N14: =IF(AND(8>=$D$14,8<=$D$14+$E$14-1),$F$14/$E$14,0) -> 0 | O14: =IF(AND(9>=$D$14,9<=$D$14+$E$14-1),$F$14/$E$14,0) -> 0 | P14: =IF(AND(10>=$D$14,10<=$D$14+$E$14-1),$F$14/$E$14,0) -> 0 | Q14: =IF(AND(11>=$D$14,11<=$D$14+$E$14-1),$F$14/$E$14,0) -> 0 | R14: =IF(AND(12>=$D$14,12<=$D$14+$E$14-1),$F$14/$E$14,0) -> 0 | S14: =IF(AND(13>=$D$14,13<=$D$14+$E$14-1),$F$14/$E$14,0) -> 0 | T14: =IF(AND(14>=$D$14,14<=$D$14+$E$14-1),$F$14/$E$14,0) -> 0 | U14: =IF(AND(15>=$D$14,15<=$D$14+$E$14-1),$F$14/$E$14,0) -> 0 | V14: =IF(AND(16>=$D$14,16<=$D$14+$E$14-1),$F$14/$E$14,0) -> 0 | W14: =IF(AND(17>=$D$14,17<=$D$14+$E$14-1),$F$14/$E$14,0) -> 0 | X14: =IF(AND(18>=$D$14,18<=$D$14+$E$14-1),$F$14/$E$14,0) -> 0 | Y14: =IF(AND(19>=$D$14,19<=$D$14+$E$14-1),$F$14/$E$14,0) -> 0 | Z14: =IF(AND(20>=$D$14,20<=$D$14+$E$14-1),$F$14/$E$14,0) -> 0 | AA14: =IF(AND(21>=$D$14,21<=$D$14+$E$14-1),$F$14/$E$14,0) -> 0 | AB14: =IF(AND(22>=$D$14,22<=$D$14+$E$14-1),$F$14/$E$14,0) -> 0 | AC14: =IF(AND(23>=$D$14,23<=$D$14+$E$14-1),$F$14/$E$14,0) -> 0 | AD14: =IF(AND(24>=$D$14,24<=$D$14+$E$14-1),$F$14/$E$14,0) -> 0 | AE14: =IF(AND(25>=$D$14,25<=$D$14+$E$14-1),$F$14/$E$14,0) -> 0 | AF14: =IF(AND(26>=$D$14,26<=$D$14+$E$14-1),$F$14/$E$14,0) -> 0 | AG14: =IF(AND(27>=$D$14,27<=$D$14+$E$14-1),$F$14/$E$14,0) -> 0 | AH14: =IF(AND(28>=$D$14,28<=$D$14+$E$14-1),$F$14/$E$14,0) -> 0 | AI14: =IF(AND(29>=$D$14,29<=$D$14+$E$14-1),$F$14/$E$14,0) -> 0 | AJ14: =IF(AND(30>=$D$14,30<=$D$14+$E$14-1),$F$14/$E$14,0) -> 0 | AK14: =IF(AND(31>=$D$14,31<=$D$14+$E$14-1),$F$14/$E$14,0) -> 0 | AL14: =IF(AND(32>=$D$14,32<=$D$14+$E$14-1),$F$14/$E$14,0) -> 3.2692308e+08 | AM14: =IF(AND(33>=$D$14,33<=$D$14+$E$14-1),$F$14/$E$14,0) -> 3.2692308e+08 | AN14: =IF(AND(34>=$D$14,34<=$D$14+$E$14-1),$F$14/$E$14,0) -> 3.2692308e+08 | AO14: =IF(AND(35>=$D$14,35<=$D$14+$E$14-1),$F$14/$E$14,0) -> 3.2692308e+08 | AP14: =IF(AND(36>=$D$14,36<=$D$14+$E$14-1),$F$14/$E$14,0) -> 3.2692308e+08 | AQ14: =IF(AND(37>=$D$14,37<=$D$14+$E$14-1),$F$14/$E$14,0) -> 3.2692308e+08 | AR14: =IF(AND(38>=$D$14,38<=$D$14+$E$14-1),$F$14/$E$14,0) -> 3.2692308e+08 | AS14: =IF(AND(39>=$D$14,39<=$D$14+$E$14-1),$F$14/$E$14,0) -> 3.2692308e+08 | AT14: =IF(AND(40>=$D$14,40<=$D$14+$E$14-1),$F$14/$E$14,0) -> 3.2692308e+08 | AU14: =IF(AND(41>=$D$14,41<=$D$14+$E$14-1),$F$14/$E$14,0) -> 3.2692308e+08 | AV14: =IF(AND(42>=$D$14,42<=$D$14+$E$14-1),$F$14/$E$14,0) -> 3.2692308e+08 | AW14: =IF(AND(43>=$D$14,43<=$D$14+$E$14-1),$F$14/$E$14,0) -> 3.2692308e+08 | AX14: =IF(AND(44>=$D$14,44<=$D$14+$E$14-1),$F$14/$E$14,0) -> 3.2692308e+08 | AY14: =IF(AND(45>=$D$14,45<=$D$14+$E$14-1),$F$14/$E$14,0) -> 3.2692308e+08 | AZ14: =IF(AND(46>=$D$14,46<=$D$14+$E$14-1),$F$14/$E$14,0) -> 3.2692308e+08 | BA14: =IF(AND(47>=$D$14,47<=$D$14+$E$14-1),$F$14/$E$14,0) -> 3.2692308e+08 | BB14: =IF(AND(48>=$D$14,48<=$D$14+$E$14-1),$F$14/$E$14,0) -> 3.2692308e+08 | BC14: =IF(AND(49>=$D$14,49<=$D$14+$E$14-1),$F$14/$E$14,0) -> 3.2692308e+08 | BD14: =IF(AND(50>=$D$14,50<=$D$14+$E$14-1),$F$14/$E$14,0) -> 3.2692308e+08 | BE14: =IF(AND(51>=$D$14,51<=$D$14+$E$14-1),$F$14/$E$14,0) -> 3.2692308e+08 | BF14: =IF(AND(52>=$D$14,52<=$D$14+$E$14-1),$F$14/$E$14,0) -> 3.2692308e+08 | BG14: =IF(AND(53>=$D$14,53<=$D$14+$E$14-1),$F$14/$E$14,0) -> 3.2692308e+08 | BH14: =IF(AND(54>=$D$14,54<=$D$14+$E$14-1),$F$14/$E$14,0) -> 3.2692308e+08 | BI14: =IF(AND(55>=$D$14,55<=$D$14+$E$14-1),$F$14/$E$14,0) -> 3.2692308e+08 | BJ14: =IF(AND(56>=$D$14,56<=$D$14+$E$14-1),$F$14/$E$14,0) -> 3.2692308e+08 | BK14: =IF(AND(57>=$D$14,57<=$D$14+$E$14-1),$F$14/$E$14,0) -> 3.2692308e+08 | BL14: =IF(AND(58>=$D$14,58<=$D$14+$E$14-1),$F$14/$E$14,0) -> 0 | BM14: =IF(AND(59>=$D$14,59<=$D$14+$E$14-1),$F$14/$E$14,0) -> 0 | BN14: =IF(AND(60>=$D$14,60<=$D$14+$E$14-1),$F$14/$E$14,0) -> 0
A15: CH-12 | B15: Complexe sportif olympique | C15: Public | D15: 40 | E15: 22 | F15: 6800000000 | G15: =IF(AND(1>=$D$15,1<=$D$15+$E$15-1),$F$15/$E$15,0) -> 0 | H15: =IF(AND(2>=$D$15,2<=$D$15+$E$15-1),$F$15/$E$15,0) -> 0 | I15: =IF(AND(3>=$D$15,3<=$D$15+$E$15-1),$F$15/$E$15,0) -> 0 | J15: =IF(AND(4>=$D$15,4<=$D$15+$E$15-1),$F$15/$E$15,0) -> 0 | K15: =IF(AND(5>=$D$15,5<=$D$15+$E$15-1),$F$15/$E$15,0) -> 0 | L15: =IF(AND(6>=$D$15,6<=$D$15+$E$15-1),$F$15/$E$15,0) -> 0 | M15: =IF(AND(7>=$D$15,7<=$D$15+$E$15-1),$F$15/$E$15,0) -> 0 | N15: =IF(AND(8>=$D$15,8<=$D$15+$E$15-1),$F$15/$E$15,0) -> 0 | O15: =IF(AND(9>=$D$15,9<=$D$15+$E$15-1),$F$15/$E$15,0) -> 0 | P15: =IF(AND(10>=$D$15,10<=$D$15+$E$15-1),$F$15/$E$15,0) -> 0 | Q15: =IF(AND(11>=$D$15,11<=$D$15+$E$15-1),$F$15/$E$15,0) -> 0 | R15: =IF(AND(12>=$D$15,12<=$D$15+$E$15-1),$F$15/$E$15,0) -> 0 | S15: =IF(AND(13>=$D$15,13<=$D$15+$E$15-1),$F$15/$E$15,0) -> 0 | T15: =IF(AND(14>=$D$15,14<=$D$15+$E$15-1),$F$15/$E$15,0) -> 0 | U15: =IF(AND(15>=$D$15,15<=$D$15+$E$15-1),$F$15/$E$15,0) -> 0 | V15: =IF(AND(16>=$D$15,16<=$D$15+$E$15-1),$F$15/$E$15,0) -> 0 | W15: =IF(AND(17>=$D$15,17<=$D$15+$E$15-1),$F$15/$E$15,0) -> 0 | X15: =IF(AND(18>=$D$15,18<=$D$15+$E$15-1),$F$15/$E$15,0) -> 0 | Y15: =IF(AND(19>=$D$15,19<=$D$15+$E$15-1),$F$15/$E$15,0) -> 0 | Z15: =IF(AND(20>=$D$15,20<=$D$15+$E$15-1),$F$15/$E$15,0) -> 0 | AA15: =IF(AND(21>=$D$15,21<=$D$15+$E$15-1),$F$15/$E$15,0) -> 0 | AB15: =IF(AND(22>=$D$15,22<=$D$15+$E$15-1),$F$15/$E$15,0) -> 0 | AC15: =IF(AND(23>=$D$15,23<=$D$15+$E$15-1),$F$15/$E$15,0) -> 0 | AD15: =IF(AND(24>=$D$15,24<=$D$15+$E$15-1),$F$15/$E$15,0) -> 0 | AE15: =IF(AND(25>=$D$15,25<=$D$15+$E$15-1),$F$15/$E$15,0) -> 0 | AF15: =IF(AND(26>=$D$15,26<=$D$15+$E$15-1),$F$15/$E$15,0) -> 0 | AG15: =IF(AND(27>=$D$15,27<=$D$15+$E$15-1),$F$15/$E$15,0) -> 0 | AH15: =IF(AND(28>=$D$15,28<=$D$15+$E$15-1),$F$15/$E$15,0) -> 0 | AI15: =IF(AND(29>=$D$15,29<=$D$15+$E$15-1),$F$15/$E$15,0) -> 0 | AJ15: =IF(AND(30>=$D$15,30<=$D$15+$E$15-1),$F$15/$E$15,0) -> 0 | AK15: =IF(AND(31>=$D$15,31<=$D$15+$E$15-1),$F$15/$E$15,0) -> 0 | AL15: =IF(AND(32>=$D$15,32<=$D$15+$E$15-1),$F$15/$E$15,0) -> 0 | AM15: =IF(AND(33>=$D$15,33<=$D$15+$E$15-1),$F$15/$E$15,0) -> 0 | AN15: =IF(AND(34>=$D$15,34<=$D$15+$E$15-1),$F$15/$E$15,0) -> 0 | AO15: =IF(AND(35>=$D$15,35<=$D$15+$E$15-1),$F$15/$E$15,0) -> 0 | AP15: =IF(AND(36>=$D$15,36<=$D$15+$E$15-1),$F$15/$E$15,0) -> 0 | AQ15: =IF(AND(37>=$D$15,37<=$D$15+$E$15-1),$F$15/$E$15,0) -> 0 | AR15: =IF(AND(38>=$D$15,38<=$D$15+$E$15-1),$F$15/$E$15,0) -> 0 | AS15: =IF(AND(39>=$D$15,39<=$D$15+$E$15-1),$F$15/$E$15,0) -> 0 | AT15: =IF(AND(40>=$D$15,40<=$D$15+$E$15-1),$F$15/$E$15,0) -> 3.0909091e+08 | AU15: =IF(AND(41>=$D$15,41<=$D$15+$E$15-1),$F$15/$E$15,0) -> 3.0909091e+08 | AV15: =IF(AND(42>=$D$15,42<=$D$15+$E$15-1),$F$15/$E$15,0) -> 3.0909091e+08 | AW15: =IF(AND(43>=$D$15,43<=$D$15+$E$15-1),$F$15/$E$15,0) -> 3.0909091e+08 | AX15: =IF(AND(44>=$D$15,44<=$D$15+$E$15-1),$F$15/$E$15,0) -> 3.0909091e+08 | AY15: =IF(AND(45>=$D$15,45<=$D$15+$E$15-1),$F$15/$E$15,0) -> 3.0909091e+08 | AZ15: =IF(AND(46>=$D$15,46<=$D$15+$E$15-1),$F$15/$E$15,0) -> 3.0909091e+08 | BA15: =IF(AND(47>=$D$15,47<=$D$15+$E$15-1),$F$15/$E$15,0) -> 3.0909091e+08 | BB15: =IF(AND(48>=$D$15,48<=$D$15+$E$15-1),$F$15/$E$15,0) -> 3.0909091e+08 | BC15: =IF(AND(49>=$D$15,49<=$D$15+$E$15-1),$F$15/$E$15,0) -> 3.0909091e+08 | BD15: =IF(AND(50>=$D$15,50<=$D$15+$E$15-1),$F$15/$E$15,0) -> 3.0909091e+08 | BE15: =IF(AND(51>=$D$15,51<=$D$15+$E$15-1),$F$15/$E$15,0) -> 3.0909091e+08 | BF15: =IF(AND(52>=$D$15,52<=$D$15+$E$15-1),$F$15/$E$15,0) -> 3.0909091e+08 | BG15: =IF(AND(53>=$D$15,53<=$D$15+$E$15-1),$F$15/$E$15,0) -> 3.0909091e+08 | BH15: =IF(AND(54>=$D$15,54<=$D$15+$E$15-1),$F$15/$E$15,0) -> 3.0909091e+08 | BI15: =IF(AND(55>=$D$15,55<=$D$15+$E$15-1),$F$15/$E$15,0) -> 3.0909091e+08 | BJ15: =IF(AND(56>=$D$15,56<=$D$15+$E$15-1),$F$15/$E$15,0) -> 3.0909091e+08 | BK15: =IF(AND(57>=$D$15,57<=$D$15+$E$15-1),$F$15/$E$15,0) -> 3.0909091e+08 | BL15: =IF(AND(58>=$D$15,58<=$D$15+$E$15-1),$F$15/$E$15,0) -> 3.0909091e+08 | BM15: =IF(AND(59>=$D$15,59<=$D$15+$E$15-1),$F$15/$E$15,0) -> 3.0909091e+08 | BN15: =IF(AND(60>=$D$15,60<=$D$15+$E$15-1),$F$15/$E$15,0) -> 3.0909091e+08
