Workbook

Sheet Notice
A1: MODÈLE FINANCIER — BANQUE UNIVERSELLE — ZONE UEMOA/CEMAC
B3: H&C Group — Référence multisectorielle
B4: Conformité : SYSCOHADA Bancaire — IFRS 9 — Bâle III
A6: 1. OBJET DU MODÈLE
B7: Objet | C7: Plan d'affaires sur 5 ans d'une banque universelle de zone UEMOA ou CEMAC. Modèle de référence pour les équipes de développement de l'outil multisectoriel H&C Group et exemple d'application pour les directions financières.
B8: Périmètre | C8: Activité commerciale (crédits + dépôts), produit net bancaire, charges générales, coût du risque IFRS 9, ratios prudentiels Bâle III, stress tests.
B9: Hypothèses clés | C9: Volumétrie clientèle, taux moyens crédits et dépôts, coefficient d'exploitation, RWAs, ratios cibles CET1, LCR, NSFR.
A11: 2. STRUCTURE DU MODÈLE
B12: Hypothèses | C12: Macro, fiscalité, RH, ratios cibles
B13: Volumétrie | C13: Clients par segment, agences, croissance
B14: Crédits | C14: Encours par catégorie, taux, produits d'intérêts
B15: Dépôts | C15: Encours par catégorie, taux, coût de la collecte
B16: PNB | C16: MNI + commissions + opérations financières
B17: Charges | C17: RH, IT, immobilier, autres frais généraux
B18: Coût risque IFRS 9 | C18: Provisionnement Stage 1/2/3
B19: P_L | C19: Compte de résultat bancaire complet
B20: Bilan | C20: Actif / passif, RWA, capitaux propres
B21: Ratios prudentiels | C21: CET1, CAR, levier, LCR, NSFR (Bâle III)
B22: KPIs | C22: ROE, ROA, NIM, coût/PNB
B23: Stress tests | C23: Scénarios stressés prudentiels
... B25: Scénarios | C25: Vue comparée Pess/Base/Opt
A27: 3. CODE COULEUR (NORME)
B28: Bleu (input) | C28: Cellule saisie manuellement — hypothèse modifiable
B29: Noir (formule) | C29: Cellule calculée automatiquement
B30: Vert (lien) | C30: Lien vers une autre feuille du classeur
B31: Fond jaune | C31: Hypothèse clé à vérifier
B32: Bandeau navy | C32: Titre / en-tête
B33: Bandeau or | C33: Sous-titre / regroupement

Sheet Hypothèses
A1: HYPOTHÈSES — BANQUE UNIVERSELLE
B3: Y1 (2026) | C3: Y2 (2027) | D3: Y3 (2028) | E3: Y4 (2029) | F3: Y5 (2030)
A4: 1. MACROÉCONOMIE & FISCALITÉ
A5: Inflation (%) | B5: 0.03 | C5: 0.025 | D5: 0.025 | E5: 0.025 | F5: 0.025 | H5: Zone CFA
A6: Taux directeur BCEAO/BEAC (%) | B6: 0.055 | C6: 0.055 | D6: 0.05 | E6: 0.05 | F6: 0.05
A7: Croissance du PIB (%) | B7: 0.06 | C7: 0.062 | D7: 0.063 | E7: 0.065 | F7: 0.067
A8: Taux IS (%) | B8: 0.3 | C8: 0.3 | D8: 0.3 | E8: 0.3 | F8: 0.3 | H8: Standard UEMOA
A9: Taxe sur opérations financières TAF (%) | B9: 0.1 | C9: 0.1 | D9: 0.1 | E9: 0.1 | F9: 0.1
A10: Charges patronales (%) | B10: 0.18 | C10: 0.18 | D10: 0.18 | E10: 0.18 | F10: 0.18
A12: 2. STRUCTURE COMMERCIALE
A13: Nombre d'agences fin de période | B13: 25 | C13: 28 | D13: 32 | E13: 35 | F13: 38
A14: Nombre de clients particuliers (k) | B14: 80 | C14: 92 | D14: 105 | E14: 118 | F14: 132 | H14: En milliers
A15: Croissance clients particuliers (%) | H15: Calculé en Volumétrie
A16: Nombre de PME clientes | B16: 1500 | C16: 1650 | D16: 1800 | E16: 1950 | F16: 2100
A17: Nombre de grands comptes corporate | B17: 120 | C17: 130 | D17: 140 | E17: 150 | F17: 160
A18: Effectifs totaux (ETP) | B18: 350 | C18: 380 | D18: 410 | E18: 440 | F18: 470
A19: Salaire chargé moyen annuel (M FCFA) | B19: 6.5 | C19: 6.8 | D19: 7.1 | E19: 7.4 | F19: 7.7
A21: 3. ENCOURS CRÉDITS (Md FCFA)
A22: Crédits aux particuliers | B22: 85 | C22: 102 | D22: 122 | E22: 144 | F22: 168
A23: Crédits aux PME | B23: 120 | C23: 144 | D23: 170 | E23: 198 | F23: 228
A24: Crédits aux grandes entreprises | B24: 180 | C24: 198 | D24: 217 | E24: 238 | F24: 261
A25: Crédits-bail (leasing) | B25: 25 | C25: 30 | D25: 36 | E25: 42 | F25: 48
A27: Total encours crédits | B27: =SUM(B22:B25) -> 410 | C27: =SUM(C22:C25) -> 474 | D27: =SUM(D22:D25) -> 545 | E27: =SUM(E22:E25) -> 622 | F27: =SUM(F22:F25) -> 705
A29: 4. TAUX SUR CRÉDITS (%)
A30: Taux moyen crédits particuliers | B30: 0.135 | C30: 0.135 | D30: 0.13 | E30: 0.13 | F30: 0.125
A31: Taux moyen crédits PME | B31: 0.115 | C31: 0.115 | D31: 0.11 | E31: 0.11 | F31: 0.105
A32: Taux moyen crédits corporates | B32: 0.085 | C32: 0.085 | D32: 0.08 | E32: 0.08 | F32: 0.075
A33: Taux moyen crédit-bail | B33: 0.105 | C33: 0.105 | D33: 0.1 | E33: 0.1 | F33: 0.095
A35: 5. ENCOURS DÉPÔTS (Md FCFA)
A36: Dépôts à vue (DAV) | B36: 180 | C36: 207 | D36: 238 | E36: 274 | F36: 314 | H36: Particuliers + entreprises
A37: Comptes d'épargne réglementés | B37: 85 | C37: 95 | D37: 106 | E37: 119 | F37: 133
A38: Dépôts à terme (DAT) | B38: 110 | C38: 122 | D38: 134 | E38: 147 | F38: 162
A39: Autres ressources clientèle | B39: 35 | C39: 38 | D39: 41 | E39: 45 | F39: 49
A41: Total ressources clientèle | B41: =SUM(B36:B39) -> 410 | C41: =SUM(C36:C39) -> 462 | D41: =SUM(D36:D39) -> 519 | E41: =SUM(E36:E39) -> 585 | F41: =SUM(F36:F39) -> 658
A43: 6. TAUX SUR DÉPÔTS / COÛT COLLECTE (%)
A44: Rémunération DAV (%) | B44: 0.002 | C44: 0.002 | D44: 0.002 | E44: 0.002 | F44: 0.002 | H44: Quasi nul
A45: Rémunération épargne (%) | B45: 0.0325 | C45: 0.0325 | D45: 0.0325 | E45: 0.0325 | F45: 0.0325 | H45: Taux réglementé
A46: Rémunération DAT moyenne (%) | B46: 0.055 | C46: 0.055 | D46: 0.05 | E46: 0.05 | F46: 0.045
A47: Rémunération autres ressources (%) | B47: 0.045 | C47: 0.045 | D47: 0.04 | E47: 0.04 | F47: 0.035
A48: Réserves obligatoires BCEAO sur DAV (%) | B48: 0.03 | C48: 0.03 | D48: 0.03 | E48: 0.03 | F48: 0.03 | H48: Non rémunérées
...

Sheet Volumétrie
A1: VOLUMÉTRIE CLIENTÈLE & RÉSEAU
B3: Y1 (2026) | C3: Y2 (2027) | D3: Y3 (2028) | E3: Y4 (2029) | F3: Y5 (2030)
A4: RÉSEAU
A5: Nombre d'agences | B5: =Hypothèses!B13 -> 25 | C5: =Hypothèses!C13 -> 28 | D5: =Hypothèses!D13 -> 32 | E5: =Hypothèses!E13 -> 35 | F5: =Hypothèses!F13 -> 38
A6: Effectifs totaux (ETP) | B6: =Hypothèses!B18 -> 350 | C6: =Hypothèses!C18 -> 380 | D6: =Hypothèses!D18 -> 410 | E6: =Hypothèses!E18 -> 440 | F6: =Hypothèses!F18 -> 470
A7: Ratio ETP / agence | B7: =IFERROR(B6/B5,0) -> 14 | C7: =IFERROR(C6/C5,0) -> 13.571429 | D7: =IFERROR(D6/D5,0) -> 12.8125 | E7: =IFERROR(E6/E5,0) -> 12.571429 | F7: =IFERROR(F6/F5,0) -> 12.368421
A9: CLIENTÈLE
A10: Particuliers (milliers) | B10: =Hypothèses!B14 -> 80 | C10: =Hypothèses!C14 -> 92 | D10: =Hypothèses!D14 -> 105 | E10: =Hypothèses!E14 -> 118 | F10: =Hypothèses!F14 -> 132
A11: Croissance particuliers (%) | B11: - | C11: =IFERROR(C10/B10-1,0) -> 0.15 | D11: =IFERROR(D10/C10-1,0) -> 0.14130435 | E11: =IFERROR(E10/D10-1,0) -> 0.12380952 | F11: =IFERROR(F10/E10-1,0) -> 0.11864407
A12: Clients PME | B12: =Hypothèses!B16 -> 1500 | C12: =Hypothèses!C16 -> 1650 | D12: =Hypothèses!D16 -> 1800 | E12: =Hypothèses!E16 -> 1950 | F12: =Hypothèses!F16 -> 2100
A13: Grands comptes corporates | B13: =Hypothèses!B17 -> 120 | C13: =Hypothèses!C17 -> 130 | D13: =Hypothèses!D17 -> 140 | E13: =Hypothèses!E17 -> 150 | F13: =Hypothèses!F17 -> 160
A15: ÉQUIPEMENT BANCAIRE (encours / client)
A16: Encours moyen / particulier (M FCFA) | B16: =IFERROR(Hypothèses!B22*1000/Hypothèses!B14,0) -> 1062.5 | C16: =IFERROR(Hypothèses!C22*1000/Hypothèses!C14,0) -> 1108.6957 | D16: =IFERROR(Hypothèses!D22*1000/Hypothèses!D14,0) -> 1161.9048 | E16: =IFERROR(Hypothèses!E22*1000/Hypothèses!E14,0) -> 1220.339 | F16: =IFERROR(Hypothèses!F22*1000/Hypothèses!F14,0) -> 1272.7273
A17: Encours moyen / PME (M FCFA) | B17: =IFERROR(Hypothèses!B23*1000/Hypothèses!B16,0) -> 80 | C17: =IFERROR(Hypothèses!C23*1000/Hypothèses!C16,0) -> 87.272727 | D17: =IFERROR(Hypothèses!D23*1000/Hypothèses!D16,0) -> 94.444444 | E17: =IFERROR(Hypothèses!E23*1000/Hypothèses!E16,0) -> 101.53846 | F17: =IFERROR(Hypothèses!F23*1000/Hypothèses!F16,0) -> 108.57143
A18: Encours moyen / corporate (M FCFA) | B18: =IFERROR(Hypothèses!B24*1000/Hypothèses!B17,0) -> 1500 | C18: =IFERROR(Hypothèses!C24*1000/Hypothèses!C17,0) -> 1523.0769 | D18: =IFERROR(Hypothèses!D24*1000/Hypothèses!D17,0) -> 1550 | E18: =IFERROR(Hypothèses!E24*1000/Hypothèses!E17,0) -> 1586.6667 | F18: =IFERROR(Hypothèses!F24*1000/Hypothèses!F17,0) -> 1631.25

Sheet Crédits
A1: ENCOURS CRÉDITS & PRODUITS D'INTÉRÊTS
B3: Y1 (2026) | C3: Y2 (2027) | D3: Y3 (2028) | E3: Y4 (2029) | F3: Y5 (2030)
A4: ENCOURS CRÉDITS FIN DE PÉRIODE (Md FCFA)
A5: Crédits aux particuliers | B5: =Hypothèses!B22 -> 85 | C5: =Hypothèses!C22 -> 102 | D5: =Hypothèses!D22 -> 122 | E5: =Hypothèses!E22 -> 144 | F5: =Hypothèses!F22 -> 168
A6: Crédits aux PME | B6: =Hypothèses!B23 -> 120 | C6: =Hypothèses!C23 -> 144 | D6: =Hypothèses!D23 -> 170 | E6: =Hypothèses!E23 -> 198 | F6: =Hypothèses!F23 -> 228
A7: Crédits aux grandes entreprises | B7: =Hypothèses!B24 -> 180 | C7: =Hypothèses!C24 -> 198 | D7: =Hypothèses!D24 -> 217 | E7: =Hypothèses!E24 -> 238 | F7: =Hypothèses!F24 -> 261
A8: Crédit-bail (leasing) | B8: =Hypothèses!B25 -> 25 | C8: =Hypothèses!C25 -> 30 | D8: =Hypothèses!D25 -> 36 | E8: =Hypothèses!E25 -> 42 | F8: =Hypothèses!F25 -> 48
A9: Total encours crédits | B9: =SUM(B5:B8) -> 410 | C9: =SUM(C5:C8) -> 474 | D9: =SUM(D5:D8) -> 545 | E9: =SUM(E5:E8) -> 622 | F9: =SUM(F5:F8) -> 705
A11: ENCOURS MOYEN (Md FCFA)
A12: Encours moyen particuliers | B12: =B5/2 -> 42.5 | C12: =(B5+C5)/2 -> 93.5 | D12: =(C5+D5)/2 -> 112 | E12: =(D5+E5)/2 -> 133 | F12: =(E5+F5)/2 -> 156
A13: Encours moyen PME | B13: =B6/2 -> 60 | C13: =(B6+C6)/2 -> 132 | D13: =(C6+D6)/2 -> 157 | E13: =(D6+E6)/2 -> 184 | F13: =(E6+F6)/2 -> 213
A14: Encours moyen corporates | B14: =B7/2 -> 90 | C14: =(B7+C7)/2 -> 189 | D14: =(C7+D7)/2 -> 207.5 | E14: =(D7+E7)/2 -> 227.5 | F14: =(E7+F7)/2 -> 249.5
A15: Encours moyen crédit-bail | B15: =B8/2 -> 12.5 | C15: =(B8+C8)/2 -> 27.5 | D15: =(C8+D8)/2 -> 33 | E15: =(D8+E8)/2 -> 39 | F15: =(E8+F8)/2 -> 45
A17: PRODUITS D'INTÉRÊTS (Md FCFA)
A18: Intérêts crédits particuliers | B18: =B12*Hypothèses!B30 -> 5.7375 | C18: =C12*Hypothèses!C30 -> 12.6225 | D18: =D12*Hypothèses!D30 -> 14.56 | E18: =E12*Hypothèses!E30 -> 17.29 | F18: =F12*Hypothèses!F30 -> 19.5
A19: Intérêts crédits PME | B19: =B13*Hypothèses!B31 -> 6.9 | C19: =C13*Hypothèses!C31 -> 15.18 | D19: =D13*Hypothèses!D31 -> 17.27 | E19: =E13*Hypothèses!E31 -> 20.24 | F19: =F13*Hypothèses!F31 -> 22.365
A20: Intérêts crédits corporates | B20: =B14*Hypothèses!B32 -> 7.65 | C20: =C14*Hypothèses!C32 -> 16.065 | D20: =D14*Hypothèses!D32 -> 16.6 | E20: =E14*Hypothèses!E32 -> 18.2 | F20: =F14*Hypothèses!F32 -> 18.7125
A21: Intérêts crédit-bail | B21: =B15*Hypothèses!B33 -> 1.3125 | C21: =C15*Hypothèses!C33 -> 2.8875 | D21: =D15*Hypothèses!D33 -> 3.3 | E21: =E15*Hypothèses!E33 -> 3.9 | F21: =F15*Hypothèses!F33 -> 4.275
A22: Total produits d'intérêts | B22: =SUM(B18:B21) -> 21.6 | C22: =SUM(C18:C21) -> 46.755 | D22: =SUM(D18:D21) -> 51.73 | E22: =SUM(E18:E21) -> 59.63 | F22: =SUM(F18:F21) -> 64.8525

Sheet Dépôts
A1: RESSOURCES CLIENTÈLE & COÛT DE LA COLLECTE
B3: Y1 (2026) | C3: Y2 (2027) | D3: Y3 (2028) | E3: Y4 (2029) | F3: Y5 (2030)
A4: ENCOURS DÉPÔTS FIN DE PÉRIODE (Md FCFA)
A5: Dépôts à vue (DAV) | B5: =Hypothèses!B36 -> 180 | C5: =Hypothèses!C36 -> 207 | D5: =Hypothèses!D36 -> 238 | E5: =Hypothèses!E36 -> 274 | F5: =Hypothèses!F36 -> 314
A6: Comptes d'épargne | B6: =Hypothèses!B37 -> 85 | C6: =Hypothèses!C37 -> 95 | D6: =Hypothèses!D37 -> 106 | E6: =Hypothèses!E37 -> 119 | F6: =Hypothèses!F37 -> 133
A7: Dépôts à terme (DAT) | B7: =Hypothèses!B38 -> 110 | C7: =Hypothèses!C38 -> 122 | D7: =Hypothèses!D38 -> 134 | E7: =Hypothèses!E38 -> 147 | F7: =Hypothèses!F38 -> 162
A8: Autres ressources clientèle | B8: =Hypothèses!B39 -> 35 | C8: =Hypothèses!C39 -> 38 | D8: =Hypothèses!D39 -> 41 | E8: =Hypothèses!E39 -> 45 | F8: =Hypothèses!F39 -> 49
A9: Total ressources clientèle | B9: =SUM(B5:B8) -> 410 | C9: =SUM(C5:C8) -> 462 | D9: =SUM(D5:D8) -> 519 | E9: =SUM(E5:E8) -> 585 | F9: =SUM(F5:F8) -> 658
A11: ENCOURS MOYEN DÉPÔTS (Md FCFA)
A12: Encours moyen DAV | B12: =B5/2 -> 90 | C12: =(B5+C5)/2 -> 193.5 | D12: =(C5+D5)/2 -> 222.5 | E12: =(D5+E5)/2 -> 256 | F12: =(E5+F5)/2 -> 294
A13: Encours moyen épargne | B13: =B6/2 -> 42.5 | C13: =(B6+C6)/2 -> 90 | D13: =(C6+D6)/2 -> 100.5 | E13: =(D6+E6)/2 -> 112.5 | F13: =(E6+F6)/2 -> 126
A14: Encours moyen DAT | B14: =B7/2 -> 55 | C14: =(B7+C7)/2 -> 116 | D14: =(C7+D7)/2 -> 128 | E14: =(D7+E7)/2 -> 140.5 | F14: =(E7+F7)/2 -> 154.5
A15: Encours moyen autres | B15: =B8/2 -> 17.5 | C15: =(B8+C8)/2 -> 36.5 | D15: =(C8+D8)/2 -> 39.5 | E15: =(D8+E8)/2 -> 43 | F15: =(E8+F8)/2 -> 47
A17: CHARGES D'INTÉRÊTS SUR DÉPÔTS (Md FCFA)
A18: Intérêts DAV | B18: =B12*Hypothèses!B44 -> 0.18 | C18: =C12*Hypothèses!C44 -> 0.387 | D18: =D12*Hypothèses!D44 -> 0.445 | E18: =E12*Hypothèses!E44 -> 0.512 | F18: =F12*Hypothèses!F44 -> 0.588
A19: Intérêts épargne | B19: =B13*Hypothèses!B45 -> 1.38125 | C19: =C13*Hypothèses!C45 -> 2.925 | D19: =D13*Hypothèses!D45 -> 3.26625 | E19: =E13*Hypothèses!E45 -> 3.65625 | F19: =F13*Hypothèses!F45 -> 4.095
A20: Intérêts DAT | B20: =B14*Hypothèses!B46 -> 3.025 | C20: =C14*Hypothèses!C46 -> 6.38 | D20: =D14*Hypothèses!D46 -> 6.4 | E20: =E14*Hypothèses!E46 -> 7.025 | F20: =F14*Hypothèses!F46 -> 6.9525
A21: Intérêts autres ressources | B21: =B15*Hypothèses!B47 -> 0.7875 | C21: =C15*Hypothèses!C47 -> 1.6425 | D21: =D15*Hypothèses!D47 -> 1.58 | E21: =E15*Hypothèses!E47 -> 1.72 | F21: =F15*Hypothèses!F47 -> 1.645
A22: Total charges d'intérêts dépôts | B22: =SUM(B18:B21) -> 5.37375 | C22: =SUM(C18:C21) -> 11.3345 | D22: =SUM(D18:D21) -> 11.69125 | E22: =SUM(E18:E21) -> 12.91325 | F22: =SUM(F18:F21) -> 13.2805
A24: INDICATEURS COLLECTE
A25: Encours moyen total ressources | B25: =SUM(B12:B15) -> 205 | C25: =SUM(C12:C15) -> 436 | D25: =SUM(D12:D15) -> 490.5 | E25: =SUM(E12:E15) -> 552 | F25: =SUM(F12:F15) -> 621.5
A26: Coût moyen pondéré de la collecte (%) | B26: =IFERROR(B22/B25,0) -> 0.026213415 | C26: =IFERROR(C22/C25,0) -> 0.02599656 | D26: =IFERROR(D22/D25,0) -> 0.023835372 | E26: =IFERROR(E22/E25,0) -> 0.023393569 | F26: =IFERROR(F22/F25,0) -> 0.021368463
A27: Part DAV non rémunérés (%) | B27: =IFERROR(B12/B25,0) -> 0.43902439 | C27: =IFERROR(C12/C25,0) -> 0.44380734 | D27: =IFERROR(D12/D25,0) -> 0.45361876 | E27: =IFERROR(E12/E25,0) -> 0.46376812 | F27: =IFERROR(F12/F25,0) -> 0.47304907

Sheet PNB
A1: PRODUIT NET BANCAIRE
B3: Y1 (2026) | C3: Y2 (2027) | D3: Y3 (2028) | E3: Y4 (2029) | F3: Y5 (2030)
A4: 1. MARGE NETTE D'INTÉRÊTS (MNI)
A5: Produits d'intérêts (crédits + placements) | B5: =Crédits!B22 -> 21.6 | C5: =Crédits!C22 -> 46.755 | D5: =Crédits!D22 -> 51.73 | E5: =Crédits!E22 -> 59.63 | F5: =Crédits!F22 -> 64.8525
A6: Charges d'intérêts (dépôts + emprunts) | B6: =Dépôts!B22 -> 5.37375 | C6: =Dépôts!C22 -> 11.3345 | D6: =Dépôts!D22 -> 11.69125 | E6: =Dépôts!E22 -> 12.91325 | F6: =Dépôts!F22 -> 13.2805
A7: Marge nette d'intérêts (MNI) | B7: =B5-B6 -> 16.22625 | C7: =C5-C6 -> 35.4205 | D7: =D5-D6 -> 40.03875 | E7: =E5-E6 -> 46.71675 | F7: =F5-F6 -> 51.572
A9: 2. COMMISSIONS ET AUTRES PRODUITS
A10: Commissions opérations clientèle | B10: =Hypothèses!B51 -> 4.2 | C10: =Hypothèses!C51 -> 4.8 | D10: =Hypothèses!D51 -> 5.4 | E10: =Hypothèses!E51 -> 6.1 | F10: =Hypothèses!F51 -> 6.8
A11: Commissions monétique | B11: =Hypothèses!B52 -> 3.5 | C11: =Hypothèses!C52 -> 4.2 | D11: =Hypothèses!D52 -> 5.1 | E11: =Hypothèses!E52 -> 6 | F11: =Hypothèses!F52 -> 7.1
A12: Commissions sur engagements | B12: =Hypothèses!B53 -> 2.8 | C12: =Hypothèses!C53 -> 3.1 | D12: =Hypothèses!D53 -> 3.5 | E12: =Hypothèses!E53 -> 3.9 | F12: =Hypothèses!F53 -> 4.3
A13: Commissions de change | B13: =Hypothèses!B54 -> 1.5 | C13: =Hypothèses!C54 -> 1.7 | D13: =Hypothèses!D54 -> 1.9 | E13: =Hypothèses!E54 -> 2.1 | F13: =Hypothèses!F54 -> 2.3
A14: Résultat opérations financières | B14: =Hypothèses!B55 -> 1.8 | C14: =Hypothèses!C55 -> 2 | D14: =Hypothèses!D55 -> 2.2 | E14: =Hypothèses!E55 -> 2.4 | F14: =Hypothèses!F55 -> 2.6
A15: Total commissions & autres produits | B15: =SUM(B10:B14) -> 13.8 | C15: =SUM(C10:C14) -> 15.8 | D15: =SUM(D10:D14) -> 18.1 | E15: =SUM(E10:E14) -> 20.5 | F15: =SUM(F10:F14) -> 23.1
A17: 3. PRODUIT NET BANCAIRE TOTAL
A18: PNB total | B18: =B7+B15 -> 30.02625 | C18: =C7+C15 -> 51.2205 | D18: =D7+D15 -> 58.13875 | E18: =E7+E15 -> 67.21675 | F18: =F7+F15 -> 74.672
A20: INDICATEURS DE PERFORMANCE PNB
A21: Part MNI dans PNB (%) | B21: =IFERROR(B7/B18,0) -> 0.54040215 | C21: =IFERROR(C7/C18,0) -> 0.69152976 | D21: =IFERROR(D7/D18,0) -> 0.6886758 | E21: =IFERROR(E7/E18,0) -> 0.6950165 | F21: =IFERROR(F7/F18,0) -> 0.6906471
A22: Part commissions dans PNB (%) | B22: =IFERROR(B15/B18,0) -> 0.45959785 | C22: =IFERROR(C15/C18,0) -> 0.30847024 | D22: =IFERROR(D15/D18,0) -> 0.3113242 | E22: =IFERROR(E15/E18,0) -> 0.3049835 | F22: =IFERROR(F15/F18,0) -> 0.3093529
A23: Croissance PNB (%) | B23: - | C23: =IFERROR(C18/B18-1,0) -> 0.70585737 | D23: =IFERROR(D18/C18-1,0) -> 0.13506799 | E23: =IFERROR(E18/D18-1,0) -> 0.15614371 | F23: =IFERROR(F18/E18-1,0) -> 0.11091357

Sheet Charges
A1: CHARGES GÉNÉRALES D'EXPLOITATION
B3: Y1 (2026) | C3: Y2 (2027) | D3: Y3 (2028) | E3: Y4 (2029) | F3: Y5 (2030)
A4: 1. CHARGES DE PERSONNEL
A5: Effectifs (ETP) | B5: =Hypothèses!B18 -> 350 | C5: =Hypothèses!C18 -> 380 | D5: =Hypothèses!D18 -> 410 | E5: =Hypothèses!E18 -> 440 | F5: =Hypothèses!F18 -> 470
A6: Salaire moyen chargé (M FCFA) | B6: =Hypothèses!B19 -> 6.5 | C6: =Hypothèses!C19 -> 6.8 | D6: =Hypothèses!D19 -> 7.1 | E6: =Hypothèses!E19 -> 7.4 | F6: =Hypothèses!F19 -> 7.7
A7: Masse salariale (Md FCFA) | B7: =B5*B6/1000 -> 2.275 | C7: =C5*C6/1000 -> 2.584 | D7: =D5*D6/1000 -> 2.911 | E7: =E5*E6/1000 -> 3.256 | F7: =F5*F6/1000 -> 3.619
A9: 2. AUTRES CHARGES GÉNÉRALES (Md FCFA)
A10: Loyers & immobilier | B10: =Hypothèses!B60 -> 3.5 | C10: =Hypothèses!C60 -> 3.8 | D10: =Hypothèses!D60 -> 4.1 | E10: =Hypothèses!E60 -> 4.4 | F10: =Hypothèses!F60 -> 4.8
A11: Énergie, télécoms, IT | B11: =Hypothèses!B61 -> 2.8 | C11: =Hypothèses!C61 -> 3.1 | D11: =Hypothèses!D61 -> 3.4 | E11: =Hypothèses!E61 -> 3.7 | F11: =Hypothèses!F61 -> 4
A12: Marketing & communication | B12: =Hypothèses!B62 -> 1.5 | C12: =Hypothèses!C62 -> 1.7 | D12: =Hypothèses!D62 -> 1.9 | E12: =Hypothèses!E62 -> 2.1 | F12: =Hypothèses!F62 -> 2.3
A13: Honoraires, conseil, audit | B13: =Hypothèses!B63 -> 1.2 | C13: =Hypothèses!C63 -> 1.3 | D13: =Hypothèses!D63 -> 1.4 | E13: =Hypothèses!E63 -> 1.5 | F13: =Hypothèses!F63 -> 1.6
A14: Maintenance & sécurité | B14: =Hypothèses!B64 -> 1.8 | C14: =Hypothèses!C64 -> 2 | D14: =Hypothèses!D64 -> 2.2 | E14: =Hypothèses!E64 -> 2.4 | F14: =Hypothèses!F64 -> 2.6
A15: Autres charges externes | B15: =Hypothèses!B65 -> 1.5 | C15: =Hypothèses!C65 -> 1.6 | D15: =Hypothèses!D65 -> 1.7 | E15: =Hypothèses!E65 -> 1.8 | F15: =Hypothèses!F65 -> 1.9
A16: Total autres charges générales | B16: =SUM(B10:B15) -> 12.3 | C16: =SUM(C10:C15) -> 13.5 | D16: =SUM(D10:D15) -> 14.7 | E16: =SUM(E10:E15) -> 15.9 | F16: =SUM(F10:F15) -> 17.2
A18: 3. CHARGES TOTALES D'EXPLOITATION
A19: Total charges générales d'exploitation | B19: =B7+B16 -> 14.575 | C19: =C7+C16 -> 16.084 | D19: =D7+D16 -> 17.611 | E19: =E7+E16 -> 19.156 | F19: =F7+F16 -> 20.819
A21: INDICATEURS PRODUCTIVITÉ
A22: Coefficient d'exploitation (Charges/PNB) | B22: =IFERROR(B19/PNB!B18,0) -> 0.4854086 | C22: =IFERROR(C19/PNB!C18,0) -> 0.3140149 | D22: =IFERROR(D19/PNB!D18,0) -> 0.30291329 | E22: =IFERROR(E19/PNB!E18,0) -> 0.28498849 | F22: =IFERROR(F19/PNB!F18,0) -> 0.27880598
A23: PNB par ETP (M FCFA) | B23: =IFERROR(PNB!B18*1000/B5,0) -> 85.789286 | C23: =IFERROR(PNB!C18*1000/C5,0) -> 134.79079 | D23: =IFERROR(PNB!D18*1000/D5,0) -> 141.80183 | E23: =IFERROR(PNB!E18*1000/E5,0) -> 152.76534 | F23: =IFERROR(PNB!F18*1000/F5,0) -> 158.8766

Sheet Coût risque
A1: COÛT DU RISQUE IFRS 9
B3: Y1 (2026) | C3: Y2 (2027) | D3: Y3 (2028) | E3: Y4 (2029) | F3: Y5 (2030)
A4: 1. ENCOURS NPL (Md FCFA)
A5: NPL crédits particuliers | B5: =Hypothèses!B22*Hypothèses!B68 -> 6.8 | C5: =Hypothèses!C22*Hypothèses!C68 -> 7.65 | D5: =Hypothèses!D22*Hypothèses!D68 -> 8.54 | E5: =Hypothèses!E22*Hypothèses!E68 -> 9.36 | F5: =Hypothèses!F22*Hypothèses!F68 -> 10.08
A6: NPL crédits PME | B6: =Hypothèses!B23*Hypothèses!B69 -> 13.2 | C6: =Hypothèses!C23*Hypothèses!C69 -> 15.12 | D6: =Hypothèses!D23*Hypothèses!D69 -> 17 | E6: =Hypothèses!E23*Hypothèses!E69 -> 18.81 | F6: =Hypothèses!F23*Hypothèses!F69 -> 20.52
A7: NPL crédits corporates | B7: =Hypothèses!B24*Hypothèses!B70 -> 9 | C7: =Hypothèses!C24*Hypothèses!C70 -> 8.91 | D7: =Hypothèses!D24*Hypothèses!D70 -> 8.68 | E7: =Hypothèses!E24*Hypothèses!E70 -> 8.33 | F7: =Hypothèses!F24*Hypothèses!F70 -> 7.83
A8: Total NPL | B8: =SUM(B5:B7) -> 29 | C8: =SUM(C5:C7) -> 31.68 | D8: =SUM(D5:D7) -> 34.22 | E8: =SUM(E5:E7) -> 36.5 | F8: =SUM(F5:F7) -> 38.43
A9: Taux de NPL moyen (NPL/encours) | B9: =IFERROR(B8/Crédits!B9,0) -> 0.070731707 | C9: =IFERROR(C8/Crédits!C9,0) -> 0.066835443 | D9: =IFERROR(D8/Crédits!D9,0) -> 0.062788991 | E9: =IFERROR(E8/Crédits!E9,0) -> 0.058681672 | F9: =IFERROR(F8/Crédits!F9,0) -> 0.054510638
A11: 2. RÉPARTITION DES ENCOURS PAR STAGE
A12: Encours total crédits | B12: =Crédits!B9 -> 410 | C12: =Crédits!C9 -> 474 | D12: =Crédits!D9 -> 545 | E12: =Crédits!E9 -> 622 | F12: =Crédits!F9 -> 705
A13: Encours sain (Stage 1) - 85% du non-NPL | B13: =(B12-B8)*0.85 -> 323.85 | C13: =(C12-C8)*0.85 -> 375.972 | D13: =(D12-D8)*0.85 -> 434.163 | E13: =(E12-E8)*0.85 -> 497.675 | F13: =(F12-F8)*0.85 -> 566.5845
A14: Encours sensible (Stage 2) - 15% du non-NPL | B14: =(B12-B8)*0.15 -> 57.15 | C14: =(C12-C8)*0.15 -> 66.348 | D14: =(D12-D8)*0.15 -> 76.617 | E14: =(E12-E8)*0.15 -> 87.825 | F14: =(F12-F8)*0.15 -> 99.9855
A15: Encours non performant (Stage 3) | B15: =B8 -> 29 | C15: =C8 -> 31.68 | D15: =D8 -> 34.22 | E15: =E8 -> 36.5 | F15: =F8 -> 38.43
A17: 3. PROVISIONS IFRS 9 (Md FCFA)
A18: Provisions Stage 1 (ECL 12 mois) | B18: =B13*Hypothèses!B71 -> 1.61925 | C18: =C13*Hypothèses!C71 -> 1.87986 | D18: =D13*Hypothèses!D71 -> 2.170815 | E18: =E13*Hypothèses!E71 -> 2.488375 | F18: =F13*Hypothèses!F71 -> 2.8329225
A19: Provisions Stage 2 (ECL lifetime) | B19: =B14*Hypothèses!B72 -> 2.286 | C19: =C14*Hypothèses!C72 -> 2.65392 | D19: =D14*Hypothèses!D72 -> 3.06468 | E19: =E14*Hypothèses!E72 -> 3.513 | F19: =F14*Hypothèses!F72 -> 3.99942
A20: Provisions Stage 3 (NPL net) | B20: =B15*Hypothèses!B73 -> 14.5 | C20: =C15*Hypothèses!C73 -> 15.84 | D20: =D15*Hypothèses!D73 -> 17.11 | E20: =E15*Hypothèses!E73 -> 18.25 | F20: =F15*Hypothèses!F73 -> 19.215
A21: Stock total de provisions | B21: =SUM(B18:B20) -> 18.40525 | C21: =SUM(C18:C20) -> 20.37378 | D21: =SUM(D18:D20) -> 22.345495 | E21: =SUM(E18:E20) -> 24.251375 | F21: =SUM(F18:F20) -> 26.047342
A23: 4. DOTATION ANNUELLE AU COÛT DU RISQUE
A24: Variation stock provisions (= dotation P&L) | B24: =B21 -> 18.40525 | C24: =C21-B21 -> 1.96853 | D24: =D21-C21 -> 1.971715 | E24: =E21-D21 -> 1.90588 | F24: =F21-E21 -> 1.7959675
A25: Coût du risque / encours moyen (%) | B25: =IFERROR(B24/B12,0) -> 0.044890854 | C25: =IFERROR(C24/((B12+C12)/2),0) -> 0.0044536878 | D25: =IFERROR(D24/((C12+D12)/2),0) -> 0.0038699019 | E25: =IFERROR(E24/((D12+E12)/2),0) -> 0.0032662896 | F25: =IFERROR(F24/((E12+F12)/2),0) -> 0.0027068086

Sheet P_L
A1: COMPTE DE RÉSULTAT BANCAIRE
B3: Y1 (2026) | C3: Y2 (2027) | D3: Y3 (2028) | E3: Y4 (2029) | F3: Y5 (2030)
A4: 1. PRODUIT NET BANCAIRE
A5: Produit Net Bancaire (PNB) | B5: =PNB!B18 -> 30.02625 | C5: =PNB!C18 -> 51.2205 | D5: =PNB!D18 -> 58.13875 | E5: =PNB!E18 -> 67.21675 | F5: =PNB!F18 -> 74.672
A7: 2. CHARGES GÉNÉRALES D'EXPLOITATION
A8: Charges générales d'exploitation | B8: =-Charges!B19 -> -14.575 | C8: =-Charges!C19 -> -16.084 | D8: =-Charges!D19 -> -17.611 | E8: =-Charges!E19 -> -19.156 | F8: =-Charges!F19 -> -20.819
A10: 3. RÉSULTAT BRUT D'EXPLOITATION
A11: Résultat Brut d'Exploitation (RBE) | B11: =B5+B8 -> 15.45125 | C11: =C5+C8 -> 35.1365 | D11: =D5+D8 -> 40.52775 | E11: =E5+E8 -> 48.06075 | F11: =F5+F8 -> 53.853
A13: 4. COÛT DU RISQUE
A14: Coût du risque (IFRS 9) | B14: =-'Coût risque'!B24 -> -18.40525 | C14: =-'Coût risque'!C24 -> -1.96853 | D14: =-'Coût risque'!D24 -> -1.971715 | E14: =-'Coût risque'!E24 -> -1.90588 | F14: =-'Coût risque'!F24 -> -1.7959675
A16: 5. RÉSULTAT D'EXPLOITATION & RÉSULTAT NET
A17: Résultat d'exploitation | B17: =B11+B14 -> -2.954 | C17: =C11+C14 -> 33.16797 | D17: =D11+D14 -> 38.556035 | E17: =E11+E14 -> 46.15487 | F17: =F11+F14 -> 52.057032
A18: Résultat avant impôt | B18: =B17 -> -2.954 | C18: =C17 -> 33.16797 | D18: =D17 -> 38.556035 | E18: =E17 -> 46.15487 | F18: =F17 -> 52.057032
A19: Impôt sur les sociétés (IS) | B19: =-MAX(B18,0)*Hypothèses!B8 -> 0 | C19: =-MAX(C18,0)*Hypothèses!C8 -> -9.950391 | D19: =-MAX(D18,0)*Hypothèses!D8 -> -11.566811 | E19: =-MAX(E18,0)*Hypothèses!E8 -> -13.846461 | F19: =-MAX(F18,0)*Hypothèses!F8 -> -15.61711
A20: RÉSULTAT NET | B20: =B18+B19 -> -2.954 | C20: =C18+C19 -> 23.217579 | D20: =D18+D19 -> 26.989224 | E20: =E18+E19 -> 32.308409 | F20: =F18+F19 -> 36.439923
A22: INDICATEURS DE RENTABILITÉ
A23: Coefficient d'exploitation | B23: =IFERROR(-B8/B5,0) -> 0.4854086 | C23: =IFERROR(-C8/C5,0) -> 0.3140149 | D23: =IFERROR(-D8/D5,0) -> 0.30291329 | E23: =IFERROR(-E8/E5,0) -> 0.28498849 | F23: =IFERROR(-F8/F5,0) -> 0.27880598
A24: Marge nette (RN/PNB) | B24: =IFERROR(B20/B5,0) -> -0.098380584 | C24: =IFERROR(C20/C5,0) -> 0.45328685 | D24: =IFERROR(D20/D5,0) -> 0.46422093 | E24: =IFERROR(E20/E5,0) -> 0.48066009 | F24: =IFERROR(F20/F5,0) -> 0.48799982

Sheet Bilan
A1: BILAN BANCAIRE — STRUCTURE PRUDENTIELLE
B3: Y1 (2026) | C3: Y2 (2027) | D3: Y3 (2028) | E3: Y4 (2029) | F3: Y5 (2030)
A4: ACTIF (Md FCFA)
A5: Caisse & banques centrales (incl. réserves obligatoires) | B5: =Dépôts!B5*(Hypothèses!B48+0.02) -> 9 | C5: =Dépôts!C5*(Hypothèses!C48+0.02) -> 10.35 | D5: =Dépôts!D5*(Hypothèses!D48+0.02) -> 11.9 | E5: =Dépôts!E5*(Hypothèses!E48+0.02) -> 13.7 | F5: =Dépôts!F5*(Hypothèses!F48+0.02) -> 15.7
A6: Créances interbancaires | B6: =Crédits!B9*0.06 -> 24.6 | C6: =Crédits!C9*0.06 -> 28.44 | D6: =Crédits!D9*0.06 -> 32.7 | E6: =Crédits!E9*0.06 -> 37.32 | F6: =Crédits!F9*0.06 -> 42.3
A7: Portefeuille de titres | B7: =Crédits!B9*0.15 -> 61.5 | C7: =Crédits!C9*0.15 -> 71.1 | D7: =Crédits!D9*0.15 -> 81.75 | E7: =Crédits!E9*0.15 -> 93.3 | F7: =Crédits!F9*0.15 -> 105.75
A8: Crédits clientèle bruts | B8: =Crédits!B9 -> 410 | C8: =Crédits!C9 -> 474 | D8: =Crédits!D9 -> 545 | E8: =Crédits!E9 -> 622 | F8: =Crédits!F9 -> 705
A9: - Provisions sur crédits | B9: =-'Coût risque'!B21 -> -18.40525 | C9: =-'Coût risque'!C21 -> -20.37378 | D9: =-'Coût risque'!D21 -> -22.345495 | E9: =-'Coût risque'!E21 -> -24.251375 | F9: =-'Coût risque'!F21 -> -26.047342
A10: Crédits clientèle nets | B10: =B8+B9 -> 391.59475 | C10: =C8+C9 -> 453.62622 | D10: =D8+D9 -> 522.6545 | E10: =E8+E9 -> 597.74862 | F10: =F8+F9 -> 678.95266
A11: Immobilisations nettes | B11: 18 | C11: 20 | D11: 22 | E11: 24 | F11: 26
A12: Autres actifs | B12: 10 | C12: 11 | D12: 12 | E12: 13 | F12: 14
A13: TOTAL ACTIF | B13: =B5+B6+B7+B10+B11+B12 -> 514.69475 | C13: =C5+C6+C7+C10+C11+C12 -> 594.51622 | D13: =D5+D6+D7+D10+D11+D12 -> 683.0045 | E13: =E5+E6+E7+E10+E11+E12 -> 779.06862 | F13: =F5+F6+F7+F10+F11+F12 -> 882.70266
A15: PASSIF (Md FCFA)
A16: Dépôts à vue (DAV) | B16: =Dépôts!B5 -> 180 | C16: =Dépôts!C5 -> 207 | D16: =Dépôts!D5 -> 238 | E16: =Dépôts!E5 -> 274 | F16: =Dépôts!F5 -> 314
A17: Comptes d'épargne | B17: =Dépôts!B6 -> 85 | C17: =Dépôts!C6 -> 95 | D17: =Dépôts!D6 -> 106 | E17: =Dépôts!E6 -> 119 | F17: =Dépôts!F6 -> 133
A18: Dépôts à terme (DAT) | B18: =Dépôts!B7 -> 110 | C18: =Dépôts!C7 -> 122 | D18: =Dépôts!D7 -> 134 | E18: =Dépôts!E7 -> 147 | F18: =Dépôts!F7 -> 162
A19: Autres ressources clientèle | B19: =Dépôts!B8 -> 35 | C19: =Dépôts!C8 -> 38 | D19: =Dépôts!D8 -> 41 | E19: =Dépôts!E8 -> 45 | F19: =Dépôts!F8 -> 49
A20: Total ressources clientèle | B20: =SUM(B16:B19) -> 410 | C20: =SUM(C16:C19) -> 462 | D20: =SUM(D16:D19) -> 519 | E20: =SUM(E16:E19) -> 585 | F20: =SUM(F16:F19) -> 658
A21: Emprunts interbancaires & ressources marché | B21: 12 | C21: 14 | D21: 16 | E21: 18 | F21: 20
A22: Provisions diverses | B22: 3 | C22: 3.2 | D22: 3.4 | E22: 3.6 | F22: 3.8
A23: Capital social | B23: =Hypothèses!B76 -> 50 | C23: =Hypothèses!C76 -> 50 | D23: =Hypothèses!D76 -> 50 | E23: =Hypothèses!E76 -> 60 | F23: =Hypothèses!F76 -> 60
A24: Réserves (résultats accumulés) | B24: 15 | C24: =B24+P_L!B20*(1-Hypothèses!B81) -> 12.9322 | D24: =C24+P_L!C20*(1-Hypothèses!C81) -> 26.862747 | E24: =D24+P_L!D20*(1-Hypothèses!D81) -> 41.706821 | F24: =E24+P_L!E20*(1-Hypothèses!E81) -> 57.861025
A25: Résultat de l'exercice | B25: =P_L!B20 -> -2.954 | C25: =P_L!C20 -> 23.217579 | D25: =P_L!D20 -> 26.989224 | E25: =P_L!E20 -> 32.308409 | F25: =P_L!F20 -> 36.439923
A26: Total capitaux propres | B26: =B23+B24+B25 -> 62.046 | C26: =C23+C24+C25 -> 86.149779 | D26: =D23+D24+D25 -> 103.85197 | E26: =E23+E24+E25 -> 134.01523 | F26: =F23+F24+F25 -> 154.30095
A27: TOTAL PASSIF | B27: =B20+B21+B22+B26 -> 487.046 | C27: =C20+C21+C22+C26 -> 565.34978 | D27: =D20+D21+D22+D26 -> 642.25197 | E27: =E20+E21+E22+E26 -> 740.61523 | F27: =F20+F21+F22+F26 -> 836.10095
A29: CONTRÔLE ÉQUILIBRE
A30: Écart actif - passif (doit être ~ 0) | B30: =B13-B27 -> 27.64875 | C30: =C13-C27 -> 29.166441 | D30: =D13-D27 -> 40.752533 | E30: =E13-E27 -> 38.453395 | F30: =F13-F27 -> 46.601709

Sheet Ratios prudentiels
A1: RATIOS PRUDENTIELS — BÂLE III
B3: Y1 (2026) | C3: Y2 (2027) | D3: Y3 (2028) | E3: Y4 (2029) | F3: Y5 (2030)
A4: 1. ACTIFS PONDÉRÉS DES RISQUES (RWA)
A5: RWA crédits particuliers | B5: =Hypothèses!B22*Hypothèses!B77 -> 63.75 | C5: =Hypothèses!C22*Hypothèses!C77 -> 76.5 | D5: =Hypothèses!D22*Hypothèses!D77 -> 91.5 | E5: =Hypothèses!E22*Hypothèses!E77 -> 108 | F5: =Hypothèses!F22*Hypothèses!F77 -> 126
A6: RWA crédits PME | B6: =Hypothèses!B23*Hypothèses!B78 -> 120 | C6: =Hypothèses!C23*Hypothèses!C78 -> 144 | D6: =Hypothèses!D23*Hypothèses!D78 -> 170 | E6: =Hypothèses!E23*Hypothèses!E78 -> 198 | F6: =Hypothèses!F23*Hypothèses!F78 -> 228
A7: RWA crédits corporates | B7: =Hypothèses!B24*Hypothèses!B79 -> 180 | C7: =Hypothèses!C24*Hypothèses!C79 -> 198 | D7: =Hypothèses!D24*Hypothèses!D79 -> 217 | E7: =Hypothèses!E24*Hypothèses!E79 -> 238 | F7: =Hypothèses!F24*Hypothèses!F79 -> 261
A8: RWA autres actifs | B8: =(Bilan!B13-Crédits!B9)*Hypothèses!B80 -> 31.408425 | C8: =(Bilan!C13-Crédits!C9)*Hypothèses!C80 -> 36.154866 | D8: =(Bilan!D13-Crédits!D9)*Hypothèses!D80 -> 41.401351 | E8: =(Bilan!E13-Crédits!E9)*Hypothèses!E80 -> 47.120587 | F8: =(Bilan!F13-Crédits!F9)*Hypothèses!F80 -> 53.310797
A9: Total RWA | B9: =SUM(B5:B8) -> 395.15843 | C9: =SUM(C5:C8) -> 454.65487 | D9: =SUM(D5:D8) -> 519.90135 | E9: =SUM(E5:E8) -> 591.12059 | F9: =SUM(F5:F8) -> 668.3108
A11: 2. FONDS PROPRES RÉGLEMENTAIRES
A12: Capitaux propres (CET1) | B12: =Bilan!B26 -> 62.046 | C12: =Bilan!C26 -> 86.149779 | D12: =Bilan!D26 -> 103.85197 | E12: =Bilan!E26 -> 134.01523 | F12: =Bilan!F26 -> 154.30095
A13: Fonds propres totaux | B13: =B12 -> 62.046 | C13: =C12 -> 86.149779 | D13: =D12 -> 103.85197 | E13: =E12 -> 134.01523 | F13: =F12 -> 154.30095
A15: 3. RATIOS DE SOLVABILITÉ
A16: Ratio CET1 | B16: =IFERROR(B12/B9,0) -> 0.15701551 | C16: =IFERROR(C12/C9,0) -> 0.1894839 | D16: =IFERROR(D12/D9,0) -> 0.19975323 | E16: =IFERROR(E12/E9,0) -> 0.22671386 | F16: =IFERROR(F12/F9,0) -> 0.23088202
A17: Seuil minimum CET1 | B17: 0.085 | C17: 0.085 | D17: 0.085 | E17: 0.085 | F17: 0.085
A18: Ratio de solvabilité globale (CAR) | B18: =IFERROR(B13/B9,0) -> 0.15701551 | C18: =IFERROR(C13/C9,0) -> 0.1894839 | D18: =IFERROR(D13/D9,0) -> 0.19975323 | E18: =IFERROR(E13/E9,0) -> 0.22671386 | F18: =IFERROR(F13/F9,0) -> 0.23088202
A19: Seuil minimum CAR (UEMOA) | B19: 0.115 | C19: 0.115 | D19: 0.115 | E19: 0.115 | F19: 0.115
A21: 4. RATIO DE LEVIER
A22: Ratio de levier (FP/Actif total) | B22: =IFERROR(B12/Bilan!B13,0) -> 0.12054912 | C22: =IFERROR(C12/Bilan!C13,0) -> 0.14490737 | D22: =IFERROR(D12/Bilan!D13,0) -> 0.15205166 | E22: =IFERROR(E12/Bilan!E13,0) -> 0.1720198 | F22: =IFERROR(F12/Bilan!F13,0) -> 0.17480512
A23: Seuil minimum levier | B23: 0.03 | C23: 0.03 | D23: 0.03 | E23: 0.03 | F23: 0.03
A25: 5. RATIOS DE LIQUIDITÉ
A26: LCR (HQLA/Sorties nettes 30j) | B26: =IFERROR((Bilan!B5+Bilan!B7*0.8)/(Bilan!B16*0.25+Bilan!B18*0.1),0) -> 1.0392857 | C26: =IFERROR((Bilan!C5+Bilan!C7*0.8)/(Bilan!C16*0.25+Bilan!C18*0.1),0) -> 1.0512901 | D26: =IFERROR((Bilan!D5+Bilan!D7*0.8)/(Bilan!D16*0.25+Bilan!D18*0.1),0) -> 1.0603567 | E26: =IFERROR((Bilan!E5+Bilan!E7*0.8)/(Bilan!E16*0.25+Bilan!E18*0.1),0) -> 1.0617788 | F26: =IFERROR((Bilan!F5+Bilan!F7*0.8)/(Bilan!F16*0.25+Bilan!F18*0.1),0) -> 1.0591341
A27: NSFR (ressources stables/besoins stables) | B27: =IFERROR((Bilan!B16*0.5+Bilan!B18*0.95+Bilan!B26)/(Bilan!B10*0.65),0) -> 1.0078944 | C27: =IFERROR((Bilan!C16*0.5+Bilan!C18*0.95+Bilan!C26)/(Bilan!C10*0.65),0) -> 1.0362641 | D27: =IFERROR((Bilan!D16*0.5+Bilan!D18*0.95+Bilan!D26)/(Bilan!D10*0.65),0) -> 1.0306911 | E27: =IFERROR((Bilan!E16*0.5+Bilan!E18*0.95+Bilan!E26)/(Bilan!E10*0.65),0) -> 1.0569538 | F27: =IFERROR((Bilan!F16*0.5+Bilan!F18*0.95+Bilan!F26)/(Bilan!F10*0.65),0) -> 1.0541144
A28: Ratio crédits/dépôts | B28: =IFERROR(Bilan!B10/Bilan!B20,0) -> 0.95510915 | C28: =IFERROR(Bilan!C10/Bilan!C20,0) -> 0.98187494 | D28: =IFERROR(Bilan!D10/Bilan!D20,0) -> 1.0070414 | E28: =IFERROR(Bilan!E10/Bilan!E20,0) -> 1.0217925 | F28: =IFERROR(Bilan!F10/Bilan!F20,0) -> 1.0318429

Sheet KPIs
A1: TABLEAU DE BORD — INDICATEURS CLÉS
B3: Y1 (2026) | C3: Y2 (2027) | D3: Y3 (2028) | E3: Y4 (2029) | F3: Y5 (2030)
A4: 1. PERFORMANCE FINANCIÈRE
A5: PNB (Md FCFA) | B5: =P_L!B5 -> 30.02625 | C5: =P_L!C5 -> 51.2205 | D5: =P_L!D5 -> 58.13875 | E5: =P_L!E5 -> 67.21675 | F5: =P_L!F5 -> 74.672
A6: RBE (Md FCFA) | B6: =P_L!B11 -> 15.45125 | C6: =P_L!C11 -> 35.1365 | D6: =P_L!D11 -> 40.52775 | E6: =P_L!E11 -> 48.06075 | F6: =P_L!F11 -> 53.853
A7: Résultat net (Md FCFA) | B7: =P_L!B20 -> -2.954 | C7: =P_L!C20 -> 23.217579 | D7: =P_L!D20 -> 26.989224 | E7: =P_L!E20 -> 32.308409 | F7: =P_L!F20 -> 36.439923
A8: Croissance PNB (%) | B8: - | C8: =IFERROR(P_L!C5/P_L!B5-1,0) -> 0.70585737 | D8: =IFERROR(P_L!D5/P_L!C5-1,0) -> 0.13506799 | E8: =IFERROR(P_L!E5/P_L!D5-1,0) -> 0.15614371 | F8: =IFERROR(P_L!F5/P_L!E5-1,0) -> 0.11091357
A9: Croissance RN (%) | B9: - | C9: =IFERROR(P_L!C20/P_L!B20-1,0) -> -8.8597085 | D9: =IFERROR(P_L!D20/P_L!C20-1,0) -> 0.16244784 | E9: =IFERROR(P_L!E20/P_L!D20-1,0) -> 0.19708549 | F9: =IFERROR(P_L!F20/P_L!E20-1,0) -> 0.12787735
A11: 2. RENTABILITÉ
A12: ROE (RN / FP moyens) | B12: =IFERROR(P_L!B20/Bilan!B26,0) -> -0.047609838 | C12: =IFERROR(P_L!C20/((Bilan!B26+Bilan!C26)/2),0) -> 0.31333658 | D12: =IFERROR(P_L!D20/((Bilan!C26+Bilan!D26)/2),0) -> 0.28409448 | E12: =IFERROR(P_L!E20/((Bilan!D26+Bilan!E26)/2),0) -> 0.27165081 | F12: =IFERROR(P_L!F20/((Bilan!E26+Bilan!F26)/2),0) -> 0.25277751
A13: ROA (RN / Actif moyen) | B13: =IFERROR(P_L!B20/Bilan!B13,0) -> -0.0057393241 | C13: =IFERROR(P_L!C20/((Bilan!B13+Bilan!C13)/2),0) -> 0.041863234 | D13: =IFERROR(P_L!D20/((Bilan!C13+Bilan!D13)/2),0) -> 0.042252504 | E13: =IFERROR(P_L!E20/((Bilan!D13+Bilan!E13)/2),0) -> 0.044195339 | F13: =IFERROR(P_L!F20/((Bilan!E13+Bilan!F13)/2),0) -> 0.043856725
A14: NIM (MNI / Encours crédits) | B14: =IFERROR(PNB!B7/Crédits!B9,0) -> 0.03957622 | C14: =IFERROR(PNB!C7/Crédits!C9,0) -> 0.074726793 | D14: =IFERROR(PNB!D7/Crédits!D9,0) -> 0.073465596 | E14: =IFERROR(PNB!E7/Crédits!E9,0) -> 0.075107315 | F14: =IFERROR(PNB!F7/Crédits!F9,0) -> 0.073151773
A16: 3. EFFICACITÉ
A17: Coefficient d'exploitation | B17: =IFERROR(Charges!B19/PNB!B18,0) -> 0.4854086 | C17: =IFERROR(Charges!C19/PNB!C18,0) -> 0.3140149 | D17: =IFERROR(Charges!D19/PNB!D18,0) -> 0.30291329 | E17: =IFERROR(Charges!E19/PNB!E18,0) -> 0.28498849 | F17: =IFERROR(Charges!F19/PNB!F18,0) -> 0.27880598
A18: PNB par ETP (M FCFA) | B18: =IFERROR(PNB!B18*1000/Hypothèses!B18,0) -> 85.789286 | C18: =IFERROR(PNB!C18*1000/Hypothèses!C18,0) -> 134.79079 | D18: =IFERROR(PNB!D18*1000/Hypothèses!D18,0) -> 141.80183 | E18: =IFERROR(PNB!E18*1000/Hypothèses!E18,0) -> 152.76534 | F18: =IFERROR(PNB!F18*1000/Hypothèses!F18,0) -> 158.8766
A19: PNB par agence (Md FCFA) | B19: =IFERROR(PNB!B18/Hypothèses!B13,0) -> 1.20105 | C19: =IFERROR(PNB!C18/Hypothèses!C13,0) -> 1.8293036 | D19: =IFERROR(PNB!D18/Hypothèses!D13,0) -> 1.8168359 | E19: =IFERROR(PNB!E18/Hypothèses!E13,0) -> 1.9204786 | F19: =IFERROR(PNB!F18/Hypothèses!F13,0) -> 1.9650526
A21: 4. RISQUE
A22: Taux de NPL | B22: =IFERROR('Coût risque'!B8/Crédits!B9,0) -> 0.070731707 | C22: =IFERROR('Coût risque'!C8/Crédits!C9,0) -> 0.066835443 | D22: =IFERROR('Coût risque'!D8/Crédits!D9,0) -> 0.062788991 | E22: =IFERROR('Coût risque'!E8/Crédits!E9,0) -> 0.058681672 | F22: =IFERROR('Coût risque'!F8/Crédits!F9,0) -> 0.054510638
A23: Taux de couverture (Prov/NPL) | B23: =IFERROR('Coût risque'!B21/'Coût risque'!B8,0) -> 0.63466379 | C23: =IFERROR('Coût risque'!C21/'Coût risque'!C8,0) -> 0.64311174 | D23: =IFERROR('Coût risque'!D21/'Coût risque'!D8,0) -> 0.65299518 | E23: =IFERROR('Coût risque'!E21/'Coût risque'!E8,0) -> 0.66442123 | F23: =IFERROR('Coût risque'!F21/'Coût risque'!F8,0) -> 0.67778669
A24: Coût risque / encours (bps) | B24: =IFERROR('Coût risque'!B24/Crédits!B9*10000,0) -> 448.90854 | C24: =IFERROR('Coût risque'!C24/Crédits!C9*10000,0) -> 41.530169 | D24: =IFERROR('Coût risque'!D24/Crédits!D9*10000,0) -> 36.178257 | E24: =IFERROR('Coût risque'!E24/Crédits!E9*10000,0) -> 30.641158 | F24: =IFERROR('Coût risque'!F24/Crédits!F9*10000,0) -> 25.474716
A26: 5. SOLVABILITÉ
A27: Ratio CET1 | B27: ='Ratios prudentiels'!B16 -> 0.15701551 | C27: ='Ratios prudentiels'!C16 -> 0.1894839 | D27: ='Ratios prudentiels'!D16 -> 0.19975323 | E27: ='Ratios prudentiels'!E16 -> 0.22671386 | F27: ='Ratios prudentiels'!F16 -> 0.23088202
A28: Ratio CAR | B28: ='Ratios prudentiels'!B18 -> 0.15701551 | C28: ='Ratios prudentiels'!C18 -> 0.1894839 | D28: ='Ratios prudentiels'!D18 -> 0.19975323 | E28: ='Ratios prudentiels'!E18 -> 0.22671386 | F28: ='Ratios prudentiels'!F18 -> 0.23088202
A30: 6. CROISSANCE ACTIVITÉ
A31: Croissance encours crédits | B31: - | C31: =IFERROR(Crédits!C9/Crédits!B9-1,0) -> 0.15609756 | D31: =IFERROR(Crédits!D9/Crédits!C9-1,0) -> 0.14978903 | E31: =IFERROR(Crédits!E9/Crédits!D9-1,0) -> 0.1412844 | F31: =IFERROR(Crédits!F9/Crédits!E9-1,0) -> 0.13344051
A32: Croissance dépôts | B32: - | C32: =IFERROR(Dépôts!C9/Dépôts!B9-1,0) -> 0.12682927 | D32: =IFERROR(Dépôts!D9/Dépôts!C9-1,0) -> 0.12337662 | E32: =IFERROR(Dépôts!E9/Dépôts!D9-1,0) -> 0.12716763 | F32: =IFERROR(Dépôts!F9/Dépôts!E9-1,0) -> 0.12478632

Sheet Stress tests
A1: STRESS TESTS PRUDENTIELS
B3: Y1 (2026) | C3: Y2 (2027) | D3: Y3 (2028) | E3: Y4 (2029) | F3: Y5 (2030)
A4: RÉFÉRENCE — SCÉNARIO DE BASE
A5: PNB de base (Md FCFA) | B5: =P_L!B5 -> 30.02625 | C5: =P_L!C5 -> 51.2205 | D5: =P_L!D5 -> 58.13875 | E5: =P_L!E5 -> 67.21675 | F5: =P_L!F5 -> 74.672
A6: Résultat net de base (Md FCFA) | B6: =P_L!B20 -> -2.954 | C6: =P_L!C20 -> 23.217579 | D6: =P_L!D20 -> 26.989224 | E6: =P_L!E20 -> 32.308409 | F6: =P_L!F20 -> 36.439923
A7: CET1 de base | B7: ='Ratios prudentiels'!B16 -> 0.15701551 | C7: ='Ratios prudentiels'!C16 -> 0.1894839 | D7: ='Ratios prudentiels'!D16 -> 0.19975323 | E7: ='Ratios prudentiels'!E16 -> 0.22671386 | F7: ='Ratios prudentiels'!F16 -> 0.23088202
A9: STRESS 1 — RÉCESSION (PNB -15%, coût risque +50%)
A10: PNB stressé | B10: =B5*0.85 -> 25.522313 | C10: =C5*0.85 -> 43.537425 | D10: =D5*0.85 -> 49.417938 | E10: =E5*0.85 -> 57.134237 | F10: =F5*0.85 -> 63.4712
A11: Coût risque stressé | B11: ='Coût risque'!B24*1.5 -> 27.607875 | C11: ='Coût risque'!C24*1.5 -> 2.952795 | D11: ='Coût risque'!D24*1.5 -> 2.9575725 | E11: ='Coût risque'!E24*1.5 -> 2.85882 | F11: ='Coût risque'!F24*1.5 -> 2.6939513
A12: Résultat net stressé | B12: =(B10-Charges!B19-B11)*(1-Hypothèses!B8) -> -11.662394 | C12: =(C10-Charges!C19-C11)*(1-Hypothèses!C8) -> 17.150441 | D12: =(D10-Charges!D19-D11)*(1-Hypothèses!D8) -> 20.194555 | E12: =(E10-Charges!E19-E11)*(1-Hypothèses!E8) -> 24.583592 | F12: =(F10-Charges!F19-F11)*(1-Hypothèses!F8) -> 27.970774
A13: Variation RN vs base (%) | B13: =IFERROR(B12/B6-1,0) -> 2.9480006 | C13: =IFERROR(C12/C6-1,0) -> -0.26131657 | D13: =IFERROR(D12/D6-1,0) -> -0.25175488 | E13: =IFERROR(E12/E6-1,0) -> -0.23909617 | F13: =IFERROR(F12/F6-1,0) -> -0.23241401
A15: STRESS 2 — CHOC LIQUIDITÉ (fuite 20% DAV)
A16: DAV stressés (-20%) | B16: =Bilan!B16*0.8 -> 144 | C16: =Bilan!C16*0.8 -> 165.6 | D16: =Bilan!D16*0.8 -> 190.4 | E16: =Bilan!E16*0.8 -> 219.2 | F16: =Bilan!F16*0.8 -> 251.2
A17: Besoin liquidité supplémentaire | B17: =Bilan!B16*0.2 -> 36 | C17: =Bilan!C16*0.2 -> 41.4 | D17: =Bilan!D16*0.2 -> 47.6 | E17: =Bilan!E16*0.2 -> 54.8 | F17: =Bilan!F16*0.2 -> 62.8
A18: LCR stressé | B18: =IFERROR((Bilan!B5+Bilan!B7*0.8)/(Bilan!B16*0.45+Bilan!B18*0.1),0) -> 0.6326087 | C18: =IFERROR((Bilan!C5+Bilan!C7*0.8)/(Bilan!C16*0.45+Bilan!C18*0.1),0) -> 0.63815852 | D18: =IFERROR((Bilan!D5+Bilan!D7*0.8)/(Bilan!D16*0.45+Bilan!D18*0.1),0) -> 0.64149378 | E18: =IFERROR((Bilan!E5+Bilan!E7*0.8)/(Bilan!E16*0.45+Bilan!E18*0.1),0) -> 0.64014493 | F18: =IFERROR((Bilan!F5+Bilan!F7*0.8)/(Bilan!F16*0.45+Bilan!F18*0.1),0) -> 0.6368254
A20: STRESS 3 — HAUSSE TAUX (+200 bps non répercutée)
A21: Charge supplémentaire (+2% sur DAT) | B21: =Dépôts!B14*0.02 -> 1.1 | C21: =Dépôts!C14*0.02 -> 2.32 | D21: =Dépôts!D14*0.02 -> 2.56 | E21: =Dépôts!E14*0.02 -> 2.81 | F21: =Dépôts!F14*0.02 -> 3.09
A22: MNI stressée | B22: =PNB!B7-B21 -> 15.12625 | C22: =PNB!C7-C21 -> 33.1005 | D22: =PNB!D7-D21 -> 37.47875 | E22: =PNB!E7-E21 -> 43.90675 | F22: =PNB!F7-F21 -> 48.482
A23: PNB stressé | B23: =B22+PNB!B15 -> 28.92625 | C23: =C22+PNB!C15 -> 48.9005 | D23: =D22+PNB!D15 -> 55.57875 | E23: =E22+PNB!E15 -> 64.40675 | F23: =F22+PNB!F15 -> 71.582
A24: Variation PNB vs base (%) | B24: =IFERROR(B23/B5-1,0) -> -0.036634611 | C24: =IFERROR(C23/C5-1,0) -> -0.045294365 | D24: =IFERROR(D23/D5-1,0) -> -0.044032594 | E24: =IFERROR(E23/E5-1,0) -> -0.041805056 | F24: =IFERROR(F23/F5-1,0) -> -0.041380973

Sheet TFT
A1: TABLEAU DES FLUX DE TRÉSORERIE
B3: Y1 (2026) | C3: Y2 (2027) | D3: Y3 (2028) | E3: Y4 (2029) | F3: Y5 (2030)
A4: FLUX DES ACTIVITÉS D'EXPLOITATION
A5: Résultat net | B5: =P_L!B20 -> -2.954 | C5: =P_L!C20 -> 23.217579 | D5: =P_L!D20 -> 26.989224 | E5: =P_L!E20 -> 32.308409 | F5: =P_L!F20 -> 36.439923
A6: + Dotations aux provisions | B6: ='Coût risque'!B24 -> 18.40525 | C6: ='Coût risque'!C24 -> 1.96853 | D6: ='Coût risque'!D24 -> 1.971715 | E6: ='Coût risque'!E24 -> 1.90588 | F6: ='Coût risque'!F24 -> 1.7959675
A7: - Variation crédits clientèle | B7: =-Crédits!B9 -> -410 | C7: =-(Crédits!C9-Crédits!B9) -> -64 | D7: =-(Crédits!D9-Crédits!C9) -> -71 | E7: =-(Crédits!E9-Crédits!D9) -> -77 | F7: =-(Crédits!F9-Crédits!E9) -> -83
A8: + Variation dépôts clientèle | B8: =Dépôts!B9 -> 410 | C8: =Dépôts!C9-Dépôts!B9 -> 52 | D8: =Dépôts!D9-Dépôts!C9 -> 57 | E8: =Dépôts!E9-Dépôts!D9 -> 66 | F8: =Dépôts!F9-Dépôts!E9 -> 73
A9: Flux net exploitation | B9: =SUM(B5:B8) -> 15.45125 | C9: =SUM(C5:C8) -> 13.186109 | D9: =SUM(D5:D8) -> 14.96094 | E9: =SUM(E5:E8) -> 23.214289 | F9: =SUM(F5:F8) -> 28.23589
A11: FLUX D'INVESTISSEMENT
A12: Investissements (CAPEX) | B12: -3.5 | C12: -4 | D12: -4.5 | E12: -5 | F12: -5.5
A13: Variation portefeuille titres | B13: =-Bilan!B7 -> -61.5 | C13: =-(Bilan!C7-Bilan!B7) -> -9.6 | D13: =-(Bilan!D7-Bilan!C7) -> -10.65 | E13: =-(Bilan!E7-Bilan!D7) -> -11.55 | F13: =-(Bilan!F7-Bilan!E7) -> -12.45
A14: Flux net investissement | B14: =SUM(B12:B13) -> -65 | C14: =SUM(C12:C13) -> -13.6 | D14: =SUM(D12:D13) -> -15.15 | E14: =SUM(E12:E13) -> -16.55 | F14: =SUM(F12:F13) -> -17.95
A16: FLUX DE FINANCEMENT
A17: Variation capital social | B17: =Bilan!B23 -> 50 | C17: =Bilan!C23-Bilan!B23 -> 0 | D17: =Bilan!D23-Bilan!C23 -> 0 | E17: =Bilan!E23-Bilan!D23 -> 10 | F17: =Bilan!F23-Bilan!E23 -> 0
A18: Dividendes versés | B18: 0 | C18: =-P_L!B20*Hypothèses!B81 -> 0.8862 | D18: =-P_L!C20*Hypothèses!C81 -> -9.2870316 | E18: =-P_L!D20*Hypothèses!D81 -> -12.145151 | F18: =-P_L!E20*Hypothèses!E81 -> -16.154204
A19: Flux net financement | B19: =SUM(B17:B18) -> 50 | C19: =SUM(C17:C18) -> 0.8862 | D19: =SUM(D17:D18) -> -9.2870316 | E19: =SUM(E17:E18) -> -2.145151 | F19: =SUM(F17:F18) -> -16.154204
A21: VARIATION DE TRÉSORERIE
A22: Variation totale de trésorerie | B22: =B9+B14+B19 -> 0.45125 | C22: =C9+C14+C19 -> 0.472309 | D22: =D9+D14+D19 -> -9.4760921 | E22: =E9+E14+E19 -> 4.519138 | F22: =F9+F14+F19 -> -5.8683142

Sheet Scénarios
A1: VUE COMPARÉE — SCÉNARIOS PESSIMISTE / BASE / OPTIMISTE
A3: Note : Vue synthétique. Les scénarios pessimiste et optimiste sont des sensibilités appliquées au scénario de base (Y5).
A5: KPI | B5: Pessimiste (Y5) | C5: Base (Y5) | D5: Optimiste (Y5) | F5: Sensibilité
A6: PNB Y5 (Md FCFA) | B6: =P_L!F5*0.85 -> 63.4712 | C6: =P_L!F5 -> 74.672 | D6: =P_L!F5*1.15 -> 85.8728 | F6: ±15%
A7: Résultat net Y5 (Md FCFA) | B7: =P_L!F20*0.6 -> 21.863954 | C7: =P_L!F20 -> 36.439923 | D7: =P_L!F20*1.3 -> 47.3719 | F7: ±30-40%
A8: ROE Y5 | B8: =KPIs!F12*0.6 -> 0.15166651 | C8: =KPIs!F12 -> 0.25277751 | D8: =KPIs!F12*1.3 -> 0.32861076 | F8: ±40%
A9: CET1 Y5 | B9: ='Ratios prudentiels'!F16*0.85 -> 0.19624972 | C9: ='Ratios prudentiels'!F16 -> 0.23088202 | D9: ='Ratios prudentiels'!F16*1.1 -> 0.25397022 | F9: ±10-15%
A10: Coût risque Y5 (Md FCFA) | B10: ='Coût risque'!F24*1.5 -> 2.6939513 | C10: ='Coût risque'!F24 -> 1.7959675 | D10: ='Coût risque'!F24*0.7 -> 1.2571773 | F10: ±30-50%
A13: MÉTHODOLOGIE DES SENSIBILITÉS
A14: Pessimiste : récession en zone, PNB -15%, coût risque +50%, croissance des dépôts ralentie, marges sous pression.
A15: Optimiste : croissance économique soutenue, PNB +15%, coût risque -30%, gains de productivité IT, expansion réseau accélérée.
