Workbook

Sheet Notice
A1: MODÈLE FINANCIER — INDUSTRIE & MANUFACTURE
B3: H&C Group — Référence multisectorielle
B4: Conformité : SYSCOHADA + IAS 2 (stocks)
A6: 1. OBJET DU MODÈLE
B7: Objet | C7: Plan d'affaires sur 5 ans d'une entreprise industrielle (agro-alimentaire, transformation, manufacture). Modèle de référence H&C Group.
B8: Périmètre | C8: Catalogue produits & nomenclatures, plan de production & OEE, achats matières premières, stocks multi-niveaux, coûts directs, P&L, bilan, trésorerie.
B9: Hypothèses clés | C9: Capacité de production, OEE, BOM, prix MP, productivité MOD, énergie, CAPEX industriel, prix de vente.
A11: 2. STRUCTURE DU MODÈLE
B12: Hypothèses | C12: Macro, fiscalité, catalogue, capacité, coûts
B13: Catalogue | C13: Produits, prix de vente, BOM
B14: Production | C14: Plan production, capacité, OEE, taux d'utilisation
B15: Achats MP | C15: Volumes, prix, stock MP
B16: Stocks | C16: MP, en-cours, produits finis
B17: Coûts directs | C17: MP, MOD, énergie, frais généraux usine
B18: Coûts standards | C18: Écarts prix MP, quantité MP, productivité MOD
B19: CAPEX | C19: Investissements industriels, amortissements
B20: Charges fixes | C20: RH structure, loyers, autres charges
B21: P_L | C21: Compte de résultat
B22: Bilan | C22: Actif / passif
B23: Trésorerie & KPIs | C23: BFR, FCF, OEE, marges
A25: 3. CODE COULEUR
B26: Bleu (input) | C26: Cellule saisie manuellement
B27: Noir (formule) | C27: Cellule calculée
B28: Vert (lien) | C28: Lien vers autre feuille
B29: Fond jaune | C29: Hypothèse clé
B30: Bandeau navy | C30: Titre
B31: Bandeau or | C31: Sous-titre

Sheet Hypothèses
A1: HYPOTHÈSES — INDUSTRIE
B3: Y1 (2026) | C3: Y2 (2027) | D3: Y3 (2028) | E3: Y4 (2029) | F3: Y5 (2030)
A4: 1. MACRO & FISCALITÉ
A5: Inflation (%) | B5: 0.03 | C5: 0.025 | D5: 0.025 | E5: 0.025 | F5: 0.025 | H5: Zone CFA
A6: Taux IS (%) | B6: 0.28 | C6: 0.28 | D6: 0.28 | E6: 0.28 | F6: 0.28 | H6: Avec abattements
A7: TVA (%) | B7: 0.18 | C7: 0.18 | D7: 0.18 | E7: 0.18 | F7: 0.18 | H7: Récupérable
A8: Charges patronales (%) | B8: 0.18 | C8: 0.18 | D8: 0.18 | E8: 0.18 | F8: 0.18
A9: Prix USD/FCFA | B9: 600 | C9: 605 | D9: 610 | E9: 610 | F9: 610 | H9: MP importées
A11: 2. CATALOGUE PRODUITS & PRIX
A12: Produit A — Volume vente (kT) | B12: 12 | C12: 14 | D12: 16.5 | E12: 19 | F12: 22 | H12: Famille principale
A13: Produit B — Volume vente (kT) | B13: 8 | C13: 9 | D13: 10 | E13: 11 | F13: 12.5
A14: Produit C — Volume vente (kT) | B14: 5 | C14: 5.5 | D14: 6 | E14: 6.5 | F14: 7
A15: Prix de vente Produit A (k FCFA/T) | B15: 850 | C15: 870 | D15: 890 | E15: 910 | F15: 930
A16: Prix de vente Produit B (k FCFA/T) | B16: 1100 | C16: 1130 | D16: 1160 | E16: 1190 | F16: 1220
A17: Prix de vente Produit C (k FCFA/T) | B17: 1500 | C17: 1540 | D17: 1580 | E17: 1620 | F17: 1660
A19: 3. CAPACITÉ DE PRODUCTION
A20: Capacité théorique (kT/an) | B20: 35 | C20: 35 | D20: 40 | E20: 45 | F20: 50 | H20: Limite physique
A21: OEE — Overall Equipment Effectiveness (%) | B21: 0.65 | C21: 0.68 | D21: 0.72 | E21: 0.75 | F21: 0.78 | H21: Cible évolutive
A22: Taux de rebut/casse (%) | B22: 0.03 | C22: 0.025 | D22: 0.022 | E22: 0.02 | F22: 0.018 | H22: Qualité progressive
A24: 4. BOM — COÛTS UNITAIRES (par tonne)
A25: MP par tonne Produit A (k FCFA) | B25: 350 | C25: 360 | D25: 370 | E25: 380 | F25: 390
A26: MP par tonne Produit B (k FCFA) | B26: 450 | C26: 465 | D26: 480 | E26: 495 | F26: 510
A27: MP par tonne Produit C (k FCFA) | B27: 620 | C27: 640 | D27: 660 | E27: 680 | F27: 700
A28: MOD par tonne (k FCFA, moyenne) | B28: 85 | C28: 87 | D28: 89 | E28: 91 | F28: 93
A29: Énergie par tonne (k FCFA) | B29: 45 | C29: 47 | D29: 48 | E29: 50 | F29: 52
A30: Consommables/emballages par tonne (k FCFA) | B30: 25 | C30: 26 | D30: 27 | E30: 28 | F30: 29
A32: 5. CYCLE D'EXPLOITATION (jours)
A33: Rotation MP (jours) | B33: 45 | C33: 40 | D33: 38 | E33: 35 | F33: 35 | H33: DPO MP
A34: Rotation en-cours (jours) | B34: 10 | C34: 10 | D34: 9 | E34: 8 | F34: 8
A35: Rotation produits finis (jours) | B35: 30 | C35: 28 | D35: 25 | E35: 23 | F35: 22
A36: DSO clients (jours) | B36: 60 | C36: 55 | D36: 50 | E36: 48 | F36: 45 | H36: B2B principalement
A37: DPO fournisseurs MP (jours) | B37: 45 | C37: 45 | D37: 45 | E37: 45 | F37: 45
A39: 6. RH & SALAIRES
A40: Effectifs MOD directe | B40: 85 | C40: 92 | D40: 100 | E40: 108 | F40: 115 | H40: Production
A41: Effectifs encadrement | B41: 25 | C41: 28 | D41: 30 | E41: 32 | F41: 35
A42: Effectifs support (admin, vente, R&D) | B42: 40 | C42: 42 | D42: 45 | E42: 48 | F42: 50
A43: Salaire chargé moyen MOD (M FCFA/an) | B43: 2.5 | C43: 2.6 | D43: 2.7 | E43: 2.8 | F43: 2.9
A44: Salaire chargé moyen encadrement (M FCFA/an) | B44: 5.5 | C44: 5.7 | D44: 5.9 | E44: 6.1 | F44: 6.3
A45: Salaire chargé moyen support (M FCFA/an) | B45: 4 | C45: 4.2 | D45: 4.4 | E45: 4.6 | F45: 4.8
A47: 7. CHARGES FIXES
...

Sheet Catalogue
A1: CATALOGUE — VOLUMES, PRIX & CHIFFRE D'AFFAIRES
B3: Y1 (2026) | C3: Y2 (2027) | D3: Y3 (2028) | E3: Y4 (2029) | F3: Y5 (2030)
A4: VOLUMES DE VENTE (kT)
A5: Produit A | B5: =Hypothèses!B12 -> 12 | C5: =Hypothèses!C12 -> 14 | D5: =Hypothèses!D12 -> 16.5 | E5: =Hypothèses!E12 -> 19 | F5: =Hypothèses!F12 -> 22
A6: Produit B | B6: =Hypothèses!B13 -> 8 | C6: =Hypothèses!C13 -> 9 | D6: =Hypothèses!D13 -> 10 | E6: =Hypothèses!E13 -> 11 | F6: =Hypothèses!F13 -> 12.5
A7: Produit C | B7: =Hypothèses!B14 -> 5 | C7: =Hypothèses!C14 -> 5.5 | D7: =Hypothèses!D14 -> 6 | E7: =Hypothèses!E14 -> 6.5 | F7: =Hypothèses!F14 -> 7
A8: Volume total vente (kT) | B8: =B5+B6+B7 -> 25 | C8: =C5+C6+C7 -> 28.5 | D8: =D5+D6+D7 -> 32.5 | E8: =E5+E6+E7 -> 36.5 | F8: =F5+F6+F7 -> 41.5
A10: PRIX DE VENTE (k FCFA / T)
A11: Produit A | B11: =Hypothèses!B15 -> 850 | C11: =Hypothèses!C15 -> 870 | D11: =Hypothèses!D15 -> 890 | E11: =Hypothèses!E15 -> 910 | F11: =Hypothèses!F15 -> 930
A12: Produit B | B12: =Hypothèses!B16 -> 1100 | C12: =Hypothèses!C16 -> 1130 | D12: =Hypothèses!D16 -> 1160 | E12: =Hypothèses!E16 -> 1190 | F12: =Hypothèses!F16 -> 1220
A13: Produit C | B13: =Hypothèses!B17 -> 1500 | C13: =Hypothèses!C17 -> 1540 | D13: =Hypothèses!D17 -> 1580 | E13: =Hypothèses!E17 -> 1620 | F13: =Hypothèses!F17 -> 1660
A15: CHIFFRE D'AFFAIRES (Md FCFA)
A16: CA Produit A | B16: =B5*B11/1000 -> 10.2 | C16: =C5*C11/1000 -> 12.18 | D16: =D5*D11/1000 -> 14.685 | E16: =E5*E11/1000 -> 17.29 | F16: =F5*F11/1000 -> 20.46
A17: CA Produit B | B17: =B6*B12/1000 -> 8.8 | C17: =C6*C12/1000 -> 10.17 | D17: =D6*D12/1000 -> 11.6 | E17: =E6*E12/1000 -> 13.09 | F17: =F6*F12/1000 -> 15.25
A18: CA Produit C | B18: =B7*B13/1000 -> 7.5 | C18: =C7*C13/1000 -> 8.47 | D18: =D7*D13/1000 -> 9.48 | E18: =E7*E13/1000 -> 10.53 | F18: =F7*F13/1000 -> 11.62
A19: CA TOTAL (Md FCFA) | B19: =B16+B17+B18 -> 26.5 | C19: =C16+C17+C18 -> 30.82 | D19: =D16+D17+D18 -> 35.765 | E19: =E16+E17+E18 -> 40.91 | F19: =F16+F17+F18 -> 47.33
A21: ANALYSE PRIX MOYEN
A22: Prix de vente moyen pondéré (k FCFA/T) | B22: =IFERROR(B19*1000/B8,0) -> 1060 | C22: =IFERROR(C19*1000/C8,0) -> 1081.4035 | D22: =IFERROR(D19*1000/D8,0) -> 1100.4615 | E22: =IFERROR(E19*1000/E8,0) -> 1120.8219 | F22: =IFERROR(F19*1000/F8,0) -> 1140.4819

Sheet Production
A1: PLAN DE PRODUCTION — CAPACITÉ & OEE
B3: Y1 (2026) | C3: Y2 (2027) | D3: Y3 (2028) | E3: Y4 (2029) | F3: Y5 (2030)
A4: CAPACITÉ THÉORIQUE & UTILISATION
A5: Capacité théorique (kT/an) | B5: =Hypothèses!B20 -> 35 | C5: =Hypothèses!C20 -> 35 | D5: =Hypothèses!D20 -> 40 | E5: =Hypothèses!E20 -> 45 | F5: =Hypothèses!F20 -> 50
A6: OEE — Overall Equipment Effectiveness | B6: =Hypothèses!B21 -> 0.65 | C6: =Hypothèses!C21 -> 0.68 | D6: =Hypothèses!D21 -> 0.72 | E6: =Hypothèses!E21 -> 0.75 | F6: =Hypothèses!F21 -> 0.78
A7: Production brute réelle (kT) | B7: =B5*B6 -> 22.75 | C7: =C5*C6 -> 23.8 | D7: =D5*D6 -> 28.8 | E7: =E5*E6 -> 33.75 | F7: =F5*F6 -> 39
A8: Taux de rebut (%) | B8: =Hypothèses!B22 -> 0.03 | C8: =Hypothèses!C22 -> 0.025 | D8: =Hypothèses!D22 -> 0.022 | E8: =Hypothèses!E22 -> 0.02 | F8: =Hypothèses!F22 -> 0.018
A9: Rebuts (kT) | B9: =B7*B8 -> 0.6825 | C9: =C7*C8 -> 0.595 | D9: =D7*D8 -> 0.6336 | E9: =E7*E8 -> 0.675 | F9: =F7*F8 -> 0.702
A10: Production nette (kT) | B10: =B7-B9 -> 22.0675 | C10: =C7-C9 -> 23.205 | D10: =D7-D9 -> 28.1664 | E10: =E7-E9 -> 33.075 | F10: =F7-F9 -> 38.298
A12: DEMANDE COMMERCIALE
A13: Volume total vendu (kT) | B13: =Catalogue!B8 -> 25 | C13: =Catalogue!C8 -> 28.5 | D13: =Catalogue!D8 -> 32.5 | E13: =Catalogue!E8 -> 36.5 | F13: =Catalogue!F8 -> 41.5
A14: Taux d'utilisation effectif (%) | B14: =IFERROR(B13/B5,0) -> 0.71428571 | C14: =IFERROR(C13/C5,0) -> 0.81428571 | D14: =IFERROR(D13/D5,0) -> 0.8125 | E14: =IFERROR(E13/E5,0) -> 0.81111111 | F14: =IFERROR(F13/F5,0) -> 0.83
A15: Marge / surcapacité (kT) | B15: =B10-B13 -> -2.9325 | C15: =C10-C13 -> -5.295 | D15: =D10-D13 -> -4.3336 | E15: =E10-E13 -> -3.425 | F15: =F10-F13 -> -3.202

Sheet Achats MP
A1: ACHATS MATIÈRES PREMIÈRES & CONSOMMATIONS
B3: Y1 (2026) | C3: Y2 (2027) | D3: Y3 (2028) | E3: Y4 (2029) | F3: Y5 (2030)
A4: CONSOMMATIONS DE MATIÈRES PREMIÈRES (Md FCFA)
A5: MP consommée — Produit A | B5: =Hypothèses!B12*Hypothèses!B25/1000 -> 4.2 | C5: =Hypothèses!C12*Hypothèses!C25/1000 -> 5.04 | D5: =Hypothèses!D12*Hypothèses!D25/1000 -> 6.105 | E5: =Hypothèses!E12*Hypothèses!E25/1000 -> 7.22 | F5: =Hypothèses!F12*Hypothèses!F25/1000 -> 8.58
A6: MP consommée — Produit B | B6: =Hypothèses!B13*Hypothèses!B26/1000 -> 3.6 | C6: =Hypothèses!C13*Hypothèses!C26/1000 -> 4.185 | D6: =Hypothèses!D13*Hypothèses!D26/1000 -> 4.8 | E6: =Hypothèses!E13*Hypothèses!E26/1000 -> 5.445 | F6: =Hypothèses!F13*Hypothèses!F26/1000 -> 6.375
A7: MP consommée — Produit C | B7: =Hypothèses!B14*Hypothèses!B27/1000 -> 3.1 | C7: =Hypothèses!C14*Hypothèses!C27/1000 -> 3.52 | D7: =Hypothèses!D14*Hypothèses!D27/1000 -> 3.96 | E7: =Hypothèses!E14*Hypothèses!E27/1000 -> 4.42 | F7: =Hypothèses!F14*Hypothèses!F27/1000 -> 4.9
A8: Total MP consommée (Md FCFA) | B8: =B5+B6+B7 -> 10.9 | C8: =C5+C6+C7 -> 12.745 | D8: =D5+D6+D7 -> 14.865 | E8: =E5+E6+E7 -> 17.085 | F8: =F5+F6+F7 -> 19.855
A10: STOCK MATIÈRES PREMIÈRES (Md FCFA)
A11: Rotation MP (jours) | B11: =Hypothèses!B33 -> 45 | C11: =Hypothèses!C33 -> 40 | D11: =Hypothèses!D33 -> 38 | E11: =Hypothèses!E33 -> 35 | F11: =Hypothèses!F33 -> 35
A12: Stock MP (= conso annuelle * rotation/365) | B12: =B8*Hypothèses!B33/365 -> 1.3438356 | C12: =C8*Hypothèses!C33/365 -> 1.3967123 | D12: =D8*Hypothèses!D33/365 -> 1.547589 | E12: =E8*Hypothèses!E33/365 -> 1.6382877 | F12: =F8*Hypothèses!F33/365 -> 1.9039041
A14: ACHATS MP (= conso + variation stock)
A15: Achats MP de l'exercice | B15: =B8+B12 -> 12.243836 | C15: =C8+C12-B12 -> 12.797877 | D15: =D8+D12-C12 -> 15.015877 | E15: =E8+E12-D12 -> 17.175699 | F15: =F8+F12-E12 -> 20.120616

Sheet Stocks
A1: STOCKS — MP, EN-COURS, PRODUITS FINIS
B3: Y1 (2026) | C3: Y2 (2027) | D3: Y3 (2028) | E3: Y4 (2029) | F3: Y5 (2030)
A4: VALORISATION DES STOCKS (Md FCFA)
A5: Stock MP (fin période) | B5: ='Achats MP'!B12 -> 1.3438356 | C5: ='Achats MP'!C12 -> 1.3967123 | D5: ='Achats MP'!D12 -> 1.547589 | E5: ='Achats MP'!E12 -> 1.6382877 | F5: ='Achats MP'!F12 -> 1.9039041
A6: Stock en-cours (WIP) | B6: ='Achats MP'!B8*Hypothèses!B34/365 -> 0.29863014 | C6: ='Achats MP'!C8*Hypothèses!C34/365 -> 0.34917808 | D6: ='Achats MP'!D8*Hypothèses!D34/365 -> 0.36653425 | E6: ='Achats MP'!E8*Hypothèses!E34/365 -> 0.37446575 | F6: ='Achats MP'!F8*Hypothèses!F34/365 -> 0.43517808
A7: Stock produits finis | B7: =Catalogue!B19*0.7*Hypothèses!B35/365 -> 1.5246575 | C7: =Catalogue!C19*0.7*Hypothèses!C35/365 -> 1.6549918 | D7: =Catalogue!D19*0.7*Hypothèses!D35/365 -> 1.7147603 | E7: =Catalogue!E19*0.7*Hypothèses!E35/365 -> 1.8045233 | F7: =Catalogue!F19*0.7*Hypothèses!F35/365 -> 1.996937
A8: Total stocks | B8: =B5+B6+B7 -> 3.1671233 | C8: =C5+C6+C7 -> 3.4008822 | D8: =D5+D6+D7 -> 3.6288836 | E8: =E5+E6+E7 -> 3.8172767 | F8: =F5+F6+F7 -> 4.3360192
A10: INDICATEURS STOCKS
A11: Stock total / CA (en jours) | B11: =IFERROR(B8*365/Catalogue!B19,0) -> 43.622642 | C11: =IFERROR(C8*365/Catalogue!C19,0) -> 40.276509 | D11: =IFERROR(D8*365/Catalogue!D19,0) -> 37.034601 | E11: =IFERROR(E8*365/Catalogue!E19,0) -> 34.057834 | F11: =IFERROR(F8*365/Catalogue!F19,0) -> 33.438559

Sheet Coûts directs
A1: COÛTS DIRECTS DE PRODUCTION
B3: Y1 (2026) | C3: Y2 (2027) | D3: Y3 (2028) | E3: Y4 (2029) | F3: Y5 (2030)
A4: COÛTS DIRECTS UNITAIRES (par tonne) (k FCFA/T)
A5: MOD par tonne | B5: =Hypothèses!B28 -> 85 | C5: =Hypothèses!C28 -> 87 | D5: =Hypothèses!D28 -> 89 | E5: =Hypothèses!E28 -> 91 | F5: =Hypothèses!F28 -> 93
A6: Énergie par tonne | B6: =Hypothèses!B29 -> 45 | C6: =Hypothèses!C29 -> 47 | D6: =Hypothèses!D29 -> 48 | E6: =Hypothèses!E29 -> 50 | F6: =Hypothèses!F29 -> 52
A7: Consommables par tonne | B7: =Hypothèses!B30 -> 25 | C7: =Hypothèses!C30 -> 26 | D7: =Hypothèses!D30 -> 27 | E7: =Hypothèses!E30 -> 28 | F7: =Hypothèses!F30 -> 29
A9: COÛTS DIRECTS TOTAUX (Md FCFA)
A10: Coût MP consommé | B10: ='Achats MP'!B8 -> 10.9 | C10: ='Achats MP'!C8 -> 12.745 | D10: ='Achats MP'!D8 -> 14.865 | E10: ='Achats MP'!E8 -> 17.085 | F10: ='Achats MP'!F8 -> 19.855
A11: Coût MOD totale | B11: =Catalogue!B8*Hypothèses!B28/1000 -> 2.125 | C11: =Catalogue!C8*Hypothèses!C28/1000 -> 2.4795 | D11: =Catalogue!D8*Hypothèses!D28/1000 -> 2.8925 | E11: =Catalogue!E8*Hypothèses!E28/1000 -> 3.3215 | F11: =Catalogue!F8*Hypothèses!F28/1000 -> 3.8595
A12: Coût énergie variable | B12: =Catalogue!B8*Hypothèses!B29/1000 -> 1.125 | C12: =Catalogue!C8*Hypothèses!C29/1000 -> 1.3395 | D12: =Catalogue!D8*Hypothèses!D29/1000 -> 1.56 | E12: =Catalogue!E8*Hypothèses!E29/1000 -> 1.825 | F12: =Catalogue!F8*Hypothèses!F29/1000 -> 2.158
A13: Coût consommables & emballages | B13: =Catalogue!B8*Hypothèses!B30/1000 -> 0.625 | C13: =Catalogue!C8*Hypothèses!C30/1000 -> 0.741 | D13: =Catalogue!D8*Hypothèses!D30/1000 -> 0.8775 | E13: =Catalogue!E8*Hypothèses!E30/1000 -> 1.022 | F13: =Catalogue!F8*Hypothèses!F30/1000 -> 1.2035
A14: Total coûts directs | B14: =SUM(B10:B13) -> 14.775 | C14: =SUM(C10:C13) -> 17.305 | D14: =SUM(D10:D13) -> 20.195 | E14: =SUM(E10:E13) -> 23.2535 | F14: =SUM(F10:F13) -> 27.076
A16: INDICATEURS MARGE
A17: Marge brute (Md FCFA) | B17: =Catalogue!B19-B14 -> 11.725 | C17: =Catalogue!C19-C14 -> 13.515 | D17: =Catalogue!D19-D14 -> 15.57 | E17: =Catalogue!E19-E14 -> 17.6565 | F17: =Catalogue!F19-F14 -> 20.254
A18: Taux marge brute (%) | B18: =IFERROR(B17/Catalogue!B19,0) -> 0.44245283 | C18: =IFERROR(C17/Catalogue!C19,0) -> 0.43851395 | D18: =IFERROR(D17/Catalogue!D19,0) -> 0.43534181 | E18: =IFERROR(E17/Catalogue!E19,0) -> 0.43159374 | F18: =IFERROR(F17/Catalogue!F19,0) -> 0.42793154

Sheet Coûts standards
A1: COÛTS STANDARDS & ANALYSE DES ÉCARTS
B3: Y1 (2026) | C3: Y2 (2027) | D3: Y3 (2028) | E3: Y4 (2029) | F3: Y5 (2030)
A4: COÛT STANDARD UNITAIRE (par tonne)
A5: MP standard (Produit A, k FCFA/T) | B5: =Hypothèses!B25 -> 350 | C5: =Hypothèses!C25 -> 360 | D5: =Hypothèses!D25 -> 370 | E5: =Hypothèses!E25 -> 380 | F5: =Hypothèses!F25 -> 390
A6: MOD standard (k FCFA/T) | B6: =Hypothèses!B28 -> 85 | C6: =Hypothèses!C28 -> 87 | D6: =Hypothèses!D28 -> 89 | E6: =Hypothèses!E28 -> 91 | F6: =Hypothèses!F28 -> 93
A7: Énergie standard (k FCFA/T) | B7: =Hypothèses!B29 -> 45 | C7: =Hypothèses!C29 -> 47 | D7: =Hypothèses!D29 -> 48 | E7: =Hypothèses!E29 -> 50 | F7: =Hypothèses!F29 -> 52
A8: Total coût standard Produit A (k FCFA/T) | B8: =Hypothèses!B25+Hypothèses!B28+Hypothèses!B29+Hypothèses!B30 -> 505 | C8: =Hypothèses!C25+Hypothèses!C28+Hypothèses!C29+Hypothèses!C30 -> 520 | D8: =Hypothèses!D25+Hypothèses!D28+Hypothèses!D29+Hypothèses!D30 -> 534 | E8: =Hypothèses!E25+Hypothèses!E28+Hypothèses!E29+Hypothèses!E30 -> 549 | F8: =Hypothèses!F25+Hypothèses!F28+Hypothèses!F29+Hypothèses!F30 -> 564
A10: ANALYSE DES ÉCARTS (illustratif)
A11: Écart prix MP — % budgétaire (input) | B11: 0.02 | C11: 0.015 | D11: 0.01 | E11: 0.01 | F11: 0.005
A12: Impact financier écart prix MP (Md FCFA) | B12: ='Coûts directs'!B10*B11 -> 0.218 | C12: ='Coûts directs'!C10*C11 -> 0.191175 | D12: ='Coûts directs'!D10*D11 -> 0.14865 | E12: ='Coûts directs'!E10*E11 -> 0.17085 | F12: ='Coûts directs'!F10*F11 -> 0.099275
A13: Écart quantité MP — % budgétaire (input) | B13: 0.015 | C13: 0.012 | D13: 0.01 | E13: 0.008 | F13: 0.005
A14: Impact financier écart quantité MP (Md FCFA) | B14: ='Coûts directs'!B10*B13 -> 0.1635 | C14: ='Coûts directs'!C10*C13 -> 0.15294 | D14: ='Coûts directs'!D10*D13 -> 0.14865 | E14: ='Coûts directs'!E10*E13 -> 0.13668 | F14: ='Coûts directs'!F10*F13 -> 0.099275
A15: Écart productivité MOD — % (input) | B15: 0.03 | C15: 0.025 | D15: 0.02 | E15: 0.018 | F15: 0.015
A16: Impact financier écart MOD (Md FCFA) | B16: ='Coûts directs'!B11*B15 -> 0.06375 | C16: ='Coûts directs'!C11*C15 -> 0.0619875 | D16: ='Coûts directs'!D11*D15 -> 0.05785 | E16: ='Coûts directs'!E11*E15 -> 0.059787 | F16: ='Coûts directs'!F11*F15 -> 0.0578925

Sheet CAPEX
A1: INVESTISSEMENTS & AMORTISSEMENTS
B3: Y1 (2026) | C3: Y2 (2027) | D3: Y3 (2028) | E3: Y4 (2029) | F3: Y5 (2030)
A4: IMMOBILISATIONS BRUTES (Md FCFA)
A5: Immo brutes début période | B5: =Hypothèses!B57 -> 25 | C5: =B7 -> 27 | D5: =C7 -> 30.5 | E5: =D7 -> 35.5 | F5: =E7 -> 39.5
A6: CAPEX nouveau de l'exercice | B6: =Hypothèses!B58 -> 2 | C6: =Hypothèses!C58 -> 3.5 | D6: =Hypothèses!D58 -> 5 | E6: =Hypothèses!E58 -> 4 | F6: =Hypothèses!F58 -> 3
A7: Immo brutes fin période | B7: =B5+B6 -> 27 | C7: =C5+C6 -> 30.5 | D7: =D5+D6 -> 35.5 | E7: =E5+E6 -> 39.5 | F7: =F5+F6 -> 42.5
A9: AMORTISSEMENTS (Md FCFA)
A10: Dotation aux amortissements annuelle | B10: =B7/Hypothèses!B59 -> 2.7 | C10: =C7/Hypothèses!C59 -> 3.05 | D10: =D7/Hypothèses!D59 -> 3.55 | E10: =E7/Hypothèses!E59 -> 3.95 | F10: =F7/Hypothèses!F59 -> 4.25
A11: Amortissements cumulés début | B11: 5 | C11: =B12 -> 7.7 | D11: =C12 -> 10.75 | E11: =D12 -> 14.3 | F11: =E12 -> 18.25
A12: Amortissements cumulés fin | B12: =B11+B10 -> 7.7 | C12: =C11+C10 -> 10.75 | D12: =D11+D10 -> 14.3 | E12: =E11+E10 -> 18.25 | F12: =F11+F10 -> 22.5
A14: IMMOBILISATIONS NETTES
A15: Immobilisations nettes (= brut - amortis cumulés) | B15: =B7-B12 -> 19.3 | C15: =C7-C12 -> 19.75 | D15: =D7-D12 -> 21.2 | E15: =E7-E12 -> 21.25 | F15: =F7-F12 -> 20

Sheet Charges fixes
A1: CHARGES FIXES & RH
B3: Y1 (2026) | C3: Y2 (2027) | D3: Y3 (2028) | E3: Y4 (2029) | F3: Y5 (2030)
A4: MASSE SALARIALE (Md FCFA)
A5: Encadrement production | B5: =Hypothèses!B41*Hypothèses!B44/1000 -> 0.1375 | C5: =Hypothèses!C41*Hypothèses!C44/1000 -> 0.1596 | D5: =Hypothèses!D41*Hypothèses!D44/1000 -> 0.177 | E5: =Hypothèses!E41*Hypothèses!E44/1000 -> 0.1952 | F5: =Hypothèses!F41*Hypothèses!F44/1000 -> 0.2205
A6: Support (admin, vente, R&D) | B6: =Hypothèses!B42*Hypothèses!B45/1000 -> 0.16 | C6: =Hypothèses!C42*Hypothèses!C45/1000 -> 0.1764 | D6: =Hypothèses!D42*Hypothèses!D45/1000 -> 0.198 | E6: =Hypothèses!E42*Hypothèses!E45/1000 -> 0.2208 | F6: =Hypothèses!F42*Hypothèses!F45/1000 -> 0.24
A7: Total masse salariale fixe | B7: =B5+B6 -> 0.2975 | C7: =C5+C6 -> 0.336 | D7: =D5+D6 -> 0.375 | E7: =E5+E6 -> 0.416 | F7: =F5+F6 -> 0.4605
A9: AUTRES CHARGES FIXES (Md FCFA)
A10: Loyers & immobilier | B10: =Hypothèses!B48 -> 0.8 | C10: =Hypothèses!C48 -> 0.9 | D10: =Hypothèses!D48 -> 1 | E10: =Hypothèses!E48 -> 1.1 | F10: =Hypothèses!F48 -> 1.2
A11: Maintenance équipements | B11: =Hypothèses!B49 -> 1.5 | C11: =Hypothèses!C49 -> 1.6 | D11: =Hypothèses!D49 -> 1.8 | E11: =Hypothèses!E49 -> 2 | F11: =Hypothèses!F49 -> 2.2
A12: Énergie fixe | B12: =Hypothèses!B50 -> 0.6 | C12: =Hypothèses!C50 -> 0.65 | D12: =Hypothèses!D50 -> 0.7 | E12: =Hypothèses!E50 -> 0.75 | F12: =Hypothèses!F50 -> 0.8
A13: IT, télécoms | B13: =Hypothèses!B51 -> 0.4 | C13: =Hypothèses!C51 -> 0.45 | D13: =Hypothèses!D51 -> 0.5 | E13: =Hypothèses!E51 -> 0.55 | F13: =Hypothèses!F51 -> 0.6
A14: Marketing & ventes | B14: =Hypothèses!B52 -> 0.7 | C14: =Hypothèses!C52 -> 0.8 | D14: =Hypothèses!D52 -> 0.9 | E14: =Hypothèses!E52 -> 1 | F14: =Hypothèses!F52 -> 1.1
A15: Honoraires, conseil, audit | B15: =Hypothèses!B53 -> 0.3 | C15: =Hypothèses!C53 -> 0.32 | D15: =Hypothèses!D53 -> 0.34 | E15: =Hypothèses!E53 -> 0.36 | F15: =Hypothèses!F53 -> 0.38
A16: Autres charges externes | B16: =Hypothèses!B54 -> 0.5 | C16: =Hypothèses!C54 -> 0.55 | D16: =Hypothèses!D54 -> 0.6 | E16: =Hypothèses!E54 -> 0.65 | F16: =Hypothèses!F54 -> 0.7
A17: Total autres charges fixes | B17: =SUM(B10:B16) -> 4.8 | C17: =SUM(C10:C16) -> 5.27 | D17: =SUM(D10:D16) -> 5.84 | E17: =SUM(E10:E16) -> 6.41 | F17: =SUM(F10:F16) -> 6.98
A19: TOTAL CHARGES FIXES
A20: Total charges fixes (masse + autres) | B20: =B7+B17 -> 5.0975 | C20: =C7+C17 -> 5.606 | D20: =D7+D17 -> 6.215 | E20: =E7+E17 -> 6.826 | F20: =F7+F17 -> 7.4405

Sheet P_L
A1: COMPTE DE RÉSULTAT
B3: Y1 (2026) | C3: Y2 (2027) | D3: Y3 (2028) | E3: Y4 (2029) | F3: Y5 (2030)
A4: PRODUCTION DE L'EXERCICE
A5: Chiffre d'affaires | B5: =Catalogue!B19 -> 26.5 | C5: =Catalogue!C19 -> 30.82 | D5: =Catalogue!D19 -> 35.765 | E5: =Catalogue!E19 -> 40.91 | F5: =Catalogue!F19 -> 47.33
A6: Variation stock produits finis | B6: =Stocks!B7 -> 1.5246575 | C6: =Stocks!C7-Stocks!B7 -> 0.13033425 | D6: =Stocks!D7-Stocks!C7 -> 0.059768493 | E6: =Stocks!E7-Stocks!D7 -> 0.089763014 | F6: =Stocks!F7-Stocks!E7 -> 0.1924137
A7: Production de l'exercice | B7: =B5+B6 -> 28.024658 | C7: =C5+C6 -> 30.950334 | D7: =D5+D6 -> 35.824768 | E7: =E5+E6 -> 40.999763 | F7: =F5+F6 -> 47.522414
A9: CONSOMMATIONS
A10: Consommation MP | B10: =-'Coûts directs'!B10 -> -10.9 | C10: =-'Coûts directs'!C10 -> -12.745 | D10: =-'Coûts directs'!D10 -> -14.865 | E10: =-'Coûts directs'!E10 -> -17.085 | F10: =-'Coûts directs'!F10 -> -19.855
A11: Énergie variable | B11: =-'Coûts directs'!B12 -> -1.125 | C11: =-'Coûts directs'!C12 -> -1.3395 | D11: =-'Coûts directs'!D12 -> -1.56 | E11: =-'Coûts directs'!E12 -> -1.825 | F11: =-'Coûts directs'!F12 -> -2.158
A12: Consommables & emballages | B12: =-'Coûts directs'!B13 -> -0.625 | C12: =-'Coûts directs'!C13 -> -0.741 | D12: =-'Coûts directs'!D13 -> -0.8775 | E12: =-'Coûts directs'!E13 -> -1.022 | F12: =-'Coûts directs'!F13 -> -1.2035
A13: Marge sur consommation MP | B13: =B7+SUM(B10:B12) -> 15.374658 | C13: =C7+SUM(C10:C12) -> 16.124834 | D13: =D7+SUM(D10:D12) -> 18.522268 | E13: =E7+SUM(E10:E12) -> 21.067763 | F13: =F7+SUM(F10:F12) -> 24.305914
A15: CHARGES DE PERSONNEL
A16: MOD directe (variable) | B16: =-'Coûts directs'!B11 -> -2.125 | C16: =-'Coûts directs'!C11 -> -2.4795 | D16: =-'Coûts directs'!D11 -> -2.8925 | E16: =-'Coûts directs'!E11 -> -3.3215 | F16: =-'Coûts directs'!F11 -> -3.8595
A17: Encadrement + Support | B17: =-'Charges fixes'!B7 -> -0.2975 | C17: =-'Charges fixes'!C7 -> -0.336 | D17: =-'Charges fixes'!D7 -> -0.375 | E17: =-'Charges fixes'!E7 -> -0.416 | F17: =-'Charges fixes'!F7 -> -0.4605
A18: Total charges de personnel | B18: =SUM(B16:B17) -> -2.4225 | C18: =SUM(C16:C17) -> -2.8155 | D18: =SUM(D16:D17) -> -3.2675 | E18: =SUM(E16:E17) -> -3.7375 | F18: =SUM(F16:F17) -> -4.32
A20: AUTRES CHARGES EXTERNES
A21: Autres charges fixes | B21: =-'Charges fixes'!B17 -> -4.8 | C21: =-'Charges fixes'!C17 -> -5.27 | D21: =-'Charges fixes'!D17 -> -5.84 | E21: =-'Charges fixes'!E17 -> -6.41 | F21: =-'Charges fixes'!F17 -> -6.98
A23: EBITDA & EBIT
A24: EBITDA (Excédent brut d'exploitation) | B24: =B13+B18+B21 -> 8.1521575 | C24: =C13+C18+C21 -> 8.0393342 | D24: =D13+D18+D21 -> 9.4147685 | E24: =E13+E18+E21 -> 10.920263 | F24: =F13+F18+F21 -> 13.005914
A25: Dotations aux amortissements | B25: =-CAPEX!B10 -> -2.7 | C25: =-CAPEX!C10 -> -3.05 | D25: =-CAPEX!D10 -> -3.55 | E25: =-CAPEX!E10 -> -3.95 | F25: =-CAPEX!F10 -> -4.25
A26: EBIT (Résultat d'exploitation) | B26: =B24+B25 -> 5.4521575 | C26: =C24+C25 -> 4.9893342 | D26: =D24+D25 -> 5.8647685 | E26: =E24+E25 -> 6.970263 | F26: =F24+F25 -> 8.7559137
A28: RÉSULTAT NET
A29: Charges financières (intérêts sur dette) | B29: =-Hypothèses!B61*Hypothèses!B62 -> -0.6 | C29: =-Hypothèses!C61*Hypothèses!C62 -> -0.525 | D29: =-Hypothèses!D61*Hypothèses!D62 -> -0.42 | E29: =-Hypothèses!E61*Hypothèses!E62 -> -0.35 | F29: =-Hypothèses!F61*Hypothèses!F62 -> -0.28
A30: Résultat avant impôt | B30: =B26+B29 -> 4.8521575 | C30: =C26+C29 -> 4.4643342 | D30: =D26+D29 -> 5.4447685 | E30: =E26+E29 -> 6.620263 | F30: =F26+F29 -> 8.4759137
A31: Impôt sur les sociétés | B31: =-MAX(B30,0)*Hypothèses!B6 -> -1.3586041 | C31: =-MAX(C30,0)*Hypothèses!C6 -> -1.2500136 | D31: =-MAX(D30,0)*Hypothèses!D6 -> -1.5245352 | E31: =-MAX(E30,0)*Hypothèses!E6 -> -1.8536736 | F31: =-MAX(F30,0)*Hypothèses!F6 -> -2.3732558
A32: RÉSULTAT NET | B32: =B30+B31 -> 3.4935534 | C32: =C30+C31 -> 3.2143207 | D32: =D30+D31 -> 3.9202333 | E32: =E30+E31 -> 4.7665894 | F32: =F30+F31 -> 6.1026579
A34: INDICATEURS DE MARGE
A35: Marge EBITDA (%) | B35: =IFERROR(B24/B5,0) -> 0.30762859 | C35: =IFERROR(C24/C5,0) -> 0.26084796 | D35: =IFERROR(D24/D5,0) -> 0.26323972 | E35: =IFERROR(E24/E5,0) -> 0.26693383 | F35: =IFERROR(F24/F5,0) -> 0.27479218
A36: Marge EBIT (%) | B36: =IFERROR(B26/B5,0) -> 0.20574179 | C36: =IFERROR(C26/C5,0) -> 0.16188625 | D36: =IFERROR(D26/D5,0) -> 0.16398067 | E36: =IFERROR(E26/E5,0) -> 0.17038042 | F36: =IFERROR(F26/F5,0) -> 0.18499712
A37: Marge nette (%) | B37: =IFERROR(B32/B5,0) -> 0.1318322 | C37: =IFERROR(C32/C5,0) -> 0.10429334 | D37: =IFERROR(D32/D5,0) -> 0.10961089 | E37: =IFERROR(E32/E5,0) -> 0.11651404 | F37: =IFERROR(F32/F5,0) -> 0.12893847

Sheet Bilan
A1: BILAN — INDUSTRIE
B3: Y1 (2026) | C3: Y2 (2027) | D3: Y3 (2028) | E3: Y4 (2029) | F3: Y5 (2030)
A4: ACTIF (Md FCFA)
A5: Immobilisations nettes | B5: =CAPEX!B15 -> 19.3 | C5: =CAPEX!C15 -> 19.75 | D5: =CAPEX!D15 -> 21.2 | E5: =CAPEX!E15 -> 21.25 | F5: =CAPEX!F15 -> 20
A6: Stocks (MP + EC + PF) | B6: =Stocks!B8 -> 3.1671233 | C6: =Stocks!C8 -> 3.4008822 | D6: =Stocks!D8 -> 3.6288836 | E6: =Stocks!E8 -> 3.8172767 | F6: =Stocks!F8 -> 4.3360192
A7: Créances clients (DSO) | B7: =Catalogue!B19*Hypothèses!B36/365 -> 4.3561644 | C7: =Catalogue!C19*Hypothèses!C36/365 -> 4.6441096 | D7: =Catalogue!D19*Hypothèses!D36/365 -> 4.8993151 | E7: =Catalogue!E19*Hypothèses!E36/365 -> 5.3799452 | F7: =Catalogue!F19*Hypothèses!F36/365 -> 5.8352055
A8: Trésorerie (équilibre) | B8: =B18-B5-B6-B7 -> 0.17977973 | C8: =C18-C5-C6-C7 -> 0.44263669 | D8: =D18-D5-D6-D7 -> 0.57810298 | E8: =E18-E5-E6-E7 -> 8.3238552 | F8: =F18-F5-F6-F7 -> 12.158947
A9: TOTAL ACTIF | B9: =B5+B6+B7+B8 -> 27.003067 | C9: =C5+C6+C7+C8 -> 28.237628 | D9: =D5+D6+D7+D8 -> 30.306302 | E9: =E5+E6+E7+E8 -> 38.771077 | F9: =F5+F6+F7+F8 -> 42.330171
A11: PASSIF (Md FCFA)
A12: Capital social | B12: =Hypothèses!B60 -> 12 | C12: =Hypothèses!C60 -> 12 | D12: =Hypothèses!D60 -> 12 | E12: =Hypothèses!E60 -> 18 | F12: =Hypothèses!F60 -> 18
A13: Réserves cumulées | B13: 2 | C13: =B13+P_L!B32*(1-Hypothèses!B63) -> 4.4454874 | D13: =C13+P_L!C32*(1-Hypothèses!C63) -> 6.5347958 | E13: =D13+P_L!D32*(1-Hypothèses!D63) -> 8.8869358 | F13: =E13+P_L!E32*(1-Hypothèses!E63) -> 11.746889
A14: Résultat de l'exercice | B14: =P_L!B32 -> 3.4935534 | C14: =P_L!C32 -> 3.2143207 | D14: =P_L!D32 -> 3.9202333 | E14: =P_L!E32 -> 4.7665894 | F14: =P_L!F32 -> 6.1026579
A15: Total capitaux propres | B15: =B12+B13+B14 -> 17.493553 | C15: =C12+C13+C14 -> 19.659808 | D15: =D12+D13+D14 -> 22.455029 | E15: =E12+E13+E14 -> 31.653525 | F15: =F12+F13+F14 -> 35.849547
A16: Dette long terme | B16: =Hypothèses!B61 -> 8 | C16: =Hypothèses!C61 -> 7 | D16: =Hypothèses!D61 -> 6 | E16: =Hypothèses!E61 -> 5 | F16: =Hypothèses!F61 -> 4
A17: Dettes fournisseurs (DPO) | B17: ='Achats MP'!B15*Hypothèses!B37/365 -> 1.509514 | C17: ='Achats MP'!C15*Hypothèses!C37/365 -> 1.5778204 | D17: ='Achats MP'!D15*Hypothèses!D37/365 -> 1.8512725 | E17: ='Achats MP'!E15*Hypothèses!E37/365 -> 2.1175519 | F17: ='Achats MP'!F15*Hypothèses!F37/365 -> 2.4806239
A18: TOTAL PASSIF | B18: =B15+B16+B17 -> 27.003067 | C18: =C15+C16+C17 -> 28.237628 | D18: =D15+D16+D17 -> 30.306302 | E18: =E15+E16+E17 -> 38.771077 | F18: =F15+F16+F17 -> 42.330171
A20: CONTRÔLE
A21: Écart actif - passif | B21: =B9-B18 -> 0 | C21: =C9-C18 -> 0 | D21: =D9-D18 -> 0 | E21: =E9-E18 -> 0 | F21: =F9-F18 -> 0

Sheet Trésorerie & KPIs
A1: TRÉSORERIE, BFR & KPIs INDUSTRIELS
B3: Y1 (2026) | C3: Y2 (2027) | D3: Y3 (2028) | E3: Y4 (2029) | F3: Y5 (2030)
A4: BFR — BESOIN EN FONDS DE ROULEMENT
A5: Stocks (Md FCFA) | B5: =Stocks!B8 -> 3.1671233 | C5: =Stocks!C8 -> 3.4008822 | D5: =Stocks!D8 -> 3.6288836 | E5: =Stocks!E8 -> 3.8172767 | F5: =Stocks!F8 -> 4.3360192
A6: + Créances clients (Md FCFA) | B6: =Bilan!B7 -> 4.3561644 | C6: =Bilan!C7 -> 4.6441096 | D6: =Bilan!D7 -> 4.8993151 | E6: =Bilan!E7 -> 5.3799452 | F6: =Bilan!F7 -> 5.8352055
A7: - Dettes fournisseurs (Md FCFA) | B7: =-Bilan!B17 -> -1.509514 | C7: =-Bilan!C17 -> -1.5778204 | D7: =-Bilan!D17 -> -1.8512725 | E7: =-Bilan!E17 -> -2.1175519 | F7: =-Bilan!F17 -> -2.4806239
A8: BFR (Md FCFA) | B8: =B5+B6+B7 -> 6.0137737 | C8: =C5+C6+C7 -> 6.4671714 | D8: =D5+D6+D7 -> 6.6769262 | E8: =E5+E6+E7 -> 7.07967 | F8: =F5+F6+F7 -> 7.6906007
A9: BFR / CA (en jours) | B9: =IFERROR(B8*365/Catalogue!B19,0) -> 82.831223 | C9: =IFERROR(C8*365/Catalogue!C19,0) -> 76.590446 | D9: =IFERROR(D8*365/Catalogue!D19,0) -> 68.141425 | E9: =IFERROR(E8*365/Catalogue!E19,0) -> 63.164986 | F9: =IFERROR(F8*365/Catalogue!F19,0) -> 59.308457
A11: CASH-FLOW
A12: EBITDA | B12: =P_L!B24 -> 8.1521575 | C12: =P_L!C24 -> 8.0393342 | D12: =P_L!D24 -> 9.4147685 | E12: =P_L!E24 -> 10.920263 | F12: =P_L!F24 -> 13.005914
A13: - Variation BFR | B13: =-B8 -> -6.0137737 | C13: =-(C8-B8) -> -0.45339767 | D13: =-(D8-C8) -> -0.20975479 | E13: =-(E8-D8) -> -0.40274387 | F13: =-(F8-E8) -> -0.61093068
A14: - CAPEX | B14: =-CAPEX!B6 -> -2 | C14: =-CAPEX!C6 -> -3.5 | D14: =-CAPEX!D6 -> -5 | E14: =-CAPEX!E6 -> -4 | F14: =-CAPEX!F6 -> -3
A15: - IS | B15: =P_L!B31 -> -1.3586041 | C15: =P_L!C31 -> -1.2500136 | D15: =P_L!D31 -> -1.5245352 | E15: =P_L!E31 -> -1.8536736 | F15: =P_L!F31 -> -2.3732558
A16: Free Cash Flow | B16: =B12+B13+B14+B15 -> -1.2202203 | C16: =C12+C13+C14+C15 -> 2.835923 | D16: =D12+D13+D14+D15 -> 2.6804785 | E16: =E12+E13+E14+E15 -> 4.6638455 | F16: =F12+F13+F14+F15 -> 7.0217272
A18: KPIs INDUSTRIELS
A19: OEE | B19: =Hypothèses!B21 -> 0.65 | C19: =Hypothèses!C21 -> 0.68 | D19: =Hypothèses!D21 -> 0.72 | E19: =Hypothèses!E21 -> 0.75 | F19: =Hypothèses!F21 -> 0.78
A20: Taux d'utilisation capacité | B20: =IFERROR(Catalogue!B8/Hypothèses!B20,0) -> 0.71428571 | C20: =IFERROR(Catalogue!C8/Hypothèses!C20,0) -> 0.81428571 | D20: =IFERROR(Catalogue!D8/Hypothèses!D20,0) -> 0.8125 | E20: =IFERROR(Catalogue!E8/Hypothèses!E20,0) -> 0.81111111 | F20: =IFERROR(Catalogue!F8/Hypothèses!F20,0) -> 0.83
A21: Marge brute (%) | B21: =IFERROR('Coûts directs'!B17/Catalogue!B19,0) -> 0.44245283 | C21: =IFERROR('Coûts directs'!C17/Catalogue!C19,0) -> 0.43851395 | D21: =IFERROR('Coûts directs'!D17/Catalogue!D19,0) -> 0.43534181 | E21: =IFERROR('Coûts directs'!E17/Catalogue!E19,0) -> 0.43159374 | F21: =IFERROR('Coûts directs'!F17/Catalogue!F19,0) -> 0.42793154
A22: Marge EBITDA (%) | B22: =IFERROR(P_L!B24/P_L!B5,0) -> 0.30762859 | C22: =IFERROR(P_L!C24/P_L!C5,0) -> 0.26084796 | D22: =IFERROR(P_L!D24/P_L!D5,0) -> 0.26323972 | E22: =IFERROR(P_L!E24/P_L!E5,0) -> 0.26693383 | F22: =IFERROR(P_L!F24/P_L!F5,0) -> 0.27479218
A23: ROCE (EBIT / Capitaux engagés) | B23: =IFERROR(P_L!B26/(Bilan!B15+Bilan!B16),0) -> 0.21386417 | C23: =IFERROR(P_L!C26/(Bilan!C15+Bilan!C16),0) -> 0.18714817 | D23: =IFERROR(P_L!D26/(Bilan!D15+Bilan!D16),0) -> 0.20610657 | E23: =IFERROR(P_L!E26/(Bilan!E15+Bilan!E16),0) -> 0.19016624 | F23: =IFERROR(P_L!F26/(Bilan!F15+Bilan!F16),0) -> 0.2197243
A24: ROE | B24: =IFERROR(P_L!B32/Bilan!B15,0) -> 0.19970519 | C24: =IFERROR(P_L!C32/((Bilan!B15+Bilan!C15)/2),0) -> 0.17302987 | D24: =IFERROR(P_L!D32/((Bilan!C15+Bilan!D15)/2),0) -> 0.18616875 | E24: =IFERROR(P_L!E32/((Bilan!D15+Bilan!E15)/2),0) -> 0.17618617 | F24: =IFERROR(P_L!F32/((Bilan!E15+Bilan!F15)/2),0) -> 0.18081126
A25: Point mort CA (= charges fixes / taux MCV) | B25: =IFERROR('Charges fixes'!B20/((Catalogue!B19-'Coûts directs'!B14)/Catalogue!B19),0) -> 11.521002 | C25: =IFERROR('Charges fixes'!C20/((Catalogue!C19-'Coûts directs'!C14)/Catalogue!C19),0) -> 12.784086 | D25: =IFERROR('Charges fixes'!D20/((Catalogue!D19-'Coûts directs'!D14)/Catalogue!D19),0) -> 14.276138 | E25: =IFERROR('Charges fixes'!E20/((Catalogue!E19-'Coûts directs'!E14)/Catalogue!E19),0) -> 15.815799 | F25: =IFERROR('Charges fixes'!F20/((Catalogue!F19-'Coûts directs'!F14)/Catalogue!F19),0) -> 17.387127
